{
  "version": 8,
  "blockIdVersion": 11,
  "anchorX": -3,
  "anchorY": 0,
  "anchorZ": 0,
  "blocks": [
    {
      "x": -3,
      "y": 6,
      "z": -4,
      "name": "Rock_Crystal_White_Block"
    },
    {
      "x": -3,
      "y": 7,
      "z": -4,
      "name": "Cloth_Block_Wool_White"
    },
    {
      "x": -3,
      "y": 6,
      "z": -3,
      "name": "Soil_Clay_White"
    },
    {
      "x": -3,
      "y": 4,
      "z": -1,
      "name": "Wood_Beech_Branch_Short",
      "support": 15,
      "rotation": 3
    },
    {
      "x": -3,
      "y": 0,
      "z": 0,
      "name": "Wood_Beech_Trunk_Full",
      "support": 15
    },
    {
      "x": -3,
      "y": 1,
      "z": 0,
      "name": "Wood_Beech_Trunk_Full",
      "support": 15
    },
    {
      "x": -3,
      "y": 2,
      "z": 0,
      "name": "Wood_Beech_Trunk_Full",
      "support": 15
    },
    {
      "x": -3,
      "y": 8,
      "z": 3,
      "name": "Cloth_Block_Wool_White"
    },
    {
      "x": -3,
      "y": 9,
      "z": 3,
      "name": "Cloth_Block_Wool_White"
    },
    {
      "x": -3,
      "y": 10,
      "z": 3,
      "name": "Soil_Clay_Beige"
    },
    {
      "x": -3,
      "y": 7,
      "z": 4,
      "name": "Soil_Clay_White"
    },
    {
      "x": -3,
      "y": 9,
      "z": 4,
      "name": "Soil_Clay_White"
    },
    {
      "x": -3,
      "y": 10,
      "z": 4,
      "name": "Soil_Clay_Beige"
    },
    {
      "x": -2,
      "y": 4,
      "z": -5,
      "name": "Cloth_Block_Wool_White"
    },
    {
      "x": -2,
      "y": 6,
      "z": -5,
      "name": "Soil_Clay_White"
    },
    {
      "x": -2,
      "y": 7,
      "z": -5,
      "name": "Soil_Clay_Beige"
    },
    {
      "x": -2,
      "y": 5,
      "z": -4,
      "name": "Soil_Clay_White"
    },
    {
      "x": -2,
      "y": 6,
      "z": -4,
      "name": "Cloth_Block_Wool_White"
    },
    {
      "x": -2,
      "y": 7,
      "z": -4,
      "name": "Wood_Beech_Trunk_Full",
      "support": 15,
      "rotation": 4
    },
    {
      "x": -2,
      "y": 8,
      "z": -4,
      "name": "Soil_Clay_Beige"
    },
    {
      "x": -2,
      "y": 5,
      "z": -3,
      "name": "Soil_Clay_White"
    },
    {
      "x": -2,
      "y": 6,
      "z": -3,
      "name": "Wood_Beech_Trunk_Full",
      "support": 15,
      "rotation": 4
    },
    {
      "x": -2,
      "y": 7,
      "z": -3,
      "name": "Soil_Clay_White"
    },
    {
      "x": -2,
      "y": 6,
      "z": -2,
      "name": "Wood_Beech_Trunk_Full",
      "support": 15,
      "rotation": 4
    },
    {
      "x": -2,
      "y": 3,
      "z": -1,
      "name": "Wood_Beech_Trunk_Full",
      "support": 15
    },
    {
      "x": -2,
      "y": 4,
      "z": -1,
      "name": "Wood_Beech_Trunk_Full",
      "support": 15
    },
    {
      "x": -2,
      "y": 2,
      "z": 0,
      "name": "Wood_Beech_Trunk_Full",
      "support": 15
    },
    {
      "x": -2,
      "y": 3,
      "z": 0,
      "name": "Wood_Beech_Trunk_Full",
      "support": 15
    },
    {
      "x": -2,
      "y": 3,
      "z": 1,
      "name": "Wood_Beech_Trunk_Full",
      "support": 15
    },
    {
      "x": -2,
      "y": 4,
      "z": 1,
      "name": "Wood_Beech_Trunk_Full",
      "support": 15
    },
    {
      "x": -2,
      "y": 4,
      "z": 2,
      "name": "Wood_Beech_Trunk_Full",
      "support": 15
    },
    {
      "x": -2,
      "y": 5,
      "z": 2,
      "name": "Wood_Beech_Trunk_Full",
      "support": 15
    },
    {
      "x": -2,
      "y": 6,
      "z": 2,
      "name": "Wood_Beech_Trunk_Full",
      "support": 15
    },
    {
      "x": -2,
      "y": 7,
      "z": 2,
      "name": "Wood_Beech_Trunk_Full",
      "support": 15
    },
    {
      "x": -2,
      "y": 9,
      "z": 2,
      "name": "Soil_Clay_White"
    },
    {
      "x": -2,
      "y": 5,
      "z": 3,
      "name": "Wood_Beech_Branch_Short",
      "support": 15
    },
    {
      "x": -2,
      "y": 7,
      "z": 3,
      "name": "Wood_Beech_Trunk_Full",
      "support": 15
    },
    {
      "x": -2,
      "y": 8,
      "z": 3,
      "name": "Wood_Beech_Trunk_Full",
      "support": 15
    },
    {
      "x": -2,
      "y": 9,
      "z": 3,
      "name": "Wood_Beech_Trunk_Full",
      "support": 15
    },
    {
      "x": -2,
      "y": 10,
      "z": 3,
      "name": "Cloth_Block_Wool_White"
    },
    {
      "x": -2,
      "y": 11,
      "z": 3,
      "name": "Soil_Clay_Beige"
    },
    {
      "x": -2,
      "y": 6,
      "z": 4,
      "name": "Cloth_Block_Wool_White"
    },
    {
      "x": -2,
      "y": 7,
      "z": 4,
      "name": "Soil_Clay_White"
    },
    {
      "x": -2,
      "y": 8,
      "z": 4,
      "name": "Cloth_Block_Wool_White"
    },
    {
      "x": -2,
      "y": 9,
      "z": 4,
      "name": "Wood_Beech_Trunk_Full",
      "support": 15,
      "rotation": 4
    },
    {
      "x": -2,
      "y": 10,
      "z": 4,
      "name": "Wood_Beech_Trunk_Full",
      "support": 15
    },
    {
      "x": -2,
      "y": 11,
      "z": 4,
      "name": "Soil_Clay_Orange"
    },
    {
      "x": -2,
      "y": 8,
      "z": 5,
      "name": "Rock_Crystal_White_Block"
    },
    {
      "x": -2,
      "y": 9,
      "z": 5,
      "name": "Soil_Clay_Beige"
    },
    {
      "x": -2,
      "y": 10,
      "z": 5,
      "name": "Soil_Clay_Beige"
    },
    {
      "x": -1,
      "y": 7,
      "z": -4,
      "name": "Soil_Clay_White"
    },
    {
      "x": -1,
      "y": 6,
      "z": -3,
      "name": "Cloth_Block_Wool_White"
    },
    {
      "x": -1,
      "y": 4,
      "z": -1,
      "name": "Wood_Beech_Trunk_Full",
      "support": 15
    },
    {
      "x": -1,
      "y": 5,
      "z": -1,
      "name": "Wood_Beech_Trunk_Full",
      "support": 15
    },
    {
      "x": -1,
      "y": 6,
      "z": -1,
      "name": "Wood_Beech_Trunk_Full",
      "support": 15
    },
    {
      "x": -1,
      "y": 7,
      "z": -1,
      "name": "Wood_Beech_Trunk_Full",
      "support": 15
    },
    {
      "x": -1,
      "y": 7,
      "z": 2,
      "name": "Wood_Beech_Branch_Short",
      "support": 15,
      "rotation": 1
    },
    {
      "x": -1,
      "y": 9,
      "z": 3,
      "name": "Rock_Crystal_White_Block"
    },
    {
      "x": -1,
      "y": 8,
      "z": 4,
      "name": "Cloth_Block_Wool_White"
    },
    {
      "x": -1,
      "y": 9,
      "z": 4,
      "name": "Cloth_Block_Wool_White"
    },
    {
      "x": -1,
      "y": 10,
      "z": 4,
      "name": "Soil_Clay_Beige"
    },
    {
      "x": 0,
      "y": 5,
      "z": -1,
      "name": "Wood_Beech_Branch_Short",
      "support": 15,
      "rotation": 1
    },
    {
      "x": 0,
      "y": 7,
      "z": -1,
      "name": "Wood_Beech_Trunk_Full",
      "support": 15
    },
    {
      "x": 0,
      "y": 8,
      "z": -1,
      "name": "Wood_Beech_Trunk_Full",
      "support": 15
    },
    {
      "x": 0,
      "y": 9,
      "z": -1,
      "name": "Wood_Beech_Trunk_Full",
      "support": 15
    },
    {
      "x": 0,
      "y": 10,
      "z": -1,
      "name": "Rock_Crystal_White_Block"
    },
    {
      "x": 0,
      "y": 11,
      "z": -1,
      "name": "Soil_Clay_Beige"
    },
    {
      "x": 0,
      "y": 12,
      "z": -1,
      "name": "Soil_Clay_Beige"
    },
    {
      "x": 0,
      "y": 7,
      "z": 0,
      "name": "Wood_Beech_Branch_Short",
      "support": 15
    },
    {
      "x": 1,
      "y": 9,
      "z": -2,
      "name": "Soil_Clay_White"
    },
    {
      "x": 1,
      "y": 10,
      "z": -2,
      "name": "Soil_Clay_Beige"
    },
    {
      "x": 1,
      "y": 11,
      "z": -2,
      "name": "Soil_Clay_Beige"
    },
    {
      "x": 1,
      "y": 12,
      "z": -2,
      "name": "Soil_Clay_Orange"
    },
    {
      "x": 1,
      "y": 9,
      "z": -1,
      "name": "Wood_Beech_Trunk_Full",
      "support": 15
    },
    {
      "x": 1,
      "y": 10,
      "z": -1,
      "name": "Wood_Beech_Trunk_Full",
      "support": 15
    },
    {
      "x": 1,
      "y": 11,
      "z": -1,
      "name": "Wood_Beech_Trunk_Full",
      "support": 15
    },
    {
      "x": 1,
      "y": 12,
      "z": -1,
      "name": "Wood_Beech_Trunk_Full",
      "support": 15
    },
    {
      "x": 1,
      "y": 13,
      "z": -1,
      "name": "Soil_Clay_Orange"
    },
    {
      "x": 1,
      "y": 11,
      "z": 0,
      "name": "Soil_Clay_White"
    },
    {
      "x": 1,
      "y": 12,
      "z": 0,
      "name": "Soil_Clay_Beige"
    },
    {
      "x": 1,
      "y": 13,
      "z": 0,
      "name": "Soil_Clay_Orange"
    },
    {
      "x": 2,
      "y": 10,
      "z": -2,
      "name": "Soil_Clay_Beige"
    },
    {
      "x": 2,
      "y": 11,
      "z": -2,
      "name": "Soil_Clay_Orange"
    },
    {
      "x": 2,
      "y": 12,
      "z": -2,
      "name": "Soil_Clay_Black"
    },
    {
      "x": 2,
      "y": 8,
      "z": -1,
      "name": "Soil_Clay_White"
    },
    {
      "x": 2,
      "y": 9,
      "z": -1,
      "name": "Rock_Crystal_White_Block"
    },
    {
      "x": 2,
      "y": 10,
      "z": -1,
      "name": "Soil_Clay_White"
    },
    {
      "x": 2,
      "y": 11,
      "z": -1,
      "name": "Soil_Clay_White"
    },
    {
      "x": 2,
      "y": 12,
      "z": -1,
      "name": "Soil_Clay_White"
    },
    {
      "x": 2,
      "y": 13,
      "z": -1,
      "name": "Soil_Clay_Black"
    },
    {
      "x": 2,
      "y": 10,
      "z": 0,
      "name": "Cloth_Block_Wool_White"
    },
    {
      "x": 2,
      "y": 11,
      "z": 0,
      "name": "Soil_Clay_Orange"
    },
    {
      "x": 2,
      "y": 12,
      "z": 0,
      "name": "Soil_Clay_Orange"
    },
    {
      "x": 3,
      "y": 10,
      "z": -2,
      "name": "Soil_Clay_Beige"
    },
    {
      "x": 3,
      "y": 11,
      "z": -2,
      "name": "Soil_Clay_Orange"
    },
    {
      "x": 3,
      "y": 9,
      "z": -1,
      "name": "Soil_Clay_Beige"
    },
    {
      "x": 3,
      "y": 10,
      "z": -1,
      "name": "Soil_Clay_Beige"
    },
    {
      "x": 3,
      "y": 11,
      "z": -1,
      "name": "Soil_Clay_Orange"
    },
    {
      "x": 3,
      "y": 12,
      "z": -1,
      "name": "Soil_Clay_Black"
    },
    {
      "x": 3,
      "y": 10,
      "z": 0,
      "name": "Soil_Clay_Beige"
    }
  ]
}