{
  "version": 8,
  "blockIdVersion": 11,
  "anchorX": 1,
  "anchorY": 0,
  "anchorZ": 0,
  "blocks": [
    {
      "x": -4,
      "y": 11,
      "z": -3,
      "name": "Soil_Clay_Orange"
    },
    {
      "x": -4,
      "y": 9,
      "z": -2,
      "name": "Rock_Crystal_White_Block"
    },
    {
      "x": -4,
      "y": 10,
      "z": -2,
      "name": "Soil_Clay_Beige"
    },
    {
      "x": -4,
      "y": 11,
      "z": -2,
      "name": "Soil_Clay_Orange"
    },
    {
      "x": -4,
      "y": 9,
      "z": -1,
      "name": "Soil_Clay_Beige"
    },
    {
      "x": -4,
      "y": 10,
      "z": -1,
      "name": "Soil_Clay_Beige"
    },
    {
      "x": -3,
      "y": 9,
      "z": -3,
      "name": "Soil_Clay_Beige"
    },
    {
      "x": -3,
      "y": 10,
      "z": -3,
      "name": "Soil_Clay_Black"
    },
    {
      "x": -3,
      "y": 11,
      "z": -3,
      "name": "Soil_Clay_Orange"
    },
    {
      "x": -3,
      "y": 12,
      "z": -3,
      "name": "Soil_Clay_Orange"
    },
    {
      "x": -3,
      "y": 7,
      "z": -2,
      "name": "Soil_Clay_White"
    },
    {
      "x": -3,
      "y": 8,
      "z": -2,
      "name": "Soil_Clay_Beige"
    },
    {
      "x": -3,
      "y": 9,
      "z": -2,
      "name": "Soil_Clay_Beige"
    },
    {
      "x": -3,
      "y": 10,
      "z": -2,
      "name": "Soil_Clay_Beige"
    },
    {
      "x": -3,
      "y": 11,
      "z": -2,
      "name": "Soil_Clay_Beige"
    },
    {
      "x": -3,
      "y": 12,
      "z": -2,
      "name": "Soil_Clay_Black"
    },
    {
      "x": -3,
      "y": 8,
      "z": -1,
      "name": "Soil_Clay_Beige"
    },
    {
      "x": -3,
      "y": 9,
      "z": -1,
      "name": "Soil_Clay_Beige"
    },
    {
      "x": -3,
      "y": 10,
      "z": -1,
      "name": "Soil_Clay_Beige"
    },
    {
      "x": -3,
      "y": 11,
      "z": -1,
      "name": "Soil_Clay_Orange"
    },
    {
      "x": -3,
      "y": 12,
      "z": -1,
      "name": "Soil_Clay_Orange"
    },
    {
      "x": -2,
      "y": 9,
      "z": -3,
      "name": "Soil_Clay_Beige"
    },
    {
      "x": -2,
      "y": 10,
      "z": -3,
      "name": "Soil_Clay_Orange"
    },
    {
      "x": -2,
      "y": 11,
      "z": -3,
      "name": "Soil_Clay_Orange"
    },
    {
      "x": -2,
      "y": 8,
      "z": -2,
      "name": "Soil_Clay_White"
    },
    {
      "x": -2,
      "y": 9,
      "z": -2,
      "name": "Soil_Clay_Beige"
    },
    {
      "x": -2,
      "y": 10,
      "z": -2,
      "name": "Wood_Beech_Trunk_Full",
      "support": 15,
      "rotation": 5
    },
    {
      "x": -2,
      "y": 11,
      "z": -2,
      "name": "Wood_Beech_Trunk_Full",
      "support": 15
    },
    {
      "x": -2,
      "y": 12,
      "z": -2,
      "name": "Soil_Clay_Black"
    },
    {
      "x": -2,
      "y": 9,
      "z": -1,
      "name": "Soil_Clay_Beige"
    },
    {
      "x": -2,
      "y": 10,
      "z": -1,
      "name": "Soil_Clay_Orange"
    },
    {
      "x": -2,
      "y": 11,
      "z": -1,
      "name": "Soil_Clay_Black"
    },
    {
      "x": -1,
      "y": 10,
      "z": -3,
      "name": "Soil_Clay_Beige"
    },
    {
      "x": -1,
      "y": 11,
      "z": -3,
      "name": "Soil_Clay_Beige"
    },
    {
      "x": -1,
      "y": 7,
      "z": -2,
      "name": "Wood_Beech_Branch_Short",
      "support": 15,
      "rotation": 2
    },
    {
      "x": -1,
      "y": 9,
      "z": -2,
      "name": "Wood_Beech_Trunk_Full",
      "support": 15
    },
    {
      "x": -1,
      "y": 10,
      "z": -2,
      "name": "Wood_Beech_Trunk_Full",
      "support": 15
    },
    {
      "x": -1,
      "y": 11,
      "z": -2,
      "name": "Soil_Clay_Black"
    },
    {
      "x": -1,
      "y": 7,
      "z": -1,
      "name": "Wood_Beech_Trunk_Full",
      "support": 15
    },
    {
      "x": -1,
      "y": 8,
      "z": -1,
      "name": "Wood_Beech_Trunk_Full",
      "support": 15
    },
    {
      "x": -1,
      "y": 9,
      "z": -1,
      "name": "Wood_Beech_Trunk_Full",
      "support": 15
    },
    {
      "x": -1,
      "y": 10,
      "z": -1,
      "name": "Soil_Clay_Orange"
    },
    {
      "x": 0,
      "y": 6,
      "z": -1,
      "name": "Wood_Beech_Trunk_Full",
      "support": 15
    },
    {
      "x": 0,
      "y": 7,
      "z": -1,
      "name": "Wood_Beech_Trunk_Full",
      "support": 15
    },
    {
      "x": 0,
      "y": 1,
      "z": 0,
      "name": "Wood_Beech_Branch_Short",
      "support": 15,
      "rotation": 3
    },
    {
      "x": 0,
      "y": 3,
      "z": 0,
      "name": "Wood_Beech_Trunk_Full",
      "support": 15
    },
    {
      "x": 0,
      "y": 4,
      "z": 0,
      "name": "Wood_Beech_Trunk_Full",
      "support": 15
    },
    {
      "x": 0,
      "y": 5,
      "z": 0,
      "name": "Wood_Beech_Trunk_Full",
      "support": 15
    },
    {
      "x": 0,
      "y": 6,
      "z": 0,
      "name": "Wood_Beech_Trunk_Full",
      "support": 15
    },
    {
      "x": 0,
      "y": 4,
      "z": 1,
      "name": "Wood_Beech_Branch_Short",
      "support": 15
    },
    {
      "x": 0,
      "y": 6,
      "z": 1,
      "name": "Wood_Beech_Trunk_Full",
      "support": 15
    },
    {
      "x": 0,
      "y": 7,
      "z": 1,
      "name": "Wood_Beech_Trunk_Full",
      "support": 15
    },
    {
      "x": 0,
      "y": 10,
      "z": 1,
      "name": "Wood_Beech_Branch_Short",
      "support": 15,
      "rotation": 3
    },
    {
      "x": 1,
      "y": 0,
      "z": 0,
      "name": "Wood_Beech_Trunk_Full",
      "support": 15
    },
    {
      "x": 1,
      "y": 1,
      "z": 0,
      "name": "Wood_Beech_Trunk_Full",
      "support": 15
    },
    {
      "x": 1,
      "y": 2,
      "z": 0,
      "name": "Wood_Beech_Trunk_Full",
      "support": 15
    },
    {
      "x": 1,
      "y": 3,
      "z": 0,
      "name": "Wood_Beech_Trunk_Full",
      "support": 15
    },
    {
      "x": 1,
      "y": 7,
      "z": 1,
      "name": "Wood_Beech_Trunk_Full",
      "support": 15
    },
    {
      "x": 1,
      "y": 8,
      "z": 1,
      "name": "Wood_Beech_Trunk_Full",
      "support": 15
    },
    {
      "x": 1,
      "y": 9,
      "z": 1,
      "name": "Wood_Beech_Trunk_Full",
      "support": 15
    },
    {
      "x": 1,
      "y": 10,
      "z": 1,
      "name": "Wood_Beech_Trunk_Full",
      "support": 15
    },
    {
      "x": 2,
      "y": 8,
      "z": 1,
      "name": "Wood_Beech_Branch_Short",
      "support": 15,
      "rotation": 1
    },
    {
      "x": 2,
      "y": 10,
      "z": 1,
      "name": "Wood_Beech_Trunk_Full",
      "support": 15
    },
    {
      "x": 2,
      "y": 11,
      "z": 1,
      "name": "Wood_Beech_Trunk_Full",
      "support": 15
    },
    {
      "x": 2,
      "y": 12,
      "z": 1,
      "name": "Soil_Clay_Beige"
    },
    {
      "x": 2,
      "y": 10,
      "z": 2,
      "name": "Soil_Clay_Beige"
    },
    {
      "x": 2,
      "y": 11,
      "z": 2,
      "name": "Soil_Clay_Beige"
    },
    {
      "x": 2,
      "y": 12,
      "z": 2,
      "name": "Soil_Clay_Orange"
    },
    {
      "x": 2,
      "y": 13,
      "z": 2,
      "name": "Soil_Clay_Orange"
    },
    {
      "x": 2,
      "y": 14,
      "z": 2,
      "name": "Soil_Clay_Orange"
    },
    {
      "x": 2,
      "y": 12,
      "z": 3,
      "name": "Soil_Clay_Beige"
    },
    {
      "x": 2,
      "y": 13,
      "z": 3,
      "name": "Soil_Clay_Orange"
    },
    {
      "x": 3,
      "y": 11,
      "z": 1,
      "name": "Soil_Clay_Beige"
    },
    {
      "x": 3,
      "y": 12,
      "z": 1,
      "name": "Soil_Clay_Beige"
    },
    {
      "x": 3,
      "y": 13,
      "z": 1,
      "name": "Soil_Clay_Orange"
    },
    {
      "x": 3,
      "y": 14,
      "z": 1,
      "name": "Soil_Clay_Black"
    },
    {
      "x": 3,
      "y": 9,
      "z": 2,
      "name": "Soil_Clay_Beige"
    },
    {
      "x": 3,
      "y": 10,
      "z": 2,
      "name": "Rock_Crystal_White_Block"
    },
    {
      "x": 3,
      "y": 11,
      "z": 2,
      "name": "Wood_Beech_Trunk_Full",
      "support": 15,
      "rotation": 4
    },
    {
      "x": 3,
      "y": 12,
      "z": 2,
      "name": "Wood_Beech_Trunk_Full",
      "support": 15
    },
    {
      "x": 3,
      "y": 13,
      "z": 2,
      "name": "Wood_Beech_Trunk_Full",
      "support": 15
    },
    {
      "x": 3,
      "y": 14,
      "z": 2,
      "name": "Wood_Beech_Trunk_Full",
      "support": 15
    },
    {
      "x": 3,
      "y": 15,
      "z": 2,
      "name": "Soil_Clay_Black"
    },
    {
      "x": 3,
      "y": 11,
      "z": 3,
      "name": "Soil_Clay_Beige"
    },
    {
      "x": 3,
      "y": 12,
      "z": 3,
      "name": "Soil_Clay_Orange"
    },
    {
      "x": 3,
      "y": 13,
      "z": 3,
      "name": "Soil_Clay_Black"
    },
    {
      "x": 3,
      "y": 14,
      "z": 3,
      "name": "Soil_Clay_Orange"
    },
    {
      "x": 4,
      "y": 12,
      "z": 1,
      "name": "Soil_Clay_Orange"
    },
    {
      "x": 4,
      "y": 13,
      "z": 1,
      "name": "Soil_Clay_Black"
    },
    {
      "x": 4,
      "y": 14,
      "z": 1,
      "name": "Soil_Clay_Orange"
    },
    {
      "x": 4,
      "y": 15,
      "z": 1,
      "name": "Soil_Clay_Black"
    },
    {
      "x": 4,
      "y": 11,
      "z": 2,
      "name": "Soil_Clay_White"
    },
    {
      "x": 4,
      "y": 12,
      "z": 2,
      "name": "Soil_Clay_Beige"
    },
    {
      "x": 4,
      "y": 13,
      "z": 2,
      "name": "Soil_Clay_Beige"
    },
    {
      "x": 4,
      "y": 14,
      "z": 2,
      "name": "Soil_Clay_Beige"
    },
    {
      "x": 4,
      "y": 15,
      "z": 2,
      "name": "Soil_Clay_Black"
    },
    {
      "x": 4,
      "y": 12,
      "z": 3,
      "name": "Soil_Clay_Beige"
    },
    {
      "x": 4,
      "y": 13,
      "z": 3,
      "name": "Soil_Clay_Orange"
    },
    {
      "x": 4,
      "y": 14,
      "z": 3,
      "name": "Soil_Clay_Black"
    },
    {
      "x": 5,
      "y": 13,
      "z": 1,
      "name": "Soil_Clay_Orange"
    },
    {
      "x": 5,
      "y": 12,
      "z": 2,
      "name": "Soil_Clay_Orange"
    },
    {
      "x": 5,
      "y": 13,
      "z": 2,
      "name": "Soil_Clay_Orange"
    },
    {
      "x": 5,
      "y": 14,
      "z": 2,
      "name": "Soil_Clay_Black"
    },
    {
      "x": 5,
      "y": 13,
      "z": 3,
      "name": "Soil_Clay_Orange"
    }
  ]
}