{
  "version": 8,
  "blockIdVersion": 11,
  "anchorX": -2,
  "anchorY": 0,
  "anchorZ": 0,
  "blocks": [
    {
      "x": -4,
      "y": 9,
      "z": -5,
      "name": "Soil_Clay_Smooth_Yellow_Half",
      "rotation": 7
    },
    {
      "x": -4,
      "y": 9,
      "z": -4,
      "name": "Cloth_Block_Wool_White_Half",
      "rotation": 7
    },
    {
      "x": -4,
      "y": 13,
      "z": 7,
      "name": "Soil_Clay_Smooth_Orange_Half",
      "rotation": 7
    },
    {
      "x": -3,
      "y": 9,
      "z": -7,
      "name": "Soil_Clay_Smooth_Yellow_Half",
      "rotation": 6
    },
    {
      "x": -3,
      "y": 8,
      "z": -6,
      "name": "Soil_Clay_Beige"
    },
    {
      "x": -3,
      "y": 9,
      "z": -6,
      "name": "Wood_Beech_Trunk_Full",
      "support": 15,
      "rotation": 4
    },
    {
      "x": -3,
      "y": 10,
      "z": -6,
      "name": "Soil_Clay_Smooth_Orange_Half"
    },
    {
      "x": -3,
      "y": 7,
      "z": -5,
      "name": "Cloth_Block_Wool_White"
    },
    {
      "x": -3,
      "y": 8,
      "z": -5,
      "name": "Soil_Clay_Beige"
    },
    {
      "x": -3,
      "y": 9,
      "z": -5,
      "name": "Wood_Beech_Trunk_Full",
      "support": 15,
      "rotation": 4
    },
    {
      "x": -3,
      "y": 10,
      "z": -5,
      "name": "Soil_Clay_Smooth_Orange_Half"
    },
    {
      "x": -3,
      "y": 8,
      "z": -4,
      "name": "Rock_Crystal_White_Block"
    },
    {
      "x": -3,
      "y": 9,
      "z": -4,
      "name": "Wood_Beech_Trunk_Full",
      "support": 15,
      "rotation": 4
    },
    {
      "x": -3,
      "y": 10,
      "z": -4,
      "name": "Soil_Clay_Smooth_Yellow_Half"
    },
    {
      "x": -3,
      "y": 8,
      "z": -3,
      "name": "Soil_Clay_White"
    },
    {
      "x": -3,
      "y": 9,
      "z": -3,
      "name": "Soil_Clay_Smooth_Yellow_Half",
      "rotation": 4
    },
    {
      "x": -3,
      "y": 8,
      "z": -2,
      "name": "Soil_Clay_Smooth_White_Half",
      "rotation": 4
    },
    {
      "x": -3,
      "y": 13,
      "z": 6,
      "name": "Soil_Clay_Smooth_Yellow_Half",
      "rotation": 7
    },
    {
      "x": -3,
      "y": 12,
      "z": 7,
      "name": "Soil_Clay_Beige"
    },
    {
      "x": -3,
      "y": 13,
      "z": 7,
      "name": "Wood_Beech_Trunk_Full",
      "support": 15,
      "rotation": 5
    },
    {
      "x": -3,
      "y": 14,
      "z": 7,
      "name": "Soil_Clay_Smooth_Orange_Half"
    },
    {
      "x": -3,
      "y": 12,
      "z": 8,
      "name": "Soil_Clay_Beige"
    },
    {
      "x": -3,
      "y": 13,
      "z": 8,
      "name": "Soil_Clay_Orange"
    },
    {
      "x": -2,
      "y": 8,
      "z": -5,
      "name": "Rock_Crystal_White_Block"
    },
    {
      "x": -2,
      "y": 9,
      "z": -5,
      "name": "Soil_Clay_Smooth_Yellow_Half",
      "rotation": 5
    },
    {
      "x": -2,
      "y": 7,
      "z": -4,
      "name": "Soil_Clay_Smooth_White_Half",
      "rotation": 8
    },
    {
      "x": -2,
      "y": 8,
      "z": -4,
      "name": "Wood_Beech_Trunk_Full",
      "support": 15,
      "rotation": 4
    },
    {
      "x": -2,
      "y": 9,
      "z": -4,
      "name": "Soil_Clay_Smooth_Yellow_Half"
    },
    {
      "x": -2,
      "y": 5,
      "z": -3,
      "name": "Cloth_Block_Wool_White"
    },
    {
      "x": -2,
      "y": 6,
      "z": -3,
      "name": "Cloth_Block_Wool_White"
    },
    {
      "x": -2,
      "y": 7,
      "z": -3,
      "name": "Soil_Clay_White"
    },
    {
      "x": -2,
      "y": 8,
      "z": -3,
      "name": "Wood_Beech_Trunk_Full",
      "support": 15,
      "rotation": 4
    },
    {
      "x": -2,
      "y": 9,
      "z": -3,
      "name": "Soil_Clay_Smooth_Yellow_Half"
    },
    {
      "x": -2,
      "y": 7,
      "z": -2,
      "name": "Cloth_Block_Wool_White"
    },
    {
      "x": -2,
      "y": 8,
      "z": -2,
      "name": "Wood_Beech_Trunk_Full",
      "support": 15,
      "rotation": 4
    },
    {
      "x": -2,
      "y": 9,
      "z": -2,
      "name": "Soil_Clay_Smooth_Yellow_Half"
    },
    {
      "x": -2,
      "y": 8,
      "z": -1,
      "name": "Cloth_Block_Wool_White_Half",
      "rotation": 4
    },
    {
      "x": -2,
      "y": 0,
      "z": 0,
      "name": "Wood_Beech_Trunk_Full",
      "support": 15
    },
    {
      "x": -2,
      "y": 1,
      "z": 0,
      "name": "Wood_Beech_Trunk_Full",
      "support": 15
    },
    {
      "x": -2,
      "y": 2,
      "z": 0,
      "name": "Wood_Beech_Trunk_Full",
      "support": 15
    },
    {
      "x": -2,
      "y": 3,
      "z": 0,
      "name": "Wood_Beech_Trunk_Full",
      "support": 15
    },
    {
      "x": -2,
      "y": 5,
      "z": 0,
      "name": "Wood_Beech_Branch_Short",
      "support": 15,
      "rotation": 3
    },
    {
      "x": -2,
      "y": 12,
      "z": 5,
      "name": "Cloth_Block_Wool_White_Half",
      "rotation": 7
    },
    {
      "x": -2,
      "y": 10,
      "z": 6,
      "name": "Soil_Clay_White"
    },
    {
      "x": -2,
      "y": 11,
      "z": 6,
      "name": "Cloth_Block_Wool_White"
    },
    {
      "x": -2,
      "y": 12,
      "z": 6,
      "name": "Rock_Crystal_White_Block"
    },
    {
      "x": -2,
      "y": 13,
      "z": 6,
      "name": "Wood_Beech_Trunk_Full",
      "support": 15
    },
    {
      "x": -2,
      "y": 14,
      "z": 6,
      "name": "Soil_Clay_Smooth_Orange_Half"
    },
    {
      "x": -2,
      "y": 11,
      "z": 7,
      "name": "Cloth_Block_Wool_White"
    },
    {
      "x": -2,
      "y": 12,
      "z": 7,
      "name": "Cloth_Block_Wool_White"
    },
    {
      "x": -2,
      "y": 13,
      "z": 7,
      "name": "Soil_Clay_Beige"
    },
    {
      "x": -1,
      "y": 8,
      "z": -4,
      "name": "Soil_Clay_Smooth_White_Half",
      "rotation": 5
    },
    {
      "x": -1,
      "y": 7,
      "z": -3,
      "name": "Rock_Crystal_White_Block"
    },
    {
      "x": -1,
      "y": 8,
      "z": -3,
      "name": "Cloth_Block_Wool_White_Half",
      "rotation": 5
    },
    {
      "x": -1,
      "y": 6,
      "z": -2,
      "name": "Soil_Clay_White"
    },
    {
      "x": -1,
      "y": 7,
      "z": -2,
      "name": "Wood_Beech_Trunk_Full",
      "support": 15,
      "rotation": 4
    },
    {
      "x": -1,
      "y": 8,
      "z": -2,
      "name": "Soil_Clay_Smooth_White_Half"
    },
    {
      "x": -1,
      "y": 6,
      "z": -1,
      "name": "Cloth_Block_Wool_White_Half",
      "rotation": 8
    },
    {
      "x": -1,
      "y": 7,
      "z": -1,
      "name": "Wood_Beech_Trunk_Full",
      "support": 15,
      "rotation": 4
    },
    {
      "x": -1,
      "y": 1,
      "z": 0,
      "name": "Wood_Beech_Branch_Short",
      "support": 15,
      "rotation": 1
    },
    {
      "x": -1,
      "y": 3,
      "z": 0,
      "name": "Wood_Beech_Trunk_Full",
      "support": 15
    },
    {
      "x": -1,
      "y": 4,
      "z": 0,
      "name": "Wood_Beech_Trunk_Full",
      "support": 15
    },
    {
      "x": -1,
      "y": 5,
      "z": 0,
      "name": "Wood_Beech_Trunk_Full",
      "support": 15
    },
    {
      "x": -1,
      "y": 6,
      "z": 0,
      "name": "Wood_Beech_Trunk_Full",
      "support": 15
    },
    {
      "x": -1,
      "y": 4,
      "z": 3,
      "name": "Cloth_Block_Wool_White_Half",
      "rotation": 7
    },
    {
      "x": -1,
      "y": 12,
      "z": 4,
      "name": "Soil_Clay_Smooth_White_Half",
      "rotation": 6
    },
    {
      "x": -1,
      "y": 11,
      "z": 5,
      "name": "Soil_Clay_White"
    },
    {
      "x": -1,
      "y": 12,
      "z": 5,
      "name": "Wood_Beech_Trunk_Full",
      "support": 15,
      "rotation": 4
    },
    {
      "x": -1,
      "y": 13,
      "z": 5,
      "name": "Soil_Clay_Smooth_Yellow_Half"
    },
    {
      "x": -1,
      "y": 12,
      "z": 6,
      "name": "Cloth_Block_Wool_White"
    },
    {
      "x": -1,
      "y": 13,
      "z": 6,
      "name": "Cloth_Block_Wool_White_Half",
      "rotation": 5
    },
    {
      "x": 0,
      "y": 7,
      "z": -2,
      "name": "Cloth_Block_Wool_White_Half",
      "rotation": 5
    },
    {
      "x": 0,
      "y": 6,
      "z": 0,
      "name": "Wood_Beech_Trunk_Full",
      "support": 15
    },
    {
      "x": 0,
      "y": 7,
      "z": 0,
      "name": "Wood_Beech_Trunk_Full",
      "support": 15
    },
    {
      "x": 0,
      "y": 8,
      "z": 0,
      "name": "Wood_Beech_Trunk_Full",
      "support": 15
    },
    {
      "x": 0,
      "y": 9,
      "z": 0,
      "name": "Wood_Beech_Branch_Short",
      "support": 15,
      "rotation": 2
    },
    {
      "x": 0,
      "y": 4,
      "z": 1,
      "name": "Wood_Beech_Trunk_Full",
      "support": 15,
      "rotation": 4
    },
    {
      "x": 0,
      "y": 8,
      "z": 1,
      "name": "Wood_Beech_Trunk_Full",
      "support": 15
    },
    {
      "x": 0,
      "y": 9,
      "z": 1,
      "name": "Wood_Beech_Trunk_Full",
      "support": 15
    },
    {
      "x": 0,
      "y": 4,
      "z": 2,
      "name": "Wood_Beech_Trunk_Full",
      "support": 15,
      "rotation": 4
    },
    {
      "x": 0,
      "y": 5,
      "z": 2,
      "name": "Cloth_Block_Wool_White_Half"
    },
    {
      "x": 0,
      "y": 9,
      "z": 2,
      "name": "Wood_Beech_Trunk_Full",
      "support": 15
    },
    {
      "x": 0,
      "y": 10,
      "z": 2,
      "name": "Wood_Beech_Trunk_Full",
      "support": 15
    },
    {
      "x": 0,
      "y": 3,
      "z": 3,
      "name": "Soil_Clay_White"
    },
    {
      "x": 0,
      "y": 4,
      "z": 3,
      "name": "Wood_Beech_Trunk_Full",
      "support": 15,
      "rotation": 4
    },
    {
      "x": 0,
      "y": 5,
      "z": 3,
      "name": "Soil_Clay_Smooth_White_Half"
    },
    {
      "x": 0,
      "y": 9,
      "z": 3,
      "name": "Wood_Beech_Branch_Short",
      "support": 15
    },
    {
      "x": 0,
      "y": 12,
      "z": 3,
      "name": "Wood_Beech_Branch_Short",
      "support": 15,
      "rotation": 3
    },
    {
      "x": 0,
      "y": 5,
      "z": 4,
      "name": "Cloth_Block_Wool_White_Half",
      "rotation": 7
    },
    {
      "x": 0,
      "y": 12,
      "z": 4,
      "name": "Wood_Beech_Trunk_Full",
      "support": 15,
      "rotation": 4
    },
    {
      "x": 0,
      "y": 13,
      "z": 4,
      "name": "Cloth_Block_Wool_White_Half"
    },
    {
      "x": 0,
      "y": 5,
      "z": 5,
      "name": "Soil_Clay_Smooth_Yellow_Half",
      "rotation": 7
    },
    {
      "x": 0,
      "y": 12,
      "z": 5,
      "name": "Soil_Clay_Smooth_White_Half",
      "rotation": 5
    },
    {
      "x": 0,
      "y": 5,
      "z": 6,
      "name": "Cloth_Block_Wool_White_Half",
      "rotation": 7
    },
    {
      "x": 1,
      "y": 9,
      "z": 1,
      "name": "Wood_Beech_Branch_Short",
      "support": 15,
      "rotation": 1
    },
    {
      "x": 1,
      "y": 10,
      "z": 2,
      "name": "Wood_Beech_Trunk_Full",
      "support": 15
    },
    {
      "x": 1,
      "y": 11,
      "z": 2,
      "name": "Wood_Beech_Trunk_Full",
      "support": 15
    },
    {
      "x": 1,
      "y": 12,
      "z": 2,
      "name": "Wood_Beech_Trunk_Full",
      "support": 15
    },
    {
      "x": 1,
      "y": 5,
      "z": 3,
      "name": "Soil_Clay_Smooth_White_Half",
      "rotation": 6
    },
    {
      "x": 1,
      "y": 12,
      "z": 3,
      "name": "Wood_Beech_Trunk_Full",
      "support": 15,
      "rotation": 5
    },
    {
      "x": 1,
      "y": 3,
      "z": 4,
      "name": "Cloth_Block_Wool_White"
    },
    {
      "x": 1,
      "y": 4,
      "z": 4,
      "name": "Rock_Crystal_White_Block"
    },
    {
      "x": 1,
      "y": 5,
      "z": 4,
      "name": "Wood_Beech_Trunk_Full",
      "support": 15
    },
    {
      "x": 1,
      "y": 6,
      "z": 4,
      "name": "Soil_Clay_Smooth_White_Half"
    },
    {
      "x": 1,
      "y": 4,
      "z": 5,
      "name": "Soil_Clay_White"
    },
    {
      "x": 1,
      "y": 5,
      "z": 5,
      "name": "Wood_Beech_Trunk_Full",
      "support": 15,
      "rotation": 4
    },
    {
      "x": 1,
      "y": 6,
      "z": 5,
      "name": "Soil_Clay_Beige"
    },
    {
      "x": 1,
      "y": 3,
      "z": 6,
      "name": "Cloth_Block_Wool_White"
    },
    {
      "x": 1,
      "y": 4,
      "z": 6,
      "name": "Cloth_Block_Wool_White"
    },
    {
      "x": 1,
      "y": 5,
      "z": 6,
      "name": "Wood_Beech_Trunk_Full",
      "support": 15,
      "rotation": 4
    },
    {
      "x": 1,
      "y": 6,
      "z": 6,
      "name": "Soil_Clay_Smooth_Yellow_Half"
    },
    {
      "x": 1,
      "y": 5,
      "z": 7,
      "name": "Soil_Clay_Beige"
    },
    {
      "x": 2,
      "y": 13,
      "z": 2,
      "name": "Cloth_Block_Wool_White_Half",
      "rotation": 6
    },
    {
      "x": 2,
      "y": 12,
      "z": 3,
      "name": "Wood_Beech_Trunk_Full",
      "support": 15,
      "rotation": 5
    },
    {
      "x": 2,
      "y": 13,
      "z": 3,
      "name": "Wood_Beech_Trunk_Full",
      "support": 15,
      "rotation": 5
    },
    {
      "x": 2,
      "y": 14,
      "z": 3,
      "name": "Soil_Clay_Smooth_White_Half",
      "rotation": 7
    },
    {
      "x": 2,
      "y": 15,
      "z": 3,
      "name": "Cloth_Block_Wool_White_Half",
      "rotation": 7
    },
    {
      "x": 2,
      "y": 5,
      "z": 4,
      "name": "Cloth_Block_Wool_White_Half",
      "rotation": 5
    },
    {
      "x": 2,
      "y": 15,
      "z": 4,
      "name": "Soil_Clay_Smooth_White_Half",
      "rotation": 7
    },
    {
      "x": 2,
      "y": 16,
      "z": 4,
      "name": "Cloth_Block_Wool_White"
    },
    {
      "x": 2,
      "y": 17,
      "z": 4,
      "name": "Rock_Crystal_White_Block"
    },
    {
      "x": 2,
      "y": 18,
      "z": 4,
      "name": "Soil_Clay_Smooth_Yellow_Half",
      "rotation": 7
    },
    {
      "x": 2,
      "y": 19,
      "z": 4,
      "name": "Soil_Clay_Smooth_Yellow_Half",
      "rotation": 7
    },
    {
      "x": 2,
      "y": 5,
      "z": 5,
      "name": "Soil_Clay_Smooth_Yellow_Half",
      "rotation": 5
    },
    {
      "x": 2,
      "y": 16,
      "z": 5,
      "name": "Soil_Clay_Smooth_White_Half",
      "rotation": 4
    },
    {
      "x": 2,
      "y": 17,
      "z": 5,
      "name": "Soil_Clay_Smooth_White_Half",
      "rotation": 4
    },
    {
      "x": 3,
      "y": 14,
      "z": 2,
      "name": "Wood_Beech_Branch_Short",
      "support": 15,
      "rotation": 2
    },
    {
      "x": 3,
      "y": 15,
      "z": 2,
      "name": "Soil_Clay_Smooth_White_Half",
      "rotation": 6
    },
    {
      "x": 3,
      "y": 13,
      "z": 3,
      "name": "Soil_Clay_Smooth_White_Half",
      "rotation": 5
    },
    {
      "x": 3,
      "y": 14,
      "z": 3,
      "name": "Wood_Beech_Trunk_Full",
      "support": 15
    },
    {
      "x": 3,
      "y": 15,
      "z": 3,
      "name": "Wood_Beech_Trunk_Full",
      "support": 15
    },
    {
      "x": 3,
      "y": 16,
      "z": 3,
      "name": "Soil_Clay_Beige"
    },
    {
      "x": 3,
      "y": 17,
      "z": 3,
      "name": "Soil_Clay_Beige"
    },
    {
      "x": 3,
      "y": 18,
      "z": 3,
      "name": "Soil_Clay_Beige"
    },
    {
      "x": 3,
      "y": 19,
      "z": 3,
      "name": "Soil_Clay_Smooth_Orange_Half",
      "rotation": 6
    },
    {
      "x": 3,
      "y": 15,
      "z": 4,
      "name": "Wood_Beech_Trunk_Full",
      "support": 15
    },
    {
      "x": 3,
      "y": 16,
      "z": 4,
      "name": "Wood_Beech_Trunk_Full",
      "support": 15
    },
    {
      "x": 3,
      "y": 17,
      "z": 4,
      "name": "Wood_Beech_Trunk_Full",
      "support": 15
    },
    {
      "x": 3,
      "y": 18,
      "z": 4,
      "name": "Wood_Beech_Trunk_Full",
      "support": 15
    },
    {
      "x": 3,
      "y": 19,
      "z": 4,
      "name": "Soil_Clay_Orange"
    },
    {
      "x": 3,
      "y": 20,
      "z": 4,
      "name": "Soil_Clay_Orange"
    },
    {
      "x": 3,
      "y": 15,
      "z": 5,
      "name": "Cloth_Block_Wool_White"
    },
    {
      "x": 3,
      "y": 16,
      "z": 5,
      "name": "Cloth_Block_Wool_White"
    },
    {
      "x": 3,
      "y": 17,
      "z": 5,
      "name": "Soil_Clay_Beige"
    },
    {
      "x": 3,
      "y": 18,
      "z": 5,
      "name": "Soil_Clay_Beige"
    },
    {
      "x": 3,
      "y": 19,
      "z": 5,
      "name": "Soil_Clay_Orange"
    },
    {
      "x": 4,
      "y": 14,
      "z": 3,
      "name": "Cloth_Block_Wool_White_Half",
      "rotation": 5
    },
    {
      "x": 4,
      "y": 15,
      "z": 3,
      "name": "Wood_Beech_Branch_Short",
      "support": 15,
      "rotation": 1
    },
    {
      "x": 4,
      "y": 17,
      "z": 3,
      "name": "Cloth_Block_Wool_White_Half",
      "rotation": 6
    },
    {
      "x": 4,
      "y": 18,
      "z": 3,
      "name": "Soil_Clay_Smooth_Yellow_Half",
      "rotation": 6
    },
    {
      "x": 4,
      "y": 13,
      "z": 4,
      "name": "Cloth_Block_Wool_White"
    },
    {
      "x": 4,
      "y": 14,
      "z": 4,
      "name": "Soil_Clay_White"
    },
    {
      "x": 4,
      "y": 15,
      "z": 4,
      "name": "Rock_Crystal_White_Block"
    },
    {
      "x": 4,
      "y": 16,
      "z": 4,
      "name": "Soil_Clay_White"
    },
    {
      "x": 4,
      "y": 17,
      "z": 4,
      "name": "Soil_Clay_Beige"
    },
    {
      "x": 4,
      "y": 18,
      "z": 4,
      "name": "Soil_Clay_Orange"
    },
    {
      "x": 5,
      "y": 16,
      "z": 4,
      "name": "Soil_Clay_Smooth_Yellow_Half",
      "rotation": 5
    }
  ]
}