{
  "version": 8,
  "blockIdVersion": 11,
  "anchorX": 1,
  "anchorY": 3,
  "anchorZ": 1,
  "blocks": [
    {
      "x": -24,
      "y": 0,
      "z": -24,
      "name": "Rock_Basalt_Brick"
    },
    {
      "x": -24,
      "y": 1,
      "z": -24,
      "name": "Rock_Basalt_Brick"
    },
    {
      "x": -24,
      "y": 2,
      "z": -24,
      "name": "Rock_Basalt_Brick"
    },
    {
      "x": -24,
      "y": 3,
      "z": -24,
      "name": "Rock_Basalt_Brick"
    },
    {
      "x": -24,
      "y": 4,
      "z": -24,
      "name": "Rock_Basalt_Brick"
    },
    {
      "x": -24,
      "y": 5,
      "z": -24,
      "name": "Rock_Basalt_Brick"
    },
    {
      "x": -24,
      "y": 6,
      "z": -24,
      "name": "Rock_Basalt_Brick"
    },
    {
      "x": -24,
      "y": 7,
      "z": -24,
      "name": "Rock_Basalt_Brick"
    },
    {
      "x": -24,
      "y": 8,
      "z": -24,
      "name": "Rock_Basalt_Brick"
    },
    {
      "x": -24,
      "y": 9,
      "z": -24,
      "name": "Rock_Basalt_Brick"
    },
    {
      "x": -24,
      "y": 10,
      "z": -24,
      "name": "Rock_Basalt_Brick"
    },
    {
      "x": -24,
      "y": 11,
      "z": -24,
      "name": "Rock_Basalt_Brick"
    },
    {
      "x": -24,
      "y": 12,
      "z": -24,
      "name": "Rock_Basalt_Brick"
    },
    {
      "x": -24,
      "y": 13,
      "z": -24,
      "name": "Rock_Basalt_Brick"
    },
    {
      "x": -24,
      "y": 14,
      "z": -24,
      "name": "Rock_Basalt_Brick"
    },
    {
      "x": -24,
      "y": 0,
      "z": -23,
      "name": "Rock_Basalt_Brick"
    },
    {
      "x": -24,
      "y": 1,
      "z": -23,
      "name": "Rock_Stone_Aqua"
    },
    {
      "x": -24,
      "y": 2,
      "z": -23,
      "name": "Rock_Stone_Aqua"
    },
    {
      "x": -24,
      "y": 3,
      "z": -23,
      "name": "Rock_Stone_Aqua"
    },
    {
      "x": -24,
      "y": 4,
      "z": -23,
      "name": "Rock_Stone_Aqua"
    },
    {
      "x": -24,
      "y": 5,
      "z": -23,
      "name": "Rock_Stone_Aqua"
    },
    {
      "x": -24,
      "y": 6,
      "z": -23,
      "name": "Rock_Stone_Aqua"
    },
    {
      "x": -24,
      "y": 7,
      "z": -23,
      "name": "Rock_Stone_Aqua"
    },
    {
      "x": -24,
      "y": 8,
      "z": -23,
      "name": "Rock_Stone_Aqua"
    },
    {
      "x": -24,
      "y": 9,
      "z": -23,
      "name": "Rock_Stone_Aqua"
    },
    {
      "x": -24,
      "y": 10,
      "z": -23,
      "name": "Rock_Stone_Aqua"
    },
    {
      "x": -24,
      "y": 11,
      "z": -23,
      "name": "Rock_Stone_Aqua"
    },
    {
      "x": -24,
      "y": 12,
      "z": -23,
      "name": "Rock_Stone_Aqua"
    },
    {
      "x": -24,
      "y": 13,
      "z": -23,
      "name": "Rock_Stone_Aqua"
    },
    {
      "x": -24,
      "y": 14,
      "z": -23,
      "name": "Rock_Basalt_Brick"
    },
    {
      "x": -24,
      "y": 0,
      "z": -22,
      "name": "Rock_Basalt_Brick"
    },
    {
      "x": -24,
      "y": 1,
      "z": -22,
      "name": "Rock_Stone_Aqua"
    },
    {
      "x": -24,
      "y": 2,
      "z": -22,
      "name": "Rock_Stone_Aqua"
    },
    {
      "x": -24,
      "y": 3,
      "z": -22,
      "name": "Rock_Stone_Aqua"
    },
    {
      "x": -24,
      "y": 4,
      "z": -22,
      "name": "Rock_Stone_Aqua"
    },
    {
      "x": -24,
      "y": 5,
      "z": -22,
      "name": "Rock_Stone_Aqua"
    },
    {
      "x": -24,
      "y": 6,
      "z": -22,
      "name": "Rock_Stone_Aqua"
    },
    {
      "x": -24,
      "y": 7,
      "z": -22,
      "name": "Rock_Stone_Aqua"
    },
    {
      "x": -24,
      "y": 8,
      "z": -22,
      "name": "Rock_Stone_Aqua"
    },
    {
      "x": -24,
      "y": 9,
      "z": -22,
      "name": "Rock_Stone_Aqua"
    },
    {
      "x": -24,
      "y": 10,
      "z": -22,
      "name": "Rock_Stone_Aqua"
    },
    {
      "x": -24,
      "y": 11,
      "z": -22,
      "name": "Rock_Stone_Aqua"
    },
    {
      "x": -24,
      "y": 12,
      "z": -22,
      "name": "Rock_Stone_Aqua"
    },
    {
      "x": -24,
      "y": 13,
      "z": -22,
      "name": "Rock_Stone_Aqua"
    },
    {
      "x": -24,
      "y": 14,
      "z": -22,
      "name": "Rock_Basalt_Brick"
    },
    {
      "x": -24,
      "y": 0,
      "z": -21,
      "name": "Rock_Basalt_Brick"
    },
    {
      "x": -24,
      "y": 1,
      "z": -21,
      "name": "Rock_Stone_Aqua"
    },
    {
      "x": -24,
      "y": 2,
      "z": -21,
      "name": "Rock_Stone_Aqua"
    },
    {
      "x": -24,
      "y": 3,
      "z": -21,
      "name": "Rock_Stone_Aqua"
    },
    {
      "x": -24,
      "y": 4,
      "z": -21,
      "name": "Rock_Stone_Aqua"
    },
    {
      "x": -24,
      "y": 5,
      "z": -21,
      "name": "Rock_Stone_Aqua"
    },
    {
      "x": -24,
      "y": 6,
      "z": -21,
      "name": "Rock_Stone_Aqua"
    },
    {
      "x": -24,
      "y": 7,
      "z": -21,
      "name": "Rock_Stone_Aqua"
    },
    {
      "x": -24,
      "y": 8,
      "z": -21,
      "name": "Rock_Stone_Aqua"
    },
    {
      "x": -24,
      "y": 9,
      "z": -21,
      "name": "Rock_Stone_Aqua"
    },
    {
      "x": -24,
      "y": 10,
      "z": -21,
      "name": "Rock_Stone_Aqua"
    },
    {
      "x": -24,
      "y": 11,
      "z": -21,
      "name": "Rock_Stone_Aqua"
    },
    {
      "x": -24,
      "y": 12,
      "z": -21,
      "name": "Rock_Stone_Aqua"
    },
    {
      "x": -24,
      "y": 13,
      "z": -21,
      "name": "Rock_Stone_Aqua"
    },
    {
      "x": -24,
      "y": 14,
      "z": -21,
      "name": "Rock_Basalt_Brick"
    },
    {
      "x": -24,
      "y": 0,
      "z": -20,
      "name": "Rock_Basalt_Brick"
    },
    {
      "x": -24,
      "y": 1,
      "z": -20,
      "name": "Rock_Stone_Aqua"
    },
    {
      "x": -24,
      "y": 2,
      "z": -20,
      "name": "Rock_Stone_Aqua"
    },
    {
      "x": -24,
      "y": 3,
      "z": -20,
      "name": "Rock_Stone_Aqua"
    },
    {
      "x": -24,
      "y": 4,
      "z": -20,
      "name": "Rock_Stone_Aqua"
    },
    {
      "x": -24,
      "y": 5,
      "z": -20,
      "name": "Rock_Stone_Aqua"
    },
    {
      "x": -24,
      "y": 6,
      "z": -20,
      "name": "Rock_Stone_Aqua"
    },
    {
      "x": -24,
      "y": 7,
      "z": -20,
      "name": "Rock_Stone_Aqua"
    },
    {
      "x": -24,
      "y": 8,
      "z": -20,
      "name": "Rock_Stone_Aqua"
    },
    {
      "x": -24,
      "y": 9,
      "z": -20,
      "name": "Rock_Stone_Aqua"
    },
    {
      "x": -24,
      "y": 10,
      "z": -20,
      "name": "Rock_Stone_Aqua"
    },
    {
      "x": -24,
      "y": 11,
      "z": -20,
      "name": "Rock_Stone_Aqua"
    },
    {
      "x": -24,
      "y": 12,
      "z": -20,
      "name": "Rock_Stone_Aqua"
    },
    {
      "x": -24,
      "y": 13,
      "z": -20,
      "name": "Rock_Stone_Aqua"
    },
    {
      "x": -24,
      "y": 14,
      "z": -20,
      "name": "Rock_Basalt_Brick"
    },
    {
      "x": -24,
      "y": 0,
      "z": -19,
      "name": "Rock_Basalt_Brick"
    },
    {
      "x": -24,
      "y": 1,
      "z": -19,
      "name": "Rock_Basalt_Brick"
    },
    {
      "x": -24,
      "y": 2,
      "z": -19,
      "name": "Rock_Basalt_Brick"
    },
    {
      "x": -24,
      "y": 3,
      "z": -19,
      "name": "Rock_Basalt_Brick"
    },
    {
      "x": -24,
      "y": 4,
      "z": -19,
      "name": "Rock_Basalt_Brick"
    },
    {
      "x": -24,
      "y": 5,
      "z": -19,
      "name": "Rock_Basalt_Brick"
    },
    {
      "x": -24,
      "y": 6,
      "z": -19,
      "name": "Rock_Basalt_Brick"
    },
    {
      "x": -24,
      "y": 7,
      "z": -19,
      "name": "Rock_Stone_Aqua"
    },
    {
      "x": -24,
      "y": 8,
      "z": -19,
      "name": "Rock_Stone_Aqua"
    },
    {
      "x": -24,
      "y": 9,
      "z": -19,
      "name": "Rock_Stone_Aqua"
    },
    {
      "x": -24,
      "y": 10,
      "z": -19,
      "name": "Rock_Stone_Aqua"
    },
    {
      "x": -24,
      "y": 11,
      "z": -19,
      "name": "Rock_Stone_Aqua"
    },
    {
      "x": -24,
      "y": 12,
      "z": -19,
      "name": "Rock_Stone_Aqua"
    },
    {
      "x": -24,
      "y": 13,
      "z": -19,
      "name": "Rock_Stone_Aqua"
    },
    {
      "x": -24,
      "y": 14,
      "z": -19,
      "name": "Rock_Basalt_Brick"
    },
    {
      "x": -24,
      "y": 0,
      "z": -18,
      "name": "Rock_Basalt_Brick"
    },
    {
      "x": -24,
      "y": 1,
      "z": -18,
      "name": "Rock_Basalt_Brick_Decorative"
    },
    {
      "x": -24,
      "y": 2,
      "z": -18,
      "name": "Rock_Basalt_Brick_Smooth"
    },
    {
      "x": -24,
      "y": 3,
      "z": -18,
      "name": "Rock_Basalt_Brick_Smooth"
    },
    {
      "x": -24,
      "y": 4,
      "z": -18,
      "name": "Rock_Basalt_Brick_Smooth"
    },
    {
      "x": -24,
      "y": 5,
      "z": -18,
      "name": "Rock_Basalt_Brick_Decorative"
    },
    {
      "x": -24,
      "y": 6,
      "z": -18,
      "name": "Rock_Basalt_Brick"
    },
    {
      "x": -24,
      "y": 7,
      "z": -18,
      "name": "Rock_Stone_Aqua"
    },
    {
      "x": -24,
      "y": 8,
      "z": -18,
      "name": "Rock_Stone_Aqua"
    },
    {
      "x": -24,
      "y": 9,
      "z": -18,
      "name": "Rock_Stone_Aqua"
    },
    {
      "x": -24,
      "y": 10,
      "z": -18,
      "name": "Rock_Stone_Aqua"
    },
    {
      "x": -24,
      "y": 11,
      "z": -18,
      "name": "Rock_Stone_Aqua"
    },
    {
      "x": -24,
      "y": 12,
      "z": -18,
      "name": "Rock_Stone_Aqua"
    },
    {
      "x": -24,
      "y": 13,
      "z": -18,
      "name": "Rock_Stone_Aqua"
    },
    {
      "x": -24,
      "y": 14,
      "z": -18,
      "name": "Rock_Basalt_Brick"
    },
    {
      "x": -24,
      "y": 0,
      "z": -17,
      "name": "Rock_Basalt_Brick"
    },
    {
      "x": -24,
      "y": 1,
      "z": -17,
      "name": "Rock_Basalt_Brick_Smooth"
    },
    {
      "x": -24,
      "y": 2,
      "z": -17,
      "name": "Rock_Basalt_Brick_Smooth"
    },
    {
      "x": -24,
      "y": 3,
      "z": -17,
      "name": "Rock_Basalt_Brick_Smooth"
    },
    {
      "x": -24,
      "y": 4,
      "z": -17,
      "name": "Rock_Basalt_Brick_Smooth"
    },
    {
      "x": -24,
      "y": 5,
      "z": -17,
      "name": "Rock_Basalt_Brick_Smooth"
    },
    {
      "x": -24,
      "y": 6,
      "z": -17,
      "name": "Rock_Basalt_Brick"
    },
    {
      "x": -24,
      "y": 7,
      "z": -17,
      "name": "Rock_Stone_Aqua"
    },
    {
      "x": -24,
      "y": 8,
      "z": -17,
      "name": "Rock_Stone_Aqua"
    },
    {
      "x": -24,
      "y": 9,
      "z": -17,
      "name": "Rock_Stone_Aqua"
    },
    {
      "x": -24,
      "y": 10,
      "z": -17,
      "name": "Rock_Stone_Aqua"
    },
    {
      "x": -24,
      "y": 11,
      "z": -17,
      "name": "Rock_Stone_Aqua"
    },
    {
      "x": -24,
      "y": 12,
      "z": -17,
      "name": "Rock_Stone_Aqua"
    },
    {
      "x": -24,
      "y": 13,
      "z": -17,
      "name": "Rock_Stone_Aqua"
    },
    {
      "x": -24,
      "y": 14,
      "z": -17,
      "name": "Rock_Basalt_Brick"
    },
    {
      "x": -24,
      "y": 0,
      "z": -16,
      "name": "Rock_Basalt_Brick"
    },
    {
      "x": -24,
      "y": 1,
      "z": -16,
      "name": "Rock_Basalt_Brick_Smooth"
    },
    {
      "x": -24,
      "y": 2,
      "z": -16,
      "name": "Rock_Basalt_Brick_Smooth"
    },
    {
      "x": -24,
      "y": 3,
      "z": -16,
      "name": "Rock_Basalt_Brick_Smooth"
    },
    {
      "x": -24,
      "y": 4,
      "z": -16,
      "name": "Rock_Basalt_Brick_Smooth"
    },
    {
      "x": -24,
      "y": 5,
      "z": -16,
      "name": "Rock_Basalt_Brick_Smooth"
    },
    {
      "x": -24,
      "y": 6,
      "z": -16,
      "name": "Rock_Basalt_Brick"
    },
    {
      "x": -24,
      "y": 7,
      "z": -16,
      "name": "Rock_Stone_Aqua"
    },
    {
      "x": -24,
      "y": 8,
      "z": -16,
      "name": "Rock_Stone_Aqua"
    },
    {
      "x": -24,
      "y": 9,
      "z": -16,
      "name": "Rock_Stone_Aqua"
    },
    {
      "x": -24,
      "y": 10,
      "z": -16,
      "name": "Rock_Stone_Aqua"
    },
    {
      "x": -24,
      "y": 11,
      "z": -16,
      "name": "Rock_Stone_Aqua"
    },
    {
      "x": -24,
      "y": 12,
      "z": -16,
      "name": "Rock_Stone_Aqua"
    },
    {
      "x": -24,
      "y": 13,
      "z": -16,
      "name": "Rock_Stone_Aqua"
    },
    {
      "x": -24,
      "y": 14,
      "z": -16,
      "name": "Rock_Basalt_Brick"
    },
    {
      "x": -24,
      "y": 0,
      "z": -15,
      "name": "Rock_Basalt_Brick"
    },
    {
      "x": -24,
      "y": 1,
      "z": -15,
      "name": "Rock_Basalt_Brick_Smooth"
    },
    {
      "x": -24,
      "y": 2,
      "z": -15,
      "name": "Rock_Basalt_Brick_Smooth"
    },
    {
      "x": -24,
      "y": 3,
      "z": -15,
      "name": "Rock_Basalt_Brick_Smooth"
    },
    {
      "x": -24,
      "y": 4,
      "z": -15,
      "name": "Rock_Basalt_Brick_Smooth"
    },
    {
      "x": -24,
      "y": 5,
      "z": -15,
      "name": "Rock_Basalt_Brick_Smooth"
    },
    {
      "x": -24,
      "y": 6,
      "z": -15,
      "name": "Rock_Basalt_Brick"
    },
    {
      "x": -24,
      "y": 7,
      "z": -15,
      "name": "Rock_Stone_Aqua"
    },
    {
      "x": -24,
      "y": 8,
      "z": -15,
      "name": "Rock_Stone_Aqua"
    },
    {
      "x": -24,
      "y": 9,
      "z": -15,
      "name": "Rock_Stone_Aqua"
    },
    {
      "x": -24,
      "y": 10,
      "z": -15,
      "name": "Rock_Stone_Aqua"
    },
    {
      "x": -24,
      "y": 11,
      "z": -15,
      "name": "Rock_Stone_Aqua"
    },
    {
      "x": -24,
      "y": 12,
      "z": -15,
      "name": "Rock_Stone_Aqua"
    },
    {
      "x": -24,
      "y": 13,
      "z": -15,
      "name": "Rock_Stone_Aqua"
    },
    {
      "x": -24,
      "y": 14,
      "z": -15,
      "name": "Rock_Basalt_Brick"
    },
    {
      "x": -24,
      "y": 0,
      "z": -14,
      "name": "Rock_Basalt_Brick"
    },
    {
      "x": -24,
      "y": 1,
      "z": -14,
      "name": "Rock_Basalt_Brick_Decorative"
    },
    {
      "x": -24,
      "y": 2,
      "z": -14,
      "name": "Rock_Basalt_Brick_Smooth"
    },
    {
      "x": -24,
      "y": 3,
      "z": -14,
      "name": "Rock_Basalt_Brick_Smooth"
    },
    {
      "x": -24,
      "y": 4,
      "z": -14,
      "name": "Rock_Basalt_Brick_Smooth"
    },
    {
      "x": -24,
      "y": 5,
      "z": -14,
      "name": "Rock_Basalt_Brick_Decorative"
    },
    {
      "x": -24,
      "y": 6,
      "z": -14,
      "name": "Rock_Basalt_Brick"
    },
    {
      "x": -24,
      "y": 7,
      "z": -14,
      "name": "Rock_Stone_Aqua"
    },
    {
      "x": -24,
      "y": 8,
      "z": -14,
      "name": "Rock_Stone_Aqua"
    },
    {
      "x": -24,
      "y": 9,
      "z": -14,
      "name": "Rock_Stone_Aqua"
    },
    {
      "x": -24,
      "y": 10,
      "z": -14,
      "name": "Rock_Stone_Aqua"
    },
    {
      "x": -24,
      "y": 11,
      "z": -14,
      "name": "Rock_Stone_Aqua"
    },
    {
      "x": -24,
      "y": 12,
      "z": -14,
      "name": "Rock_Stone_Aqua"
    },
    {
      "x": -24,
      "y": 13,
      "z": -14,
      "name": "Rock_Stone_Aqua"
    },
    {
      "x": -24,
      "y": 14,
      "z": -14,
      "name": "Rock_Basalt_Brick"
    },
    {
      "x": -24,
      "y": 0,
      "z": -13,
      "name": "Rock_Basalt_Brick"
    },
    {
      "x": -24,
      "y": 1,
      "z": -13,
      "name": "Rock_Basalt_Brick"
    },
    {
      "x": -24,
      "y": 2,
      "z": -13,
      "name": "Rock_Basalt_Brick"
    },
    {
      "x": -24,
      "y": 3,
      "z": -13,
      "name": "Rock_Basalt_Brick"
    },
    {
      "x": -24,
      "y": 4,
      "z": -13,
      "name": "Rock_Basalt_Brick"
    },
    {
      "x": -24,
      "y": 5,
      "z": -13,
      "name": "Rock_Basalt_Brick"
    },
    {
      "x": -24,
      "y": 6,
      "z": -13,
      "name": "Rock_Basalt_Brick"
    },
    {
      "x": -24,
      "y": 7,
      "z": -13,
      "name": "Rock_Stone_Aqua"
    },
    {
      "x": -24,
      "y": 8,
      "z": -13,
      "name": "Rock_Stone_Aqua"
    },
    {
      "x": -24,
      "y": 9,
      "z": -13,
      "name": "Rock_Stone_Aqua"
    },
    {
      "x": -24,
      "y": 10,
      "z": -13,
      "name": "Rock_Stone_Aqua"
    },
    {
      "x": -24,
      "y": 11,
      "z": -13,
      "name": "Rock_Stone_Aqua"
    },
    {
      "x": -24,
      "y": 12,
      "z": -13,
      "name": "Rock_Stone_Aqua"
    },
    {
      "x": -24,
      "y": 13,
      "z": -13,
      "name": "Rock_Stone_Aqua"
    },
    {
      "x": -24,
      "y": 14,
      "z": -13,
      "name": "Rock_Basalt_Brick"
    },
    {
      "x": -24,
      "y": 0,
      "z": -12,
      "name": "Rock_Basalt_Brick"
    },
    {
      "x": -24,
      "y": 1,
      "z": -12,
      "name": "Rock_Stone_Aqua"
    },
    {
      "x": -24,
      "y": 2,
      "z": -12,
      "name": "Rock_Stone_Aqua"
    },
    {
      "x": -24,
      "y": 3,
      "z": -12,
      "name": "Rock_Stone_Aqua"
    },
    {
      "x": -24,
      "y": 4,
      "z": -12,
      "name": "Rock_Stone_Aqua"
    },
    {
      "x": -24,
      "y": 5,
      "z": -12,
      "name": "Rock_Stone_Aqua"
    },
    {
      "x": -24,
      "y": 6,
      "z": -12,
      "name": "Rock_Stone_Aqua"
    },
    {
      "x": -24,
      "y": 7,
      "z": -12,
      "name": "Rock_Stone_Aqua"
    },
    {
      "x": -24,
      "y": 8,
      "z": -12,
      "name": "Rock_Stone_Aqua"
    },
    {
      "x": -24,
      "y": 9,
      "z": -12,
      "name": "Rock_Stone_Aqua"
    },
    {
      "x": -24,
      "y": 10,
      "z": -12,
      "name": "Rock_Stone_Aqua"
    },
    {
      "x": -24,
      "y": 11,
      "z": -12,
      "name": "Rock_Stone_Aqua"
    },
    {
      "x": -24,
      "y": 12,
      "z": -12,
      "name": "Rock_Stone_Aqua"
    },
    {
      "x": -24,
      "y": 13,
      "z": -12,
      "name": "Rock_Stone_Aqua"
    },
    {
      "x": -24,
      "y": 14,
      "z": -12,
      "name": "Rock_Basalt_Brick"
    },
    {
      "x": -24,
      "y": 0,
      "z": -11,
      "name": "Rock_Basalt_Brick"
    },
    {
      "x": -24,
      "y": 1,
      "z": -11,
      "name": "Rock_Stone_Aqua"
    },
    {
      "x": -24,
      "y": 2,
      "z": -11,
      "name": "Rock_Stone_Aqua"
    },
    {
      "x": -24,
      "y": 3,
      "z": -11,
      "name": "Rock_Stone_Aqua"
    },
    {
      "x": -24,
      "y": 4,
      "z": -11,
      "name": "Rock_Stone_Aqua"
    },
    {
      "x": -24,
      "y": 5,
      "z": -11,
      "name": "Rock_Stone_Aqua"
    },
    {
      "x": -24,
      "y": 6,
      "z": -11,
      "name": "Rock_Stone_Aqua"
    },
    {
      "x": -24,
      "y": 7,
      "z": -11,
      "name": "Rock_Stone_Aqua"
    },
    {
      "x": -24,
      "y": 8,
      "z": -11,
      "name": "Rock_Stone_Aqua"
    },
    {
      "x": -24,
      "y": 9,
      "z": -11,
      "name": "Rock_Stone_Aqua"
    },
    {
      "x": -24,
      "y": 10,
      "z": -11,
      "name": "Rock_Stone_Aqua"
    },
    {
      "x": -24,
      "y": 11,
      "z": -11,
      "name": "Rock_Stone_Aqua"
    },
    {
      "x": -24,
      "y": 12,
      "z": -11,
      "name": "Rock_Stone_Aqua"
    },
    {
      "x": -24,
      "y": 13,
      "z": -11,
      "name": "Rock_Stone_Aqua"
    },
    {
      "x": -24,
      "y": 14,
      "z": -11,
      "name": "Rock_Basalt_Brick"
    },
    {
      "x": -24,
      "y": 0,
      "z": -10,
      "name": "Rock_Basalt_Brick"
    },
    {
      "x": -24,
      "y": 1,
      "z": -10,
      "name": "Rock_Stone_Aqua"
    },
    {
      "x": -24,
      "y": 2,
      "z": -10,
      "name": "Rock_Stone_Aqua"
    },
    {
      "x": -24,
      "y": 3,
      "z": -10,
      "name": "Rock_Stone_Aqua"
    },
    {
      "x": -24,
      "y": 4,
      "z": -10,
      "name": "Rock_Stone_Aqua"
    },
    {
      "x": -24,
      "y": 5,
      "z": -10,
      "name": "Rock_Stone_Aqua"
    },
    {
      "x": -24,
      "y": 6,
      "z": -10,
      "name": "Rock_Stone_Aqua"
    },
    {
      "x": -24,
      "y": 7,
      "z": -10,
      "name": "Rock_Stone_Aqua"
    },
    {
      "x": -24,
      "y": 8,
      "z": -10,
      "name": "Rock_Stone_Aqua"
    },
    {
      "x": -24,
      "y": 9,
      "z": -10,
      "name": "Rock_Stone_Aqua"
    },
    {
      "x": -24,
      "y": 10,
      "z": -10,
      "name": "Rock_Stone_Aqua"
    },
    {
      "x": -24,
      "y": 11,
      "z": -10,
      "name": "Rock_Stone_Aqua"
    },
    {
      "x": -24,
      "y": 12,
      "z": -10,
      "name": "Rock_Stone_Aqua"
    },
    {
      "x": -24,
      "y": 13,
      "z": -10,
      "name": "Rock_Stone_Aqua"
    },
    {
      "x": -24,
      "y": 14,
      "z": -10,
      "name": "Rock_Basalt_Brick"
    },
    {
      "x": -24,
      "y": 0,
      "z": -9,
      "name": "Rock_Basalt_Brick"
    },
    {
      "x": -24,
      "y": 1,
      "z": -9,
      "name": "Rock_Stone_Aqua"
    },
    {
      "x": -24,
      "y": 2,
      "z": -9,
      "name": "Rock_Stone_Aqua"
    },
    {
      "x": -24,
      "y": 3,
      "z": -9,
      "name": "Rock_Stone_Aqua"
    },
    {
      "x": -24,
      "y": 4,
      "z": -9,
      "name": "Rock_Stone_Aqua"
    },
    {
      "x": -24,
      "y": 5,
      "z": -9,
      "name": "Rock_Stone_Aqua"
    },
    {
      "x": -24,
      "y": 6,
      "z": -9,
      "name": "Rock_Stone_Aqua"
    },
    {
      "x": -24,
      "y": 7,
      "z": -9,
      "name": "Rock_Stone_Aqua"
    },
    {
      "x": -24,
      "y": 8,
      "z": -9,
      "name": "Rock_Stone_Aqua"
    },
    {
      "x": -24,
      "y": 9,
      "z": -9,
      "name": "Rock_Stone_Aqua"
    },
    {
      "x": -24,
      "y": 10,
      "z": -9,
      "name": "Rock_Stone_Aqua"
    },
    {
      "x": -24,
      "y": 11,
      "z": -9,
      "name": "Rock_Stone_Aqua"
    },
    {
      "x": -24,
      "y": 12,
      "z": -9,
      "name": "Rock_Stone_Aqua"
    },
    {
      "x": -24,
      "y": 13,
      "z": -9,
      "name": "Rock_Stone_Aqua"
    },
    {
      "x": -24,
      "y": 14,
      "z": -9,
      "name": "Rock_Basalt_Brick"
    },
    {
      "x": -24,
      "y": 0,
      "z": -8,
      "name": "Rock_Basalt_Brick"
    },
    {
      "x": -24,
      "y": 1,
      "z": -8,
      "name": "Rock_Stone_Aqua"
    },
    {
      "x": -24,
      "y": 2,
      "z": -8,
      "name": "Rock_Stone_Aqua"
    },
    {
      "x": -24,
      "y": 3,
      "z": -8,
      "name": "Rock_Stone_Aqua"
    },
    {
      "x": -24,
      "y": 4,
      "z": -8,
      "name": "Rock_Stone_Aqua"
    },
    {
      "x": -24,
      "y": 5,
      "z": -8,
      "name": "Rock_Stone_Aqua"
    },
    {
      "x": -24,
      "y": 6,
      "z": -8,
      "name": "Rock_Stone_Aqua"
    },
    {
      "x": -24,
      "y": 7,
      "z": -8,
      "name": "Rock_Stone_Aqua"
    },
    {
      "x": -24,
      "y": 8,
      "z": -8,
      "name": "Rock_Stone_Aqua"
    },
    {
      "x": -24,
      "y": 9,
      "z": -8,
      "name": "Rock_Stone_Aqua"
    },
    {
      "x": -24,
      "y": 10,
      "z": -8,
      "name": "Rock_Stone_Aqua"
    },
    {
      "x": -24,
      "y": 11,
      "z": -8,
      "name": "Rock_Stone_Aqua"
    },
    {
      "x": -24,
      "y": 12,
      "z": -8,
      "name": "Rock_Stone_Aqua"
    },
    {
      "x": -24,
      "y": 13,
      "z": -8,
      "name": "Rock_Stone_Aqua"
    },
    {
      "x": -24,
      "y": 14,
      "z": -8,
      "name": "Rock_Basalt_Brick"
    },
    {
      "x": -24,
      "y": 0,
      "z": -7,
      "name": "Rock_Basalt_Brick"
    },
    {
      "x": -24,
      "y": 1,
      "z": -7,
      "name": "Rock_Stone_Aqua"
    },
    {
      "x": -24,
      "y": 2,
      "z": -7,
      "name": "Rock_Stone_Aqua"
    },
    {
      "x": -24,
      "y": 3,
      "z": -7,
      "name": "Rock_Stone_Aqua"
    },
    {
      "x": -24,
      "y": 4,
      "z": -7,
      "name": "Rock_Stone_Aqua"
    },
    {
      "x": -24,
      "y": 5,
      "z": -7,
      "name": "Rock_Stone_Aqua"
    },
    {
      "x": -24,
      "y": 6,
      "z": -7,
      "name": "Rock_Stone_Aqua"
    },
    {
      "x": -24,
      "y": 7,
      "z": -7,
      "name": "Rock_Stone_Aqua"
    },
    {
      "x": -24,
      "y": 8,
      "z": -7,
      "name": "Rock_Stone_Aqua"
    },
    {
      "x": -24,
      "y": 9,
      "z": -7,
      "name": "Rock_Stone_Aqua"
    },
    {
      "x": -24,
      "y": 10,
      "z": -7,
      "name": "Rock_Stone_Aqua"
    },
    {
      "x": -24,
      "y": 11,
      "z": -7,
      "name": "Rock_Stone_Aqua"
    },
    {
      "x": -24,
      "y": 12,
      "z": -7,
      "name": "Rock_Stone_Aqua"
    },
    {
      "x": -24,
      "y": 13,
      "z": -7,
      "name": "Rock_Stone_Aqua"
    },
    {
      "x": -24,
      "y": 14,
      "z": -7,
      "name": "Rock_Basalt_Brick"
    },
    {
      "x": -24,
      "y": 0,
      "z": -6,
      "name": "Rock_Basalt_Brick"
    },
    {
      "x": -24,
      "y": 1,
      "z": -6,
      "name": "Rock_Stone_Aqua"
    },
    {
      "x": -24,
      "y": 2,
      "z": -6,
      "name": "Rock_Stone_Aqua"
    },
    {
      "x": -24,
      "y": 3,
      "z": -6,
      "name": "Rock_Stone_Aqua"
    },
    {
      "x": -24,
      "y": 4,
      "z": -6,
      "name": "Rock_Stone_Aqua"
    },
    {
      "x": -24,
      "y": 5,
      "z": -6,
      "name": "Rock_Stone_Aqua"
    },
    {
      "x": -24,
      "y": 6,
      "z": -6,
      "name": "Rock_Stone_Aqua"
    },
    {
      "x": -24,
      "y": 7,
      "z": -6,
      "name": "Rock_Stone_Aqua"
    },
    {
      "x": -24,
      "y": 8,
      "z": -6,
      "name": "Rock_Stone_Aqua"
    },
    {
      "x": -24,
      "y": 9,
      "z": -6,
      "name": "Rock_Stone_Aqua"
    },
    {
      "x": -24,
      "y": 10,
      "z": -6,
      "name": "Rock_Stone_Aqua"
    },
    {
      "x": -24,
      "y": 11,
      "z": -6,
      "name": "Rock_Stone_Aqua"
    },
    {
      "x": -24,
      "y": 12,
      "z": -6,
      "name": "Rock_Stone_Aqua"
    },
    {
      "x": -24,
      "y": 13,
      "z": -6,
      "name": "Rock_Stone_Aqua"
    },
    {
      "x": -24,
      "y": 14,
      "z": -6,
      "name": "Rock_Basalt_Brick"
    },
    {
      "x": -24,
      "y": 0,
      "z": -5,
      "name": "Rock_Basalt_Brick"
    },
    {
      "x": -24,
      "y": 1,
      "z": -5,
      "name": "Rock_Stone_Aqua"
    },
    {
      "x": -24,
      "y": 2,
      "z": -5,
      "name": "Rock_Stone_Aqua"
    },
    {
      "x": -24,
      "y": 3,
      "z": -5,
      "name": "Rock_Stone_Aqua"
    },
    {
      "x": -24,
      "y": 4,
      "z": -5,
      "name": "Rock_Stone_Aqua"
    },
    {
      "x": -24,
      "y": 5,
      "z": -5,
      "name": "Rock_Stone_Aqua"
    },
    {
      "x": -24,
      "y": 6,
      "z": -5,
      "name": "Rock_Stone_Aqua"
    },
    {
      "x": -24,
      "y": 7,
      "z": -5,
      "name": "Rock_Stone_Aqua"
    },
    {
      "x": -24,
      "y": 8,
      "z": -5,
      "name": "Rock_Stone_Aqua"
    },
    {
      "x": -24,
      "y": 9,
      "z": -5,
      "name": "Rock_Stone_Aqua"
    },
    {
      "x": -24,
      "y": 10,
      "z": -5,
      "name": "Rock_Stone_Aqua"
    },
    {
      "x": -24,
      "y": 11,
      "z": -5,
      "name": "Rock_Stone_Aqua"
    },
    {
      "x": -24,
      "y": 12,
      "z": -5,
      "name": "Rock_Stone_Aqua"
    },
    {
      "x": -24,
      "y": 13,
      "z": -5,
      "name": "Rock_Stone_Aqua"
    },
    {
      "x": -24,
      "y": 14,
      "z": -5,
      "name": "Rock_Basalt_Brick"
    },
    {
      "x": -24,
      "y": 0,
      "z": -4,
      "name": "Rock_Basalt_Brick"
    },
    {
      "x": -24,
      "y": 1,
      "z": -4,
      "name": "Rock_Stone_Aqua"
    },
    {
      "x": -24,
      "y": 2,
      "z": -4,
      "name": "Rock_Stone_Aqua"
    },
    {
      "x": -24,
      "y": 3,
      "z": -4,
      "name": "Rock_Stone_Aqua"
    },
    {
      "x": -24,
      "y": 4,
      "z": -4,
      "name": "Rock_Stone_Aqua"
    },
    {
      "x": -24,
      "y": 5,
      "z": -4,
      "name": "Rock_Stone_Aqua"
    },
    {
      "x": -24,
      "y": 6,
      "z": -4,
      "name": "Rock_Stone_Aqua"
    },
    {
      "x": -24,
      "y": 7,
      "z": -4,
      "name": "Rock_Stone_Aqua"
    },
    {
      "x": -24,
      "y": 8,
      "z": -4,
      "name": "Rock_Stone_Aqua"
    },
    {
      "x": -24,
      "y": 9,
      "z": -4,
      "name": "Rock_Stone_Aqua"
    },
    {
      "x": -24,
      "y": 10,
      "z": -4,
      "name": "Rock_Stone_Aqua"
    },
    {
      "x": -24,
      "y": 11,
      "z": -4,
      "name": "Rock_Stone_Aqua"
    },
    {
      "x": -24,
      "y": 12,
      "z": -4,
      "name": "Rock_Stone_Aqua"
    },
    {
      "x": -24,
      "y": 13,
      "z": -4,
      "name": "Rock_Stone_Aqua"
    },
    {
      "x": -24,
      "y": 14,
      "z": -4,
      "name": "Rock_Basalt_Brick"
    },
    {
      "x": -24,
      "y": 0,
      "z": -3,
      "name": "Rock_Basalt_Brick"
    },
    {
      "x": -24,
      "y": 1,
      "z": -3,
      "name": "Rock_Stone_Aqua"
    },
    {
      "x": -24,
      "y": 2,
      "z": -3,
      "name": "Rock_Stone_Aqua"
    },
    {
      "x": -24,
      "y": 3,
      "z": -3,
      "name": "Rock_Stone_Aqua"
    },
    {
      "x": -24,
      "y": 4,
      "z": -3,
      "name": "Rock_Stone_Aqua"
    },
    {
      "x": -24,
      "y": 5,
      "z": -3,
      "name": "Rock_Stone_Aqua"
    },
    {
      "x": -24,
      "y": 6,
      "z": -3,
      "name": "Rock_Stone_Aqua"
    },
    {
      "x": -24,
      "y": 7,
      "z": -3,
      "name": "Rock_Stone_Aqua"
    },
    {
      "x": -24,
      "y": 8,
      "z": -3,
      "name": "Rock_Stone_Aqua"
    },
    {
      "x": -24,
      "y": 9,
      "z": -3,
      "name": "Rock_Stone_Aqua"
    },
    {
      "x": -24,
      "y": 10,
      "z": -3,
      "name": "Rock_Stone_Aqua"
    },
    {
      "x": -24,
      "y": 11,
      "z": -3,
      "name": "Rock_Stone_Aqua"
    },
    {
      "x": -24,
      "y": 12,
      "z": -3,
      "name": "Rock_Stone_Aqua"
    },
    {
      "x": -24,
      "y": 13,
      "z": -3,
      "name": "Rock_Stone_Aqua"
    },
    {
      "x": -24,
      "y": 14,
      "z": -3,
      "name": "Rock_Basalt_Brick"
    },
    {
      "x": -24,
      "y": 0,
      "z": -2,
      "name": "Rock_Basalt_Brick"
    },
    {
      "x": -24,
      "y": 1,
      "z": -2,
      "name": "Rock_Basalt_Brick"
    },
    {
      "x": -24,
      "y": 2,
      "z": -2,
      "name": "Rock_Basalt_Brick"
    },
    {
      "x": -24,
      "y": 3,
      "z": -2,
      "name": "Rock_Basalt_Brick"
    },
    {
      "x": -24,
      "y": 4,
      "z": -2,
      "name": "Rock_Basalt_Brick"
    },
    {
      "x": -24,
      "y": 5,
      "z": -2,
      "name": "Rock_Basalt_Brick"
    },
    {
      "x": -24,
      "y": 6,
      "z": -2,
      "name": "Rock_Basalt_Brick"
    },
    {
      "x": -24,
      "y": 7,
      "z": -2,
      "name": "Rock_Stone_Aqua"
    },
    {
      "x": -24,
      "y": 8,
      "z": -2,
      "name": "Rock_Stone_Aqua"
    },
    {
      "x": -24,
      "y": 9,
      "z": -2,
      "name": "Rock_Stone_Aqua"
    },
    {
      "x": -24,
      "y": 10,
      "z": -2,
      "name": "Rock_Stone_Aqua"
    },
    {
      "x": -24,
      "y": 11,
      "z": -2,
      "name": "Rock_Stone_Aqua"
    },
    {
      "x": -24,
      "y": 12,
      "z": -2,
      "name": "Rock_Stone_Aqua"
    },
    {
      "x": -24,
      "y": 13,
      "z": -2,
      "name": "Rock_Stone_Aqua"
    },
    {
      "x": -24,
      "y": 14,
      "z": -2,
      "name": "Rock_Basalt_Brick"
    },
    {
      "x": -24,
      "y": 0,
      "z": -1,
      "name": "Rock_Basalt_Brick"
    },
    {
      "x": -24,
      "y": 1,
      "z": -1,
      "name": "Rock_Basalt_Brick_Decorative"
    },
    {
      "x": -24,
      "y": 2,
      "z": -1,
      "name": "Rock_Basalt_Brick_Smooth"
    },
    {
      "x": -24,
      "y": 3,
      "z": -1,
      "name": "Rock_Basalt_Brick_Smooth"
    },
    {
      "x": -24,
      "y": 4,
      "z": -1,
      "name": "Rock_Basalt_Brick_Smooth"
    },
    {
      "x": -24,
      "y": 5,
      "z": -1,
      "name": "Rock_Basalt_Brick_Decorative"
    },
    {
      "x": -24,
      "y": 6,
      "z": -1,
      "name": "Rock_Basalt_Brick"
    },
    {
      "x": -24,
      "y": 7,
      "z": -1,
      "name": "Rock_Stone_Aqua"
    },
    {
      "x": -24,
      "y": 8,
      "z": -1,
      "name": "Rock_Stone_Aqua"
    },
    {
      "x": -24,
      "y": 9,
      "z": -1,
      "name": "Rock_Stone_Aqua"
    },
    {
      "x": -24,
      "y": 10,
      "z": -1,
      "name": "Rock_Stone_Aqua"
    },
    {
      "x": -24,
      "y": 11,
      "z": -1,
      "name": "Rock_Stone_Aqua"
    },
    {
      "x": -24,
      "y": 12,
      "z": -1,
      "name": "Rock_Stone_Aqua"
    },
    {
      "x": -24,
      "y": 13,
      "z": -1,
      "name": "Rock_Stone_Aqua"
    },
    {
      "x": -24,
      "y": 14,
      "z": -1,
      "name": "Rock_Basalt_Brick"
    },
    {
      "x": -24,
      "y": 0,
      "z": 0,
      "name": "Rock_Basalt_Brick"
    },
    {
      "x": -24,
      "y": 1,
      "z": 0,
      "name": "Rock_Basalt_Brick_Smooth"
    },
    {
      "x": -24,
      "y": 2,
      "z": 0,
      "name": "Rock_Basalt_Brick_Smooth"
    },
    {
      "x": -24,
      "y": 3,
      "z": 0,
      "name": "Rock_Basalt_Brick_Smooth"
    },
    {
      "x": -24,
      "y": 4,
      "z": 0,
      "name": "Rock_Basalt_Brick_Smooth"
    },
    {
      "x": -24,
      "y": 5,
      "z": 0,
      "name": "Rock_Basalt_Brick_Smooth"
    },
    {
      "x": -24,
      "y": 6,
      "z": 0,
      "name": "Rock_Basalt_Brick"
    },
    {
      "x": -24,
      "y": 7,
      "z": 0,
      "name": "Rock_Stone_Aqua"
    },
    {
      "x": -24,
      "y": 8,
      "z": 0,
      "name": "Rock_Stone_Aqua"
    },
    {
      "x": -24,
      "y": 9,
      "z": 0,
      "name": "Rock_Stone_Aqua"
    },
    {
      "x": -24,
      "y": 10,
      "z": 0,
      "name": "Rock_Stone_Aqua"
    },
    {
      "x": -24,
      "y": 11,
      "z": 0,
      "name": "Rock_Stone_Aqua"
    },
    {
      "x": -24,
      "y": 12,
      "z": 0,
      "name": "Rock_Stone_Aqua"
    },
    {
      "x": -24,
      "y": 13,
      "z": 0,
      "name": "Rock_Stone_Aqua"
    },
    {
      "x": -24,
      "y": 14,
      "z": 0,
      "name": "Rock_Basalt_Brick"
    },
    {
      "x": -24,
      "y": 0,
      "z": 1,
      "name": "Rock_Basalt_Brick"
    },
    {
      "x": -24,
      "y": 1,
      "z": 1,
      "name": "Rock_Basalt_Brick_Smooth"
    },
    {
      "x": -24,
      "y": 2,
      "z": 1,
      "name": "Rock_Basalt_Brick_Smooth"
    },
    {
      "x": -24,
      "y": 3,
      "z": 1,
      "name": "Rock_Basalt_Brick_Smooth"
    },
    {
      "x": -24,
      "y": 4,
      "z": 1,
      "name": "Rock_Basalt_Brick_Smooth"
    },
    {
      "x": -24,
      "y": 5,
      "z": 1,
      "name": "Rock_Basalt_Brick_Smooth"
    },
    {
      "x": -24,
      "y": 6,
      "z": 1,
      "name": "Rock_Basalt_Brick"
    },
    {
      "x": -24,
      "y": 7,
      "z": 1,
      "name": "Rock_Basalt_Brick"
    },
    {
      "x": -24,
      "y": 8,
      "z": 1,
      "name": "Rock_Basalt_Brick"
    },
    {
      "x": -24,
      "y": 9,
      "z": 1,
      "name": "Rock_Basalt_Brick"
    },
    {
      "x": -24,
      "y": 10,
      "z": 1,
      "name": "Rock_Basalt_Brick"
    },
    {
      "x": -24,
      "y": 11,
      "z": 1,
      "name": "Rock_Basalt_Brick"
    },
    {
      "x": -24,
      "y": 12,
      "z": 1,
      "name": "Rock_Basalt_Brick"
    },
    {
      "x": -24,
      "y": 13,
      "z": 1,
      "name": "Rock_Basalt_Brick"
    },
    {
      "x": -24,
      "y": 14,
      "z": 1,
      "name": "Rock_Basalt_Brick"
    },
    {
      "x": -24,
      "y": 0,
      "z": 2,
      "name": "Rock_Basalt_Brick"
    },
    {
      "x": -24,
      "y": 1,
      "z": 2,
      "name": "Rock_Basalt_Brick_Smooth"
    },
    {
      "x": -24,
      "y": 2,
      "z": 2,
      "name": "Rock_Basalt_Brick_Smooth"
    },
    {
      "x": -24,
      "y": 3,
      "z": 2,
      "name": "Rock_Basalt_Brick_Smooth"
    },
    {
      "x": -24,
      "y": 4,
      "z": 2,
      "name": "Rock_Basalt_Brick_Smooth"
    },
    {
      "x": -24,
      "y": 5,
      "z": 2,
      "name": "Rock_Basalt_Brick_Smooth"
    },
    {
      "x": -24,
      "y": 6,
      "z": 2,
      "name": "Rock_Basalt_Brick"
    },
    {
      "x": -24,
      "y": 7,
      "z": 2,
      "name": "Rock_Stone_Aqua"
    },
    {
      "x": -24,
      "y": 8,
      "z": 2,
      "name": "Rock_Stone_Aqua"
    },
    {
      "x": -24,
      "y": 9,
      "z": 2,
      "name": "Rock_Stone_Aqua"
    },
    {
      "x": -24,
      "y": 10,
      "z": 2,
      "name": "Rock_Stone_Aqua"
    },
    {
      "x": -24,
      "y": 11,
      "z": 2,
      "name": "Rock_Stone_Aqua"
    },
    {
      "x": -24,
      "y": 12,
      "z": 2,
      "name": "Rock_Stone_Aqua"
    },
    {
      "x": -24,
      "y": 13,
      "z": 2,
      "name": "Rock_Stone_Aqua"
    },
    {
      "x": -24,
      "y": 14,
      "z": 2,
      "name": "Rock_Basalt_Brick"
    },
    {
      "x": -24,
      "y": 0,
      "z": 3,
      "name": "Rock_Basalt_Brick"
    },
    {
      "x": -24,
      "y": 1,
      "z": 3,
      "name": "Rock_Basalt_Brick_Decorative"
    },
    {
      "x": -24,
      "y": 2,
      "z": 3,
      "name": "Rock_Basalt_Brick_Smooth"
    },
    {
      "x": -24,
      "y": 3,
      "z": 3,
      "name": "Rock_Basalt_Brick_Smooth"
    },
    {
      "x": -24,
      "y": 4,
      "z": 3,
      "name": "Rock_Basalt_Brick_Smooth"
    },
    {
      "x": -24,
      "y": 5,
      "z": 3,
      "name": "Rock_Basalt_Brick_Decorative"
    },
    {
      "x": -24,
      "y": 6,
      "z": 3,
      "name": "Rock_Basalt_Brick"
    },
    {
      "x": -24,
      "y": 7,
      "z": 3,
      "name": "Rock_Stone_Aqua"
    },
    {
      "x": -24,
      "y": 8,
      "z": 3,
      "name": "Rock_Stone_Aqua"
    },
    {
      "x": -24,
      "y": 9,
      "z": 3,
      "name": "Rock_Stone_Aqua"
    },
    {
      "x": -24,
      "y": 10,
      "z": 3,
      "name": "Rock_Stone_Aqua"
    },
    {
      "x": -24,
      "y": 11,
      "z": 3,
      "name": "Rock_Stone_Aqua"
    },
    {
      "x": -24,
      "y": 12,
      "z": 3,
      "name": "Rock_Stone_Aqua"
    },
    {
      "x": -24,
      "y": 13,
      "z": 3,
      "name": "Rock_Stone_Aqua"
    },
    {
      "x": -24,
      "y": 14,
      "z": 3,
      "name": "Rock_Basalt_Brick"
    },
    {
      "x": -24,
      "y": 0,
      "z": 4,
      "name": "Rock_Basalt_Brick"
    },
    {
      "x": -24,
      "y": 1,
      "z": 4,
      "name": "Rock_Basalt_Brick"
    },
    {
      "x": -24,
      "y": 2,
      "z": 4,
      "name": "Rock_Basalt_Brick"
    },
    {
      "x": -24,
      "y": 3,
      "z": 4,
      "name": "Rock_Basalt_Brick"
    },
    {
      "x": -24,
      "y": 4,
      "z": 4,
      "name": "Rock_Basalt_Brick"
    },
    {
      "x": -24,
      "y": 5,
      "z": 4,
      "name": "Rock_Basalt_Brick"
    },
    {
      "x": -24,
      "y": 6,
      "z": 4,
      "name": "Rock_Basalt_Brick"
    },
    {
      "x": -24,
      "y": 7,
      "z": 4,
      "name": "Rock_Stone_Aqua"
    },
    {
      "x": -24,
      "y": 8,
      "z": 4,
      "name": "Rock_Stone_Aqua"
    },
    {
      "x": -24,
      "y": 9,
      "z": 4,
      "name": "Rock_Stone_Aqua"
    },
    {
      "x": -24,
      "y": 10,
      "z": 4,
      "name": "Rock_Stone_Aqua"
    },
    {
      "x": -24,
      "y": 11,
      "z": 4,
      "name": "Rock_Stone_Aqua"
    },
    {
      "x": -24,
      "y": 12,
      "z": 4,
      "name": "Rock_Stone_Aqua"
    },
    {
      "x": -24,
      "y": 13,
      "z": 4,
      "name": "Rock_Stone_Aqua"
    },
    {
      "x": -24,
      "y": 14,
      "z": 4,
      "name": "Rock_Basalt_Brick"
    },
    {
      "x": -24,
      "y": 0,
      "z": 5,
      "name": "Rock_Basalt_Brick"
    },
    {
      "x": -24,
      "y": 1,
      "z": 5,
      "name": "Rock_Stone_Aqua"
    },
    {
      "x": -24,
      "y": 2,
      "z": 5,
      "name": "Rock_Stone_Aqua"
    },
    {
      "x": -24,
      "y": 3,
      "z": 5,
      "name": "Rock_Stone_Aqua"
    },
    {
      "x": -24,
      "y": 4,
      "z": 5,
      "name": "Rock_Stone_Aqua"
    },
    {
      "x": -24,
      "y": 5,
      "z": 5,
      "name": "Rock_Stone_Aqua"
    },
    {
      "x": -24,
      "y": 6,
      "z": 5,
      "name": "Rock_Stone_Aqua"
    },
    {
      "x": -24,
      "y": 7,
      "z": 5,
      "name": "Rock_Stone_Aqua"
    },
    {
      "x": -24,
      "y": 8,
      "z": 5,
      "name": "Rock_Stone_Aqua"
    },
    {
      "x": -24,
      "y": 9,
      "z": 5,
      "name": "Rock_Stone_Aqua"
    },
    {
      "x": -24,
      "y": 10,
      "z": 5,
      "name": "Rock_Stone_Aqua"
    },
    {
      "x": -24,
      "y": 11,
      "z": 5,
      "name": "Rock_Stone_Aqua"
    },
    {
      "x": -24,
      "y": 12,
      "z": 5,
      "name": "Rock_Stone_Aqua"
    },
    {
      "x": -24,
      "y": 13,
      "z": 5,
      "name": "Rock_Stone_Aqua"
    },
    {
      "x": -24,
      "y": 14,
      "z": 5,
      "name": "Rock_Basalt_Brick"
    },
    {
      "x": -24,
      "y": 0,
      "z": 6,
      "name": "Rock_Basalt_Brick"
    },
    {
      "x": -24,
      "y": 1,
      "z": 6,
      "name": "Rock_Stone_Aqua"
    },
    {
      "x": -24,
      "y": 2,
      "z": 6,
      "name": "Rock_Stone_Aqua"
    },
    {
      "x": -24,
      "y": 3,
      "z": 6,
      "name": "Rock_Stone_Aqua"
    },
    {
      "x": -24,
      "y": 4,
      "z": 6,
      "name": "Rock_Stone_Aqua"
    },
    {
      "x": -24,
      "y": 5,
      "z": 6,
      "name": "Rock_Stone_Aqua"
    },
    {
      "x": -24,
      "y": 6,
      "z": 6,
      "name": "Rock_Stone_Aqua"
    },
    {
      "x": -24,
      "y": 7,
      "z": 6,
      "name": "Rock_Stone_Aqua"
    },
    {
      "x": -24,
      "y": 8,
      "z": 6,
      "name": "Rock_Stone_Aqua"
    },
    {
      "x": -24,
      "y": 9,
      "z": 6,
      "name": "Rock_Stone_Aqua"
    },
    {
      "x": -24,
      "y": 10,
      "z": 6,
      "name": "Rock_Stone_Aqua"
    },
    {
      "x": -24,
      "y": 11,
      "z": 6,
      "name": "Rock_Stone_Aqua"
    },
    {
      "x": -24,
      "y": 12,
      "z": 6,
      "name": "Rock_Stone_Aqua"
    },
    {
      "x": -24,
      "y": 13,
      "z": 6,
      "name": "Rock_Stone_Aqua"
    },
    {
      "x": -24,
      "y": 14,
      "z": 6,
      "name": "Rock_Basalt_Brick"
    },
    {
      "x": -24,
      "y": 0,
      "z": 7,
      "name": "Rock_Basalt_Brick"
    },
    {
      "x": -24,
      "y": 1,
      "z": 7,
      "name": "Rock_Stone_Aqua"
    },
    {
      "x": -24,
      "y": 2,
      "z": 7,
      "name": "Rock_Stone_Aqua"
    },
    {
      "x": -24,
      "y": 3,
      "z": 7,
      "name": "Rock_Stone_Aqua"
    },
    {
      "x": -24,
      "y": 4,
      "z": 7,
      "name": "Rock_Stone_Aqua"
    },
    {
      "x": -24,
      "y": 5,
      "z": 7,
      "name": "Rock_Stone_Aqua"
    },
    {
      "x": -24,
      "y": 6,
      "z": 7,
      "name": "Rock_Stone_Aqua"
    },
    {
      "x": -24,
      "y": 7,
      "z": 7,
      "name": "Rock_Stone_Aqua"
    },
    {
      "x": -24,
      "y": 8,
      "z": 7,
      "name": "Rock_Stone_Aqua"
    },
    {
      "x": -24,
      "y": 9,
      "z": 7,
      "name": "Rock_Stone_Aqua"
    },
    {
      "x": -24,
      "y": 10,
      "z": 7,
      "name": "Rock_Stone_Aqua"
    },
    {
      "x": -24,
      "y": 11,
      "z": 7,
      "name": "Rock_Stone_Aqua"
    },
    {
      "x": -24,
      "y": 12,
      "z": 7,
      "name": "Rock_Stone_Aqua"
    },
    {
      "x": -24,
      "y": 13,
      "z": 7,
      "name": "Rock_Stone_Aqua"
    },
    {
      "x": -24,
      "y": 14,
      "z": 7,
      "name": "Rock_Basalt_Brick"
    },
    {
      "x": -24,
      "y": 0,
      "z": 8,
      "name": "Rock_Basalt_Brick"
    },
    {
      "x": -24,
      "y": 1,
      "z": 8,
      "name": "Rock_Stone_Aqua"
    },
    {
      "x": -24,
      "y": 2,
      "z": 8,
      "name": "Rock_Stone_Aqua"
    },
    {
      "x": -24,
      "y": 3,
      "z": 8,
      "name": "Rock_Stone_Aqua"
    },
    {
      "x": -24,
      "y": 4,
      "z": 8,
      "name": "Rock_Stone_Aqua"
    },
    {
      "x": -24,
      "y": 5,
      "z": 8,
      "name": "Rock_Stone_Aqua"
    },
    {
      "x": -24,
      "y": 6,
      "z": 8,
      "name": "Rock_Stone_Aqua"
    },
    {
      "x": -24,
      "y": 7,
      "z": 8,
      "name": "Rock_Stone_Aqua"
    },
    {
      "x": -24,
      "y": 8,
      "z": 8,
      "name": "Rock_Stone_Aqua"
    },
    {
      "x": -24,
      "y": 9,
      "z": 8,
      "name": "Rock_Stone_Aqua"
    },
    {
      "x": -24,
      "y": 10,
      "z": 8,
      "name": "Rock_Stone_Aqua"
    },
    {
      "x": -24,
      "y": 11,
      "z": 8,
      "name": "Rock_Stone_Aqua"
    },
    {
      "x": -24,
      "y": 12,
      "z": 8,
      "name": "Rock_Stone_Aqua"
    },
    {
      "x": -24,
      "y": 13,
      "z": 8,
      "name": "Rock_Stone_Aqua"
    },
    {
      "x": -24,
      "y": 14,
      "z": 8,
      "name": "Rock_Basalt_Brick"
    },
    {
      "x": -24,
      "y": 0,
      "z": 9,
      "name": "Rock_Basalt_Brick"
    },
    {
      "x": -24,
      "y": 1,
      "z": 9,
      "name": "Rock_Stone_Aqua"
    },
    {
      "x": -24,
      "y": 2,
      "z": 9,
      "name": "Rock_Stone_Aqua"
    },
    {
      "x": -24,
      "y": 3,
      "z": 9,
      "name": "Rock_Stone_Aqua"
    },
    {
      "x": -24,
      "y": 4,
      "z": 9,
      "name": "Rock_Stone_Aqua"
    },
    {
      "x": -24,
      "y": 5,
      "z": 9,
      "name": "Rock_Stone_Aqua"
    },
    {
      "x": -24,
      "y": 6,
      "z": 9,
      "name": "Rock_Stone_Aqua"
    },
    {
      "x": -24,
      "y": 7,
      "z": 9,
      "name": "Rock_Stone_Aqua"
    },
    {
      "x": -24,
      "y": 8,
      "z": 9,
      "name": "Rock_Stone_Aqua"
    },
    {
      "x": -24,
      "y": 9,
      "z": 9,
      "name": "Rock_Stone_Aqua"
    },
    {
      "x": -24,
      "y": 10,
      "z": 9,
      "name": "Rock_Stone_Aqua"
    },
    {
      "x": -24,
      "y": 11,
      "z": 9,
      "name": "Rock_Stone_Aqua"
    },
    {
      "x": -24,
      "y": 12,
      "z": 9,
      "name": "Rock_Stone_Aqua"
    },
    {
      "x": -24,
      "y": 13,
      "z": 9,
      "name": "Rock_Stone_Aqua"
    },
    {
      "x": -24,
      "y": 14,
      "z": 9,
      "name": "Rock_Basalt_Brick"
    },
    {
      "x": -24,
      "y": 0,
      "z": 10,
      "name": "Rock_Basalt_Brick"
    },
    {
      "x": -24,
      "y": 1,
      "z": 10,
      "name": "Rock_Stone_Aqua"
    },
    {
      "x": -24,
      "y": 2,
      "z": 10,
      "name": "Rock_Stone_Aqua"
    },
    {
      "x": -24,
      "y": 3,
      "z": 10,
      "name": "Rock_Stone_Aqua"
    },
    {
      "x": -24,
      "y": 4,
      "z": 10,
      "name": "Rock_Stone_Aqua"
    },
    {
      "x": -24,
      "y": 5,
      "z": 10,
      "name": "Rock_Stone_Aqua"
    },
    {
      "x": -24,
      "y": 6,
      "z": 10,
      "name": "Rock_Stone_Aqua"
    },
    {
      "x": -24,
      "y": 7,
      "z": 10,
      "name": "Rock_Stone_Aqua"
    },
    {
      "x": -24,
      "y": 8,
      "z": 10,
      "name": "Rock_Stone_Aqua"
    },
    {
      "x": -24,
      "y": 9,
      "z": 10,
      "name": "Rock_Stone_Aqua"
    },
    {
      "x": -24,
      "y": 10,
      "z": 10,
      "name": "Rock_Stone_Aqua"
    },
    {
      "x": -24,
      "y": 11,
      "z": 10,
      "name": "Rock_Stone_Aqua"
    },
    {
      "x": -24,
      "y": 12,
      "z": 10,
      "name": "Rock_Stone_Aqua"
    },
    {
      "x": -24,
      "y": 13,
      "z": 10,
      "name": "Rock_Stone_Aqua"
    },
    {
      "x": -24,
      "y": 14,
      "z": 10,
      "name": "Rock_Basalt_Brick"
    },
    {
      "x": -24,
      "y": 0,
      "z": 11,
      "name": "Rock_Basalt_Brick"
    },
    {
      "x": -24,
      "y": 1,
      "z": 11,
      "name": "Rock_Stone_Aqua"
    },
    {
      "x": -24,
      "y": 2,
      "z": 11,
      "name": "Rock_Stone_Aqua"
    },
    {
      "x": -24,
      "y": 3,
      "z": 11,
      "name": "Rock_Stone_Aqua"
    },
    {
      "x": -24,
      "y": 4,
      "z": 11,
      "name": "Rock_Stone_Aqua"
    },
    {
      "x": -24,
      "y": 5,
      "z": 11,
      "name": "Rock_Stone_Aqua"
    },
    {
      "x": -24,
      "y": 6,
      "z": 11,
      "name": "Rock_Stone_Aqua"
    },
    {
      "x": -24,
      "y": 7,
      "z": 11,
      "name": "Rock_Stone_Aqua"
    },
    {
      "x": -24,
      "y": 8,
      "z": 11,
      "name": "Rock_Stone_Aqua"
    },
    {
      "x": -24,
      "y": 9,
      "z": 11,
      "name": "Rock_Stone_Aqua"
    },
    {
      "x": -24,
      "y": 10,
      "z": 11,
      "name": "Rock_Stone_Aqua"
    },
    {
      "x": -24,
      "y": 11,
      "z": 11,
      "name": "Rock_Stone_Aqua"
    },
    {
      "x": -24,
      "y": 12,
      "z": 11,
      "name": "Rock_Stone_Aqua"
    },
    {
      "x": -24,
      "y": 13,
      "z": 11,
      "name": "Rock_Stone_Aqua"
    },
    {
      "x": -24,
      "y": 14,
      "z": 11,
      "name": "Rock_Basalt_Brick"
    },
    {
      "x": -24,
      "y": 0,
      "z": 12,
      "name": "Rock_Basalt_Brick"
    },
    {
      "x": -24,
      "y": 1,
      "z": 12,
      "name": "Rock_Stone_Aqua"
    },
    {
      "x": -24,
      "y": 2,
      "z": 12,
      "name": "Rock_Stone_Aqua"
    },
    {
      "x": -24,
      "y": 3,
      "z": 12,
      "name": "Rock_Stone_Aqua"
    },
    {
      "x": -24,
      "y": 4,
      "z": 12,
      "name": "Rock_Stone_Aqua"
    },
    {
      "x": -24,
      "y": 5,
      "z": 12,
      "name": "Rock_Stone_Aqua"
    },
    {
      "x": -24,
      "y": 6,
      "z": 12,
      "name": "Rock_Stone_Aqua"
    },
    {
      "x": -24,
      "y": 7,
      "z": 12,
      "name": "Rock_Stone_Aqua"
    },
    {
      "x": -24,
      "y": 8,
      "z": 12,
      "name": "Rock_Stone_Aqua"
    },
    {
      "x": -24,
      "y": 9,
      "z": 12,
      "name": "Rock_Stone_Aqua"
    },
    {
      "x": -24,
      "y": 10,
      "z": 12,
      "name": "Rock_Stone_Aqua"
    },
    {
      "x": -24,
      "y": 11,
      "z": 12,
      "name": "Rock_Stone_Aqua"
    },
    {
      "x": -24,
      "y": 12,
      "z": 12,
      "name": "Rock_Stone_Aqua"
    },
    {
      "x": -24,
      "y": 13,
      "z": 12,
      "name": "Rock_Stone_Aqua"
    },
    {
      "x": -24,
      "y": 14,
      "z": 12,
      "name": "Rock_Basalt_Brick"
    },
    {
      "x": -24,
      "y": 0,
      "z": 13,
      "name": "Rock_Basalt_Brick"
    },
    {
      "x": -24,
      "y": 1,
      "z": 13,
      "name": "Rock_Stone_Aqua"
    },
    {
      "x": -24,
      "y": 2,
      "z": 13,
      "name": "Rock_Stone_Aqua"
    },
    {
      "x": -24,
      "y": 3,
      "z": 13,
      "name": "Rock_Stone_Aqua"
    },
    {
      "x": -24,
      "y": 4,
      "z": 13,
      "name": "Rock_Stone_Aqua"
    },
    {
      "x": -24,
      "y": 5,
      "z": 13,
      "name": "Rock_Stone_Aqua"
    },
    {
      "x": -24,
      "y": 6,
      "z": 13,
      "name": "Rock_Stone_Aqua"
    },
    {
      "x": -24,
      "y": 7,
      "z": 13,
      "name": "Rock_Stone_Aqua"
    },
    {
      "x": -24,
      "y": 8,
      "z": 13,
      "name": "Rock_Stone_Aqua"
    },
    {
      "x": -24,
      "y": 9,
      "z": 13,
      "name": "Rock_Stone_Aqua"
    },
    {
      "x": -24,
      "y": 10,
      "z": 13,
      "name": "Rock_Stone_Aqua"
    },
    {
      "x": -24,
      "y": 11,
      "z": 13,
      "name": "Rock_Stone_Aqua"
    },
    {
      "x": -24,
      "y": 12,
      "z": 13,
      "name": "Rock_Stone_Aqua"
    },
    {
      "x": -24,
      "y": 13,
      "z": 13,
      "name": "Rock_Stone_Aqua"
    },
    {
      "x": -24,
      "y": 14,
      "z": 13,
      "name": "Rock_Basalt_Brick"
    },
    {
      "x": -24,
      "y": 0,
      "z": 14,
      "name": "Rock_Basalt_Brick"
    },
    {
      "x": -24,
      "y": 1,
      "z": 14,
      "name": "Rock_Stone_Aqua"
    },
    {
      "x": -24,
      "y": 2,
      "z": 14,
      "name": "Rock_Stone_Aqua"
    },
    {
      "x": -24,
      "y": 3,
      "z": 14,
      "name": "Rock_Stone_Aqua"
    },
    {
      "x": -24,
      "y": 4,
      "z": 14,
      "name": "Rock_Stone_Aqua"
    },
    {
      "x": -24,
      "y": 5,
      "z": 14,
      "name": "Rock_Stone_Aqua"
    },
    {
      "x": -24,
      "y": 6,
      "z": 14,
      "name": "Rock_Stone_Aqua"
    },
    {
      "x": -24,
      "y": 7,
      "z": 14,
      "name": "Rock_Stone_Aqua"
    },
    {
      "x": -24,
      "y": 8,
      "z": 14,
      "name": "Rock_Stone_Aqua"
    },
    {
      "x": -24,
      "y": 9,
      "z": 14,
      "name": "Rock_Stone_Aqua"
    },
    {
      "x": -24,
      "y": 10,
      "z": 14,
      "name": "Rock_Stone_Aqua"
    },
    {
      "x": -24,
      "y": 11,
      "z": 14,
      "name": "Rock_Stone_Aqua"
    },
    {
      "x": -24,
      "y": 12,
      "z": 14,
      "name": "Rock_Stone_Aqua"
    },
    {
      "x": -24,
      "y": 13,
      "z": 14,
      "name": "Rock_Stone_Aqua"
    },
    {
      "x": -24,
      "y": 14,
      "z": 14,
      "name": "Rock_Basalt_Brick"
    },
    {
      "x": -24,
      "y": 0,
      "z": 15,
      "name": "Rock_Basalt_Brick"
    },
    {
      "x": -24,
      "y": 1,
      "z": 15,
      "name": "Rock_Basalt_Brick"
    },
    {
      "x": -24,
      "y": 2,
      "z": 15,
      "name": "Rock_Basalt_Brick"
    },
    {
      "x": -24,
      "y": 3,
      "z": 15,
      "name": "Rock_Basalt_Brick"
    },
    {
      "x": -24,
      "y": 4,
      "z": 15,
      "name": "Rock_Basalt_Brick"
    },
    {
      "x": -24,
      "y": 5,
      "z": 15,
      "name": "Rock_Basalt_Brick"
    },
    {
      "x": -24,
      "y": 6,
      "z": 15,
      "name": "Rock_Basalt_Brick"
    },
    {
      "x": -24,
      "y": 7,
      "z": 15,
      "name": "Rock_Stone_Aqua"
    },
    {
      "x": -24,
      "y": 8,
      "z": 15,
      "name": "Rock_Stone_Aqua"
    },
    {
      "x": -24,
      "y": 9,
      "z": 15,
      "name": "Rock_Stone_Aqua"
    },
    {
      "x": -24,
      "y": 10,
      "z": 15,
      "name": "Rock_Stone_Aqua"
    },
    {
      "x": -24,
      "y": 11,
      "z": 15,
      "name": "Rock_Stone_Aqua"
    },
    {
      "x": -24,
      "y": 12,
      "z": 15,
      "name": "Rock_Stone_Aqua"
    },
    {
      "x": -24,
      "y": 13,
      "z": 15,
      "name": "Rock_Stone_Aqua"
    },
    {
      "x": -24,
      "y": 14,
      "z": 15,
      "name": "Rock_Basalt_Brick"
    },
    {
      "x": -24,
      "y": 0,
      "z": 16,
      "name": "Rock_Basalt_Brick"
    },
    {
      "x": -24,
      "y": 1,
      "z": 16,
      "name": "Rock_Basalt_Brick_Decorative"
    },
    {
      "x": -24,
      "y": 2,
      "z": 16,
      "name": "Rock_Basalt_Brick_Smooth"
    },
    {
      "x": -24,
      "y": 3,
      "z": 16,
      "name": "Rock_Basalt_Brick_Smooth"
    },
    {
      "x": -24,
      "y": 4,
      "z": 16,
      "name": "Rock_Basalt_Brick_Smooth"
    },
    {
      "x": -24,
      "y": 5,
      "z": 16,
      "name": "Rock_Basalt_Brick_Decorative"
    },
    {
      "x": -24,
      "y": 6,
      "z": 16,
      "name": "Rock_Basalt_Brick"
    },
    {
      "x": -24,
      "y": 7,
      "z": 16,
      "name": "Rock_Stone_Aqua"
    },
    {
      "x": -24,
      "y": 8,
      "z": 16,
      "name": "Rock_Stone_Aqua"
    },
    {
      "x": -24,
      "y": 9,
      "z": 16,
      "name": "Rock_Stone_Aqua"
    },
    {
      "x": -24,
      "y": 10,
      "z": 16,
      "name": "Rock_Stone_Aqua"
    },
    {
      "x": -24,
      "y": 11,
      "z": 16,
      "name": "Rock_Stone_Aqua"
    },
    {
      "x": -24,
      "y": 12,
      "z": 16,
      "name": "Rock_Stone_Aqua"
    },
    {
      "x": -24,
      "y": 13,
      "z": 16,
      "name": "Rock_Stone_Aqua"
    },
    {
      "x": -24,
      "y": 14,
      "z": 16,
      "name": "Rock_Basalt_Brick"
    },
    {
      "x": -24,
      "y": 0,
      "z": 17,
      "name": "Rock_Basalt_Brick"
    },
    {
      "x": -24,
      "y": 1,
      "z": 17,
      "name": "Rock_Basalt_Brick_Smooth"
    },
    {
      "x": -24,
      "y": 2,
      "z": 17,
      "name": "Rock_Basalt_Brick_Smooth"
    },
    {
      "x": -24,
      "y": 3,
      "z": 17,
      "name": "Rock_Basalt_Brick_Smooth"
    },
    {
      "x": -24,
      "y": 4,
      "z": 17,
      "name": "Rock_Basalt_Brick_Smooth"
    },
    {
      "x": -24,
      "y": 5,
      "z": 17,
      "name": "Rock_Basalt_Brick_Smooth"
    },
    {
      "x": -24,
      "y": 6,
      "z": 17,
      "name": "Rock_Basalt_Brick"
    },
    {
      "x": -24,
      "y": 7,
      "z": 17,
      "name": "Rock_Stone_Aqua"
    },
    {
      "x": -24,
      "y": 8,
      "z": 17,
      "name": "Rock_Stone_Aqua"
    },
    {
      "x": -24,
      "y": 9,
      "z": 17,
      "name": "Rock_Stone_Aqua"
    },
    {
      "x": -24,
      "y": 10,
      "z": 17,
      "name": "Rock_Stone_Aqua"
    },
    {
      "x": -24,
      "y": 11,
      "z": 17,
      "name": "Rock_Stone_Aqua"
    },
    {
      "x": -24,
      "y": 12,
      "z": 17,
      "name": "Rock_Stone_Aqua"
    },
    {
      "x": -24,
      "y": 13,
      "z": 17,
      "name": "Rock_Stone_Aqua"
    },
    {
      "x": -24,
      "y": 14,
      "z": 17,
      "name": "Rock_Basalt_Brick"
    },
    {
      "x": -24,
      "y": 0,
      "z": 18,
      "name": "Rock_Basalt_Brick"
    },
    {
      "x": -24,
      "y": 1,
      "z": 18,
      "name": "Rock_Basalt_Brick_Smooth"
    },
    {
      "x": -24,
      "y": 2,
      "z": 18,
      "name": "Rock_Basalt_Brick_Smooth"
    },
    {
      "x": -24,
      "y": 3,
      "z": 18,
      "name": "Rock_Basalt_Brick_Smooth"
    },
    {
      "x": -24,
      "y": 4,
      "z": 18,
      "name": "Rock_Basalt_Brick_Smooth"
    },
    {
      "x": -24,
      "y": 5,
      "z": 18,
      "name": "Rock_Basalt_Brick_Smooth"
    },
    {
      "x": -24,
      "y": 6,
      "z": 18,
      "name": "Rock_Basalt_Brick"
    },
    {
      "x": -24,
      "y": 7,
      "z": 18,
      "name": "Rock_Stone_Aqua"
    },
    {
      "x": -24,
      "y": 8,
      "z": 18,
      "name": "Rock_Stone_Aqua"
    },
    {
      "x": -24,
      "y": 9,
      "z": 18,
      "name": "Rock_Stone_Aqua"
    },
    {
      "x": -24,
      "y": 10,
      "z": 18,
      "name": "Rock_Stone_Aqua"
    },
    {
      "x": -24,
      "y": 11,
      "z": 18,
      "name": "Rock_Stone_Aqua"
    },
    {
      "x": -24,
      "y": 12,
      "z": 18,
      "name": "Rock_Stone_Aqua"
    },
    {
      "x": -24,
      "y": 13,
      "z": 18,
      "name": "Rock_Stone_Aqua"
    },
    {
      "x": -24,
      "y": 14,
      "z": 18,
      "name": "Rock_Basalt_Brick"
    },
    {
      "x": -24,
      "y": 0,
      "z": 19,
      "name": "Rock_Basalt_Brick"
    },
    {
      "x": -24,
      "y": 1,
      "z": 19,
      "name": "Rock_Basalt_Brick_Smooth"
    },
    {
      "x": -24,
      "y": 2,
      "z": 19,
      "name": "Rock_Basalt_Brick_Smooth"
    },
    {
      "x": -24,
      "y": 3,
      "z": 19,
      "name": "Rock_Basalt_Brick_Smooth"
    },
    {
      "x": -24,
      "y": 4,
      "z": 19,
      "name": "Rock_Basalt_Brick_Smooth"
    },
    {
      "x": -24,
      "y": 5,
      "z": 19,
      "name": "Rock_Basalt_Brick_Smooth"
    },
    {
      "x": -24,
      "y": 6,
      "z": 19,
      "name": "Rock_Basalt_Brick"
    },
    {
      "x": -24,
      "y": 7,
      "z": 19,
      "name": "Rock_Stone_Aqua"
    },
    {
      "x": -24,
      "y": 8,
      "z": 19,
      "name": "Rock_Stone_Aqua"
    },
    {
      "x": -24,
      "y": 9,
      "z": 19,
      "name": "Rock_Stone_Aqua"
    },
    {
      "x": -24,
      "y": 10,
      "z": 19,
      "name": "Rock_Stone_Aqua"
    },
    {
      "x": -24,
      "y": 11,
      "z": 19,
      "name": "Rock_Stone_Aqua"
    },
    {
      "x": -24,
      "y": 12,
      "z": 19,
      "name": "Rock_Stone_Aqua"
    },
    {
      "x": -24,
      "y": 13,
      "z": 19,
      "name": "Rock_Stone_Aqua"
    },
    {
      "x": -24,
      "y": 14,
      "z": 19,
      "name": "Rock_Basalt_Brick"
    },
    {
      "x": -24,
      "y": 0,
      "z": 20,
      "name": "Rock_Basalt_Brick"
    },
    {
      "x": -24,
      "y": 1,
      "z": 20,
      "name": "Rock_Basalt_Brick_Decorative"
    },
    {
      "x": -24,
      "y": 2,
      "z": 20,
      "name": "Rock_Basalt_Brick_Smooth"
    },
    {
      "x": -24,
      "y": 3,
      "z": 20,
      "name": "Rock_Basalt_Brick_Smooth"
    },
    {
      "x": -24,
      "y": 4,
      "z": 20,
      "name": "Rock_Basalt_Brick_Smooth"
    },
    {
      "x": -24,
      "y": 5,
      "z": 20,
      "name": "Rock_Basalt_Brick_Decorative"
    },
    {
      "x": -24,
      "y": 6,
      "z": 20,
      "name": "Rock_Basalt_Brick"
    },
    {
      "x": -24,
      "y": 7,
      "z": 20,
      "name": "Rock_Stone_Aqua"
    },
    {
      "x": -24,
      "y": 8,
      "z": 20,
      "name": "Rock_Stone_Aqua"
    },
    {
      "x": -24,
      "y": 9,
      "z": 20,
      "name": "Rock_Stone_Aqua"
    },
    {
      "x": -24,
      "y": 10,
      "z": 20,
      "name": "Rock_Stone_Aqua"
    },
    {
      "x": -24,
      "y": 11,
      "z": 20,
      "name": "Rock_Stone_Aqua"
    },
    {
      "x": -24,
      "y": 12,
      "z": 20,
      "name": "Rock_Stone_Aqua"
    },
    {
      "x": -24,
      "y": 13,
      "z": 20,
      "name": "Rock_Stone_Aqua"
    },
    {
      "x": -24,
      "y": 14,
      "z": 20,
      "name": "Rock_Basalt_Brick"
    },
    {
      "x": -24,
      "y": 0,
      "z": 21,
      "name": "Rock_Basalt_Brick"
    },
    {
      "x": -24,
      "y": 1,
      "z": 21,
      "name": "Rock_Basalt_Brick"
    },
    {
      "x": -24,
      "y": 2,
      "z": 21,
      "name": "Rock_Basalt_Brick"
    },
    {
      "x": -24,
      "y": 3,
      "z": 21,
      "name": "Rock_Basalt_Brick"
    },
    {
      "x": -24,
      "y": 4,
      "z": 21,
      "name": "Rock_Basalt_Brick"
    },
    {
      "x": -24,
      "y": 5,
      "z": 21,
      "name": "Rock_Basalt_Brick"
    },
    {
      "x": -24,
      "y": 6,
      "z": 21,
      "name": "Rock_Basalt_Brick"
    },
    {
      "x": -24,
      "y": 7,
      "z": 21,
      "name": "Rock_Stone_Aqua"
    },
    {
      "x": -24,
      "y": 8,
      "z": 21,
      "name": "Rock_Stone_Aqua"
    },
    {
      "x": -24,
      "y": 9,
      "z": 21,
      "name": "Rock_Stone_Aqua"
    },
    {
      "x": -24,
      "y": 10,
      "z": 21,
      "name": "Rock_Stone_Aqua"
    },
    {
      "x": -24,
      "y": 11,
      "z": 21,
      "name": "Rock_Stone_Aqua"
    },
    {
      "x": -24,
      "y": 12,
      "z": 21,
      "name": "Rock_Stone_Aqua"
    },
    {
      "x": -24,
      "y": 13,
      "z": 21,
      "name": "Rock_Stone_Aqua"
    },
    {
      "x": -24,
      "y": 14,
      "z": 21,
      "name": "Rock_Basalt_Brick"
    },
    {
      "x": -24,
      "y": 0,
      "z": 22,
      "name": "Rock_Basalt_Brick"
    },
    {
      "x": -24,
      "y": 1,
      "z": 22,
      "name": "Rock_Stone_Aqua"
    },
    {
      "x": -24,
      "y": 2,
      "z": 22,
      "name": "Rock_Stone_Aqua"
    },
    {
      "x": -24,
      "y": 3,
      "z": 22,
      "name": "Rock_Stone_Aqua"
    },
    {
      "x": -24,
      "y": 4,
      "z": 22,
      "name": "Rock_Stone_Aqua"
    },
    {
      "x": -24,
      "y": 5,
      "z": 22,
      "name": "Rock_Stone_Aqua"
    },
    {
      "x": -24,
      "y": 6,
      "z": 22,
      "name": "Rock_Stone_Aqua"
    },
    {
      "x": -24,
      "y": 7,
      "z": 22,
      "name": "Rock_Stone_Aqua"
    },
    {
      "x": -24,
      "y": 8,
      "z": 22,
      "name": "Rock_Stone_Aqua"
    },
    {
      "x": -24,
      "y": 9,
      "z": 22,
      "name": "Rock_Stone_Aqua"
    },
    {
      "x": -24,
      "y": 10,
      "z": 22,
      "name": "Rock_Stone_Aqua"
    },
    {
      "x": -24,
      "y": 11,
      "z": 22,
      "name": "Rock_Stone_Aqua"
    },
    {
      "x": -24,
      "y": 12,
      "z": 22,
      "name": "Rock_Stone_Aqua"
    },
    {
      "x": -24,
      "y": 13,
      "z": 22,
      "name": "Rock_Stone_Aqua"
    },
    {
      "x": -24,
      "y": 14,
      "z": 22,
      "name": "Rock_Basalt_Brick"
    },
    {
      "x": -24,
      "y": 0,
      "z": 23,
      "name": "Rock_Basalt_Brick"
    },
    {
      "x": -24,
      "y": 1,
      "z": 23,
      "name": "Rock_Stone_Aqua"
    },
    {
      "x": -24,
      "y": 2,
      "z": 23,
      "name": "Rock_Stone_Aqua"
    },
    {
      "x": -24,
      "y": 3,
      "z": 23,
      "name": "Rock_Stone_Aqua"
    },
    {
      "x": -24,
      "y": 4,
      "z": 23,
      "name": "Rock_Stone_Aqua"
    },
    {
      "x": -24,
      "y": 5,
      "z": 23,
      "name": "Rock_Stone_Aqua"
    },
    {
      "x": -24,
      "y": 6,
      "z": 23,
      "name": "Rock_Stone_Aqua"
    },
    {
      "x": -24,
      "y": 7,
      "z": 23,
      "name": "Rock_Stone_Aqua"
    },
    {
      "x": -24,
      "y": 8,
      "z": 23,
      "name": "Rock_Stone_Aqua"
    },
    {
      "x": -24,
      "y": 9,
      "z": 23,
      "name": "Rock_Stone_Aqua"
    },
    {
      "x": -24,
      "y": 10,
      "z": 23,
      "name": "Rock_Stone_Aqua"
    },
    {
      "x": -24,
      "y": 11,
      "z": 23,
      "name": "Rock_Stone_Aqua"
    },
    {
      "x": -24,
      "y": 12,
      "z": 23,
      "name": "Rock_Stone_Aqua"
    },
    {
      "x": -24,
      "y": 13,
      "z": 23,
      "name": "Rock_Stone_Aqua"
    },
    {
      "x": -24,
      "y": 14,
      "z": 23,
      "name": "Rock_Basalt_Brick"
    },
    {
      "x": -24,
      "y": 0,
      "z": 24,
      "name": "Rock_Basalt_Brick"
    },
    {
      "x": -24,
      "y": 1,
      "z": 24,
      "name": "Rock_Stone_Aqua"
    },
    {
      "x": -24,
      "y": 2,
      "z": 24,
      "name": "Rock_Stone_Aqua"
    },
    {
      "x": -24,
      "y": 3,
      "z": 24,
      "name": "Rock_Stone_Aqua"
    },
    {
      "x": -24,
      "y": 4,
      "z": 24,
      "name": "Rock_Stone_Aqua"
    },
    {
      "x": -24,
      "y": 5,
      "z": 24,
      "name": "Rock_Stone_Aqua"
    },
    {
      "x": -24,
      "y": 6,
      "z": 24,
      "name": "Rock_Stone_Aqua"
    },
    {
      "x": -24,
      "y": 7,
      "z": 24,
      "name": "Rock_Stone_Aqua"
    },
    {
      "x": -24,
      "y": 8,
      "z": 24,
      "name": "Rock_Stone_Aqua"
    },
    {
      "x": -24,
      "y": 9,
      "z": 24,
      "name": "Rock_Stone_Aqua"
    },
    {
      "x": -24,
      "y": 10,
      "z": 24,
      "name": "Rock_Stone_Aqua"
    },
    {
      "x": -24,
      "y": 11,
      "z": 24,
      "name": "Rock_Stone_Aqua"
    },
    {
      "x": -24,
      "y": 12,
      "z": 24,
      "name": "Rock_Stone_Aqua"
    },
    {
      "x": -24,
      "y": 13,
      "z": 24,
      "name": "Rock_Stone_Aqua"
    },
    {
      "x": -24,
      "y": 14,
      "z": 24,
      "name": "Rock_Basalt_Brick"
    },
    {
      "x": -24,
      "y": 0,
      "z": 25,
      "name": "Rock_Basalt_Brick"
    },
    {
      "x": -24,
      "y": 1,
      "z": 25,
      "name": "Rock_Stone_Aqua"
    },
    {
      "x": -24,
      "y": 2,
      "z": 25,
      "name": "Rock_Stone_Aqua"
    },
    {
      "x": -24,
      "y": 3,
      "z": 25,
      "name": "Rock_Stone_Aqua"
    },
    {
      "x": -24,
      "y": 4,
      "z": 25,
      "name": "Rock_Stone_Aqua"
    },
    {
      "x": -24,
      "y": 5,
      "z": 25,
      "name": "Rock_Stone_Aqua"
    },
    {
      "x": -24,
      "y": 6,
      "z": 25,
      "name": "Rock_Stone_Aqua"
    },
    {
      "x": -24,
      "y": 7,
      "z": 25,
      "name": "Rock_Stone_Aqua"
    },
    {
      "x": -24,
      "y": 8,
      "z": 25,
      "name": "Rock_Stone_Aqua"
    },
    {
      "x": -24,
      "y": 9,
      "z": 25,
      "name": "Rock_Stone_Aqua"
    },
    {
      "x": -24,
      "y": 10,
      "z": 25,
      "name": "Rock_Stone_Aqua"
    },
    {
      "x": -24,
      "y": 11,
      "z": 25,
      "name": "Rock_Stone_Aqua"
    },
    {
      "x": -24,
      "y": 12,
      "z": 25,
      "name": "Rock_Stone_Aqua"
    },
    {
      "x": -24,
      "y": 13,
      "z": 25,
      "name": "Rock_Stone_Aqua"
    },
    {
      "x": -24,
      "y": 14,
      "z": 25,
      "name": "Rock_Basalt_Brick"
    },
    {
      "x": -24,
      "y": 0,
      "z": 26,
      "name": "Rock_Basalt_Brick"
    },
    {
      "x": -24,
      "y": 1,
      "z": 26,
      "name": "Rock_Basalt_Brick"
    },
    {
      "x": -24,
      "y": 2,
      "z": 26,
      "name": "Rock_Basalt_Brick"
    },
    {
      "x": -24,
      "y": 3,
      "z": 26,
      "name": "Rock_Basalt_Brick"
    },
    {
      "x": -24,
      "y": 4,
      "z": 26,
      "name": "Rock_Basalt_Brick"
    },
    {
      "x": -24,
      "y": 5,
      "z": 26,
      "name": "Rock_Basalt_Brick"
    },
    {
      "x": -24,
      "y": 6,
      "z": 26,
      "name": "Rock_Basalt_Brick"
    },
    {
      "x": -24,
      "y": 7,
      "z": 26,
      "name": "Rock_Basalt_Brick"
    },
    {
      "x": -24,
      "y": 8,
      "z": 26,
      "name": "Rock_Basalt_Brick"
    },
    {
      "x": -24,
      "y": 9,
      "z": 26,
      "name": "Rock_Basalt_Brick"
    },
    {
      "x": -24,
      "y": 10,
      "z": 26,
      "name": "Rock_Basalt_Brick"
    },
    {
      "x": -24,
      "y": 11,
      "z": 26,
      "name": "Rock_Basalt_Brick"
    },
    {
      "x": -24,
      "y": 12,
      "z": 26,
      "name": "Rock_Basalt_Brick"
    },
    {
      "x": -24,
      "y": 13,
      "z": 26,
      "name": "Rock_Basalt_Brick"
    },
    {
      "x": -24,
      "y": 14,
      "z": 26,
      "name": "Rock_Basalt_Brick"
    },
    {
      "x": -23,
      "y": 0,
      "z": -24,
      "name": "Rock_Basalt_Brick"
    },
    {
      "x": -23,
      "y": 1,
      "z": -24,
      "name": "Rock_Stone_Aqua"
    },
    {
      "x": -23,
      "y": 2,
      "z": -24,
      "name": "Rock_Stone_Aqua"
    },
    {
      "x": -23,
      "y": 3,
      "z": -24,
      "name": "Rock_Stone_Aqua"
    },
    {
      "x": -23,
      "y": 4,
      "z": -24,
      "name": "Rock_Stone_Aqua"
    },
    {
      "x": -23,
      "y": 5,
      "z": -24,
      "name": "Rock_Stone_Aqua"
    },
    {
      "x": -23,
      "y": 6,
      "z": -24,
      "name": "Rock_Stone_Aqua"
    },
    {
      "x": -23,
      "y": 7,
      "z": -24,
      "name": "Rock_Stone_Aqua"
    },
    {
      "x": -23,
      "y": 8,
      "z": -24,
      "name": "Rock_Stone_Aqua"
    },
    {
      "x": -23,
      "y": 9,
      "z": -24,
      "name": "Rock_Stone_Aqua"
    },
    {
      "x": -23,
      "y": 10,
      "z": -24,
      "name": "Rock_Stone_Aqua"
    },
    {
      "x": -23,
      "y": 11,
      "z": -24,
      "name": "Rock_Stone_Aqua"
    },
    {
      "x": -23,
      "y": 12,
      "z": -24,
      "name": "Rock_Stone_Aqua"
    },
    {
      "x": -23,
      "y": 13,
      "z": -24,
      "name": "Rock_Stone_Aqua"
    },
    {
      "x": -23,
      "y": 14,
      "z": -24,
      "name": "Rock_Basalt_Brick"
    },
    {
      "x": -23,
      "y": 0,
      "z": -23,
      "name": "Rock_Stone_Aqua"
    },
    {
      "x": -23,
      "y": 14,
      "z": -23,
      "name": "Rock_Stone_Aqua"
    },
    {
      "x": -23,
      "y": 0,
      "z": -22,
      "name": "Rock_Stone_Aqua"
    },
    {
      "x": -23,
      "y": 14,
      "z": -22,
      "name": "Rock_Stone_Aqua"
    },
    {
      "x": -23,
      "y": 0,
      "z": -21,
      "name": "Rock_Stone_Aqua"
    },
    {
      "x": -23,
      "y": 14,
      "z": -21,
      "name": "Rock_Stone_Aqua"
    },
    {
      "x": -23,
      "y": 0,
      "z": -20,
      "name": "Rock_Stone_Aqua"
    },
    {
      "x": -23,
      "y": 14,
      "z": -20,
      "name": "Rock_Stone_Aqua"
    },
    {
      "x": -23,
      "y": 0,
      "z": -19,
      "name": "Rock_Stone_Aqua"
    },
    {
      "x": -23,
      "y": 14,
      "z": -19,
      "name": "Rock_Stone_Aqua"
    },
    {
      "x": -23,
      "y": 0,
      "z": -18,
      "name": "Rock_Stone_Aqua"
    },
    {
      "x": -23,
      "y": 14,
      "z": -18,
      "name": "Rock_Stone_Aqua"
    },
    {
      "x": -23,
      "y": 0,
      "z": -17,
      "name": "Rock_Stone_Aqua"
    },
    {
      "x": -23,
      "y": 14,
      "z": -17,
      "name": "Rock_Stone_Aqua"
    },
    {
      "x": -23,
      "y": 0,
      "z": -16,
      "name": "Rock_Stone_Aqua"
    },
    {
      "x": -23,
      "y": 14,
      "z": -16,
      "name": "Rock_Stone_Aqua"
    },
    {
      "x": -23,
      "y": 0,
      "z": -15,
      "name": "Rock_Stone_Aqua"
    },
    {
      "x": -23,
      "y": 14,
      "z": -15,
      "name": "Rock_Stone_Aqua"
    },
    {
      "x": -23,
      "y": 0,
      "z": -14,
      "name": "Rock_Stone_Aqua"
    },
    {
      "x": -23,
      "y": 14,
      "z": -14,
      "name": "Rock_Stone_Aqua"
    },
    {
      "x": -23,
      "y": 0,
      "z": -13,
      "name": "Rock_Stone_Aqua"
    },
    {
      "x": -23,
      "y": 14,
      "z": -13,
      "name": "Rock_Stone_Aqua"
    },
    {
      "x": -23,
      "y": 0,
      "z": -12,
      "name": "Rock_Stone_Aqua"
    },
    {
      "x": -23,
      "y": 14,
      "z": -12,
      "name": "Rock_Stone_Aqua"
    },
    {
      "x": -23,
      "y": 0,
      "z": -11,
      "name": "Rock_Stone_Aqua"
    },
    {
      "x": -23,
      "y": 14,
      "z": -11,
      "name": "Rock_Stone_Aqua"
    },
    {
      "x": -23,
      "y": 0,
      "z": -10,
      "name": "Rock_Stone_Aqua"
    },
    {
      "x": -23,
      "y": 14,
      "z": -10,
      "name": "Rock_Stone_Aqua"
    },
    {
      "x": -23,
      "y": 0,
      "z": -9,
      "name": "Rock_Stone_Aqua"
    },
    {
      "x": -23,
      "y": 14,
      "z": -9,
      "name": "Rock_Stone_Aqua"
    },
    {
      "x": -23,
      "y": 0,
      "z": -8,
      "name": "Rock_Stone_Aqua"
    },
    {
      "x": -23,
      "y": 14,
      "z": -8,
      "name": "Rock_Stone_Aqua"
    },
    {
      "x": -23,
      "y": 0,
      "z": -7,
      "name": "Rock_Stone_Aqua"
    },
    {
      "x": -23,
      "y": 14,
      "z": -7,
      "name": "Rock_Stone_Aqua"
    },
    {
      "x": -23,
      "y": 0,
      "z": -6,
      "name": "Rock_Stone_Aqua"
    },
    {
      "x": -23,
      "y": 14,
      "z": -6,
      "name": "Rock_Stone_Aqua"
    },
    {
      "x": -23,
      "y": 0,
      "z": -5,
      "name": "Rock_Stone_Aqua"
    },
    {
      "x": -23,
      "y": 14,
      "z": -5,
      "name": "Rock_Stone_Aqua"
    },
    {
      "x": -23,
      "y": 0,
      "z": -4,
      "name": "Rock_Stone_Aqua"
    },
    {
      "x": -23,
      "y": 14,
      "z": -4,
      "name": "Rock_Stone_Aqua"
    },
    {
      "x": -23,
      "y": 0,
      "z": -3,
      "name": "Rock_Stone_Aqua"
    },
    {
      "x": -23,
      "y": 14,
      "z": -3,
      "name": "Rock_Stone_Aqua"
    },
    {
      "x": -23,
      "y": 0,
      "z": -2,
      "name": "Rock_Stone_Aqua"
    },
    {
      "x": -23,
      "y": 14,
      "z": -2,
      "name": "Rock_Stone_Aqua"
    },
    {
      "x": -23,
      "y": 0,
      "z": -1,
      "name": "Rock_Stone_Aqua"
    },
    {
      "x": -23,
      "y": 14,
      "z": -1,
      "name": "Rock_Stone_Aqua"
    },
    {
      "x": -23,
      "y": 0,
      "z": 0,
      "name": "Rock_Stone_Aqua"
    },
    {
      "x": -23,
      "y": 14,
      "z": 0,
      "name": "Rock_Stone_Aqua"
    },
    {
      "x": -23,
      "y": 0,
      "z": 1,
      "name": "Rock_Basalt_Brick"
    },
    {
      "x": -23,
      "y": 14,
      "z": 1,
      "name": "Rock_Basalt_Brick"
    },
    {
      "x": -23,
      "y": 0,
      "z": 2,
      "name": "Rock_Stone_Aqua"
    },
    {
      "x": -23,
      "y": 14,
      "z": 2,
      "name": "Rock_Stone_Aqua"
    },
    {
      "x": -23,
      "y": 0,
      "z": 3,
      "name": "Rock_Stone_Aqua"
    },
    {
      "x": -23,
      "y": 14,
      "z": 3,
      "name": "Rock_Stone_Aqua"
    },
    {
      "x": -23,
      "y": 0,
      "z": 4,
      "name": "Rock_Stone_Aqua"
    },
    {
      "x": -23,
      "y": 14,
      "z": 4,
      "name": "Rock_Stone_Aqua"
    },
    {
      "x": -23,
      "y": 0,
      "z": 5,
      "name": "Rock_Stone_Aqua"
    },
    {
      "x": -23,
      "y": 14,
      "z": 5,
      "name": "Rock_Stone_Aqua"
    },
    {
      "x": -23,
      "y": 0,
      "z": 6,
      "name": "Rock_Stone_Aqua"
    },
    {
      "x": -23,
      "y": 14,
      "z": 6,
      "name": "Rock_Stone_Aqua"
    },
    {
      "x": -23,
      "y": 0,
      "z": 7,
      "name": "Rock_Stone_Aqua"
    },
    {
      "x": -23,
      "y": 14,
      "z": 7,
      "name": "Rock_Stone_Aqua"
    },
    {
      "x": -23,
      "y": 0,
      "z": 8,
      "name": "Rock_Stone_Aqua"
    },
    {
      "x": -23,
      "y": 14,
      "z": 8,
      "name": "Rock_Stone_Aqua"
    },
    {
      "x": -23,
      "y": 0,
      "z": 9,
      "name": "Rock_Stone_Aqua"
    },
    {
      "x": -23,
      "y": 14,
      "z": 9,
      "name": "Rock_Stone_Aqua"
    },
    {
      "x": -23,
      "y": 0,
      "z": 10,
      "name": "Rock_Stone_Aqua"
    },
    {
      "x": -23,
      "y": 14,
      "z": 10,
      "name": "Rock_Stone_Aqua"
    },
    {
      "x": -23,
      "y": 0,
      "z": 11,
      "name": "Rock_Stone_Aqua"
    },
    {
      "x": -23,
      "y": 14,
      "z": 11,
      "name": "Rock_Stone_Aqua"
    },
    {
      "x": -23,
      "y": 0,
      "z": 12,
      "name": "Rock_Stone_Aqua"
    },
    {
      "x": -23,
      "y": 14,
      "z": 12,
      "name": "Rock_Stone_Aqua"
    },
    {
      "x": -23,
      "y": 0,
      "z": 13,
      "name": "Rock_Stone_Aqua"
    },
    {
      "x": -23,
      "y": 14,
      "z": 13,
      "name": "Rock_Stone_Aqua"
    },
    {
      "x": -23,
      "y": 0,
      "z": 14,
      "name": "Rock_Stone_Aqua"
    },
    {
      "x": -23,
      "y": 14,
      "z": 14,
      "name": "Rock_Stone_Aqua"
    },
    {
      "x": -23,
      "y": 0,
      "z": 15,
      "name": "Rock_Stone_Aqua"
    },
    {
      "x": -23,
      "y": 14,
      "z": 15,
      "name": "Rock_Stone_Aqua"
    },
    {
      "x": -23,
      "y": 0,
      "z": 16,
      "name": "Rock_Stone_Aqua"
    },
    {
      "x": -23,
      "y": 14,
      "z": 16,
      "name": "Rock_Stone_Aqua"
    },
    {
      "x": -23,
      "y": 0,
      "z": 17,
      "name": "Rock_Stone_Aqua"
    },
    {
      "x": -23,
      "y": 14,
      "z": 17,
      "name": "Rock_Stone_Aqua"
    },
    {
      "x": -23,
      "y": 0,
      "z": 18,
      "name": "Rock_Stone_Aqua"
    },
    {
      "x": -23,
      "y": 14,
      "z": 18,
      "name": "Rock_Stone_Aqua"
    },
    {
      "x": -23,
      "y": 0,
      "z": 19,
      "name": "Rock_Stone_Aqua"
    },
    {
      "x": -23,
      "y": 14,
      "z": 19,
      "name": "Rock_Stone_Aqua"
    },
    {
      "x": -23,
      "y": 0,
      "z": 20,
      "name": "Rock_Stone_Aqua"
    },
    {
      "x": -23,
      "y": 14,
      "z": 20,
      "name": "Rock_Stone_Aqua"
    },
    {
      "x": -23,
      "y": 0,
      "z": 21,
      "name": "Rock_Stone_Aqua"
    },
    {
      "x": -23,
      "y": 14,
      "z": 21,
      "name": "Rock_Stone_Aqua"
    },
    {
      "x": -23,
      "y": 0,
      "z": 22,
      "name": "Rock_Stone_Aqua"
    },
    {
      "x": -23,
      "y": 14,
      "z": 22,
      "name": "Rock_Stone_Aqua"
    },
    {
      "x": -23,
      "y": 0,
      "z": 23,
      "name": "Rock_Stone_Aqua"
    },
    {
      "x": -23,
      "y": 14,
      "z": 23,
      "name": "Rock_Stone_Aqua"
    },
    {
      "x": -23,
      "y": 0,
      "z": 24,
      "name": "Rock_Stone_Aqua"
    },
    {
      "x": -23,
      "y": 14,
      "z": 24,
      "name": "Rock_Stone_Aqua"
    },
    {
      "x": -23,
      "y": 0,
      "z": 25,
      "name": "Rock_Stone_Aqua"
    },
    {
      "x": -23,
      "y": 14,
      "z": 25,
      "name": "Rock_Stone_Aqua"
    },
    {
      "x": -23,
      "y": 0,
      "z": 26,
      "name": "Rock_Basalt_Brick"
    },
    {
      "x": -23,
      "y": 1,
      "z": 26,
      "name": "Rock_Stone_Aqua"
    },
    {
      "x": -23,
      "y": 2,
      "z": 26,
      "name": "Rock_Stone_Aqua"
    },
    {
      "x": -23,
      "y": 3,
      "z": 26,
      "name": "Rock_Stone_Aqua"
    },
    {
      "x": -23,
      "y": 4,
      "z": 26,
      "name": "Rock_Stone_Aqua"
    },
    {
      "x": -23,
      "y": 5,
      "z": 26,
      "name": "Rock_Stone_Aqua"
    },
    {
      "x": -23,
      "y": 6,
      "z": 26,
      "name": "Rock_Stone_Aqua"
    },
    {
      "x": -23,
      "y": 7,
      "z": 26,
      "name": "Rock_Stone_Aqua"
    },
    {
      "x": -23,
      "y": 8,
      "z": 26,
      "name": "Rock_Stone_Aqua"
    },
    {
      "x": -23,
      "y": 9,
      "z": 26,
      "name": "Rock_Stone_Aqua"
    },
    {
      "x": -23,
      "y": 10,
      "z": 26,
      "name": "Rock_Stone_Aqua"
    },
    {
      "x": -23,
      "y": 11,
      "z": 26,
      "name": "Rock_Stone_Aqua"
    },
    {
      "x": -23,
      "y": 12,
      "z": 26,
      "name": "Rock_Stone_Aqua"
    },
    {
      "x": -23,
      "y": 13,
      "z": 26,
      "name": "Rock_Stone_Aqua"
    },
    {
      "x": -23,
      "y": 14,
      "z": 26,
      "name": "Rock_Basalt_Brick"
    },
    {
      "x": -22,
      "y": 0,
      "z": -24,
      "name": "Rock_Basalt_Brick"
    },
    {
      "x": -22,
      "y": 1,
      "z": -24,
      "name": "Rock_Stone_Aqua"
    },
    {
      "x": -22,
      "y": 2,
      "z": -24,
      "name": "Rock_Stone_Aqua"
    },
    {
      "x": -22,
      "y": 3,
      "z": -24,
      "name": "Rock_Stone_Aqua"
    },
    {
      "x": -22,
      "y": 4,
      "z": -24,
      "name": "Rock_Stone_Aqua"
    },
    {
      "x": -22,
      "y": 5,
      "z": -24,
      "name": "Rock_Stone_Aqua"
    },
    {
      "x": -22,
      "y": 6,
      "z": -24,
      "name": "Rock_Stone_Aqua"
    },
    {
      "x": -22,
      "y": 7,
      "z": -24,
      "name": "Rock_Stone_Aqua"
    },
    {
      "x": -22,
      "y": 8,
      "z": -24,
      "name": "Rock_Stone_Aqua"
    },
    {
      "x": -22,
      "y": 9,
      "z": -24,
      "name": "Rock_Stone_Aqua"
    },
    {
      "x": -22,
      "y": 10,
      "z": -24,
      "name": "Rock_Stone_Aqua"
    },
    {
      "x": -22,
      "y": 11,
      "z": -24,
      "name": "Rock_Stone_Aqua"
    },
    {
      "x": -22,
      "y": 12,
      "z": -24,
      "name": "Rock_Stone_Aqua"
    },
    {
      "x": -22,
      "y": 13,
      "z": -24,
      "name": "Rock_Stone_Aqua"
    },
    {
      "x": -22,
      "y": 14,
      "z": -24,
      "name": "Rock_Basalt_Brick"
    },
    {
      "x": -22,
      "y": 0,
      "z": -23,
      "name": "Rock_Stone_Aqua"
    },
    {
      "x": -22,
      "y": 14,
      "z": -23,
      "name": "Rock_Stone_Aqua"
    },
    {
      "x": -22,
      "y": 0,
      "z": -22,
      "name": "Rock_Stone_Aqua"
    },
    {
      "x": -22,
      "y": 14,
      "z": -22,
      "name": "Rock_Stone_Aqua"
    },
    {
      "x": -22,
      "y": 0,
      "z": -21,
      "name": "Rock_Stone_Aqua"
    },
    {
      "x": -22,
      "y": 14,
      "z": -21,
      "name": "Rock_Stone_Aqua"
    },
    {
      "x": -22,
      "y": 0,
      "z": -20,
      "name": "Rock_Stone_Aqua"
    },
    {
      "x": -22,
      "y": 14,
      "z": -20,
      "name": "Rock_Stone_Aqua"
    },
    {
      "x": -22,
      "y": 0,
      "z": -19,
      "name": "Rock_Stone_Aqua"
    },
    {
      "x": -22,
      "y": 14,
      "z": -19,
      "name": "Rock_Stone_Aqua"
    },
    {
      "x": -22,
      "y": 0,
      "z": -18,
      "name": "Rock_Stone_Aqua"
    },
    {
      "x": -22,
      "y": 14,
      "z": -18,
      "name": "Rock_Stone_Aqua"
    },
    {
      "x": -22,
      "y": 0,
      "z": -17,
      "name": "Rock_Stone_Aqua"
    },
    {
      "x": -22,
      "y": 14,
      "z": -17,
      "name": "Rock_Stone_Aqua"
    },
    {
      "x": -22,
      "y": 0,
      "z": -16,
      "name": "Rock_Stone_Aqua"
    },
    {
      "x": -22,
      "y": 14,
      "z": -16,
      "name": "Rock_Stone_Aqua"
    },
    {
      "x": -22,
      "y": 0,
      "z": -15,
      "name": "Rock_Stone_Aqua"
    },
    {
      "x": -22,
      "y": 14,
      "z": -15,
      "name": "Rock_Stone_Aqua"
    },
    {
      "x": -22,
      "y": 0,
      "z": -14,
      "name": "Rock_Stone_Aqua"
    },
    {
      "x": -22,
      "y": 14,
      "z": -14,
      "name": "Rock_Stone_Aqua"
    },
    {
      "x": -22,
      "y": 0,
      "z": -13,
      "name": "Rock_Stone_Aqua"
    },
    {
      "x": -22,
      "y": 14,
      "z": -13,
      "name": "Rock_Stone_Aqua"
    },
    {
      "x": -22,
      "y": 0,
      "z": -12,
      "name": "Rock_Stone_Aqua"
    },
    {
      "x": -22,
      "y": 14,
      "z": -12,
      "name": "Rock_Stone_Aqua"
    },
    {
      "x": -22,
      "y": 0,
      "z": -11,
      "name": "Rock_Stone_Aqua"
    },
    {
      "x": -22,
      "y": 14,
      "z": -11,
      "name": "Rock_Stone_Aqua"
    },
    {
      "x": -22,
      "y": 0,
      "z": -10,
      "name": "Rock_Stone_Aqua"
    },
    {
      "x": -22,
      "y": 14,
      "z": -10,
      "name": "Rock_Stone_Aqua"
    },
    {
      "x": -22,
      "y": 0,
      "z": -9,
      "name": "Rock_Stone_Aqua"
    },
    {
      "x": -22,
      "y": 14,
      "z": -9,
      "name": "Rock_Stone_Aqua"
    },
    {
      "x": -22,
      "y": 0,
      "z": -8,
      "name": "Rock_Stone_Aqua"
    },
    {
      "x": -22,
      "y": 14,
      "z": -8,
      "name": "Rock_Stone_Aqua"
    },
    {
      "x": -22,
      "y": 0,
      "z": -7,
      "name": "Rock_Stone_Aqua"
    },
    {
      "x": -22,
      "y": 14,
      "z": -7,
      "name": "Rock_Stone_Aqua"
    },
    {
      "x": -22,
      "y": 0,
      "z": -6,
      "name": "Rock_Stone_Aqua"
    },
    {
      "x": -22,
      "y": 14,
      "z": -6,
      "name": "Rock_Stone_Aqua"
    },
    {
      "x": -22,
      "y": 0,
      "z": -5,
      "name": "Rock_Stone_Aqua"
    },
    {
      "x": -22,
      "y": 14,
      "z": -5,
      "name": "Rock_Stone_Aqua"
    },
    {
      "x": -22,
      "y": 0,
      "z": -4,
      "name": "Rock_Stone_Aqua"
    },
    {
      "x": -22,
      "y": 14,
      "z": -4,
      "name": "Rock_Stone_Aqua"
    },
    {
      "x": -22,
      "y": 0,
      "z": -3,
      "name": "Rock_Stone_Aqua"
    },
    {
      "x": -22,
      "y": 14,
      "z": -3,
      "name": "Rock_Stone_Aqua"
    },
    {
      "x": -22,
      "y": 0,
      "z": -2,
      "name": "Rock_Stone_Aqua"
    },
    {
      "x": -22,
      "y": 14,
      "z": -2,
      "name": "Rock_Stone_Aqua"
    },
    {
      "x": -22,
      "y": 0,
      "z": -1,
      "name": "Rock_Stone_Aqua"
    },
    {
      "x": -22,
      "y": 14,
      "z": -1,
      "name": "Rock_Stone_Aqua"
    },
    {
      "x": -22,
      "y": 0,
      "z": 0,
      "name": "Rock_Stone_Aqua"
    },
    {
      "x": -22,
      "y": 14,
      "z": 0,
      "name": "Rock_Stone_Aqua"
    },
    {
      "x": -22,
      "y": 0,
      "z": 1,
      "name": "Rock_Basalt_Brick"
    },
    {
      "x": -22,
      "y": 14,
      "z": 1,
      "name": "Rock_Basalt_Brick"
    },
    {
      "x": -22,
      "y": 0,
      "z": 2,
      "name": "Rock_Stone_Aqua"
    },
    {
      "x": -22,
      "y": 14,
      "z": 2,
      "name": "Rock_Stone_Aqua"
    },
    {
      "x": -22,
      "y": 0,
      "z": 3,
      "name": "Rock_Stone_Aqua"
    },
    {
      "x": -22,
      "y": 14,
      "z": 3,
      "name": "Rock_Stone_Aqua"
    },
    {
      "x": -22,
      "y": 0,
      "z": 4,
      "name": "Rock_Stone_Aqua"
    },
    {
      "x": -22,
      "y": 14,
      "z": 4,
      "name": "Rock_Stone_Aqua"
    },
    {
      "x": -22,
      "y": 0,
      "z": 5,
      "name": "Rock_Stone_Aqua"
    },
    {
      "x": -22,
      "y": 14,
      "z": 5,
      "name": "Rock_Stone_Aqua"
    },
    {
      "x": -22,
      "y": 0,
      "z": 6,
      "name": "Rock_Stone_Aqua"
    },
    {
      "x": -22,
      "y": 14,
      "z": 6,
      "name": "Rock_Stone_Aqua"
    },
    {
      "x": -22,
      "y": 0,
      "z": 7,
      "name": "Rock_Stone_Aqua"
    },
    {
      "x": -22,
      "y": 14,
      "z": 7,
      "name": "Rock_Stone_Aqua"
    },
    {
      "x": -22,
      "y": 0,
      "z": 8,
      "name": "Rock_Stone_Aqua"
    },
    {
      "x": -22,
      "y": 14,
      "z": 8,
      "name": "Rock_Stone_Aqua"
    },
    {
      "x": -22,
      "y": 0,
      "z": 9,
      "name": "Rock_Stone_Aqua"
    },
    {
      "x": -22,
      "y": 14,
      "z": 9,
      "name": "Rock_Stone_Aqua"
    },
    {
      "x": -22,
      "y": 0,
      "z": 10,
      "name": "Rock_Stone_Aqua"
    },
    {
      "x": -22,
      "y": 14,
      "z": 10,
      "name": "Rock_Stone_Aqua"
    },
    {
      "x": -22,
      "y": 0,
      "z": 11,
      "name": "Rock_Stone_Aqua"
    },
    {
      "x": -22,
      "y": 14,
      "z": 11,
      "name": "Rock_Stone_Aqua"
    },
    {
      "x": -22,
      "y": 0,
      "z": 12,
      "name": "Rock_Stone_Aqua"
    },
    {
      "x": -22,
      "y": 14,
      "z": 12,
      "name": "Rock_Stone_Aqua"
    },
    {
      "x": -22,
      "y": 0,
      "z": 13,
      "name": "Rock_Stone_Aqua"
    },
    {
      "x": -22,
      "y": 14,
      "z": 13,
      "name": "Rock_Stone_Aqua"
    },
    {
      "x": -22,
      "y": 0,
      "z": 14,
      "name": "Rock_Stone_Aqua"
    },
    {
      "x": -22,
      "y": 14,
      "z": 14,
      "name": "Rock_Stone_Aqua"
    },
    {
      "x": -22,
      "y": 0,
      "z": 15,
      "name": "Rock_Stone_Aqua"
    },
    {
      "x": -22,
      "y": 14,
      "z": 15,
      "name": "Rock_Stone_Aqua"
    },
    {
      "x": -22,
      "y": 0,
      "z": 16,
      "name": "Rock_Stone_Aqua"
    },
    {
      "x": -22,
      "y": 14,
      "z": 16,
      "name": "Rock_Stone_Aqua"
    },
    {
      "x": -22,
      "y": 0,
      "z": 17,
      "name": "Rock_Stone_Aqua"
    },
    {
      "x": -22,
      "y": 14,
      "z": 17,
      "name": "Rock_Stone_Aqua"
    },
    {
      "x": -22,
      "y": 0,
      "z": 18,
      "name": "Rock_Stone_Aqua"
    },
    {
      "x": -22,
      "y": 14,
      "z": 18,
      "name": "Rock_Stone_Aqua"
    },
    {
      "x": -22,
      "y": 0,
      "z": 19,
      "name": "Rock_Stone_Aqua"
    },
    {
      "x": -22,
      "y": 14,
      "z": 19,
      "name": "Rock_Stone_Aqua"
    },
    {
      "x": -22,
      "y": 0,
      "z": 20,
      "name": "Rock_Stone_Aqua"
    },
    {
      "x": -22,
      "y": 14,
      "z": 20,
      "name": "Rock_Stone_Aqua"
    },
    {
      "x": -22,
      "y": 0,
      "z": 21,
      "name": "Rock_Stone_Aqua"
    },
    {
      "x": -22,
      "y": 14,
      "z": 21,
      "name": "Rock_Stone_Aqua"
    },
    {
      "x": -22,
      "y": 0,
      "z": 22,
      "name": "Rock_Stone_Aqua"
    },
    {
      "x": -22,
      "y": 14,
      "z": 22,
      "name": "Rock_Stone_Aqua"
    },
    {
      "x": -22,
      "y": 0,
      "z": 23,
      "name": "Rock_Stone_Aqua"
    },
    {
      "x": -22,
      "y": 14,
      "z": 23,
      "name": "Rock_Stone_Aqua"
    },
    {
      "x": -22,
      "y": 0,
      "z": 24,
      "name": "Rock_Stone_Aqua"
    },
    {
      "x": -22,
      "y": 14,
      "z": 24,
      "name": "Rock_Stone_Aqua"
    },
    {
      "x": -22,
      "y": 0,
      "z": 25,
      "name": "Rock_Stone_Aqua"
    },
    {
      "x": -22,
      "y": 14,
      "z": 25,
      "name": "Rock_Stone_Aqua"
    },
    {
      "x": -22,
      "y": 0,
      "z": 26,
      "name": "Rock_Basalt_Brick"
    },
    {
      "x": -22,
      "y": 1,
      "z": 26,
      "name": "Rock_Stone_Aqua"
    },
    {
      "x": -22,
      "y": 2,
      "z": 26,
      "name": "Rock_Stone_Aqua"
    },
    {
      "x": -22,
      "y": 3,
      "z": 26,
      "name": "Rock_Stone_Aqua"
    },
    {
      "x": -22,
      "y": 4,
      "z": 26,
      "name": "Rock_Stone_Aqua"
    },
    {
      "x": -22,
      "y": 5,
      "z": 26,
      "name": "Rock_Stone_Aqua"
    },
    {
      "x": -22,
      "y": 6,
      "z": 26,
      "name": "Rock_Stone_Aqua"
    },
    {
      "x": -22,
      "y": 7,
      "z": 26,
      "name": "Rock_Stone_Aqua"
    },
    {
      "x": -22,
      "y": 8,
      "z": 26,
      "name": "Rock_Stone_Aqua"
    },
    {
      "x": -22,
      "y": 9,
      "z": 26,
      "name": "Rock_Stone_Aqua"
    },
    {
      "x": -22,
      "y": 10,
      "z": 26,
      "name": "Rock_Stone_Aqua"
    },
    {
      "x": -22,
      "y": 11,
      "z": 26,
      "name": "Rock_Stone_Aqua"
    },
    {
      "x": -22,
      "y": 12,
      "z": 26,
      "name": "Rock_Stone_Aqua"
    },
    {
      "x": -22,
      "y": 13,
      "z": 26,
      "name": "Rock_Stone_Aqua"
    },
    {
      "x": -22,
      "y": 14,
      "z": 26,
      "name": "Rock_Basalt_Brick"
    },
    {
      "x": -21,
      "y": 0,
      "z": -24,
      "name": "Rock_Basalt_Brick"
    },
    {
      "x": -21,
      "y": 1,
      "z": -24,
      "name": "Rock_Stone_Aqua"
    },
    {
      "x": -21,
      "y": 2,
      "z": -24,
      "name": "Rock_Stone_Aqua"
    },
    {
      "x": -21,
      "y": 3,
      "z": -24,
      "name": "Rock_Stone_Aqua"
    },
    {
      "x": -21,
      "y": 4,
      "z": -24,
      "name": "Rock_Stone_Aqua"
    },
    {
      "x": -21,
      "y": 5,
      "z": -24,
      "name": "Rock_Stone_Aqua"
    },
    {
      "x": -21,
      "y": 6,
      "z": -24,
      "name": "Rock_Stone_Aqua"
    },
    {
      "x": -21,
      "y": 7,
      "z": -24,
      "name": "Rock_Stone_Aqua"
    },
    {
      "x": -21,
      "y": 8,
      "z": -24,
      "name": "Rock_Stone_Aqua"
    },
    {
      "x": -21,
      "y": 9,
      "z": -24,
      "name": "Rock_Stone_Aqua"
    },
    {
      "x": -21,
      "y": 10,
      "z": -24,
      "name": "Rock_Stone_Aqua"
    },
    {
      "x": -21,
      "y": 11,
      "z": -24,
      "name": "Rock_Stone_Aqua"
    },
    {
      "x": -21,
      "y": 12,
      "z": -24,
      "name": "Rock_Stone_Aqua"
    },
    {
      "x": -21,
      "y": 13,
      "z": -24,
      "name": "Rock_Stone_Aqua"
    },
    {
      "x": -21,
      "y": 14,
      "z": -24,
      "name": "Rock_Basalt_Brick"
    },
    {
      "x": -21,
      "y": 0,
      "z": -23,
      "name": "Rock_Stone_Aqua"
    },
    {
      "x": -21,
      "y": 14,
      "z": -23,
      "name": "Rock_Stone_Aqua"
    },
    {
      "x": -21,
      "y": 0,
      "z": -22,
      "name": "Rock_Stone_Aqua"
    },
    {
      "x": -21,
      "y": 14,
      "z": -22,
      "name": "Rock_Stone_Aqua"
    },
    {
      "x": -21,
      "y": 0,
      "z": -21,
      "name": "Rock_Stone_Aqua"
    },
    {
      "x": -21,
      "y": 14,
      "z": -21,
      "name": "Rock_Stone_Aqua"
    },
    {
      "x": -21,
      "y": 0,
      "z": -20,
      "name": "Rock_Stone_Aqua"
    },
    {
      "x": -21,
      "y": 14,
      "z": -20,
      "name": "Rock_Stone_Aqua"
    },
    {
      "x": -21,
      "y": 0,
      "z": -19,
      "name": "Rock_Stone_Aqua"
    },
    {
      "x": -21,
      "y": 14,
      "z": -19,
      "name": "Rock_Stone_Aqua"
    },
    {
      "x": -21,
      "y": 0,
      "z": -18,
      "name": "Rock_Stone_Aqua"
    },
    {
      "x": -21,
      "y": 14,
      "z": -18,
      "name": "Rock_Stone_Aqua"
    },
    {
      "x": -21,
      "y": 0,
      "z": -17,
      "name": "Rock_Stone_Aqua"
    },
    {
      "x": -21,
      "y": 14,
      "z": -17,
      "name": "Rock_Stone_Aqua"
    },
    {
      "x": -21,
      "y": 0,
      "z": -16,
      "name": "Rock_Stone_Aqua"
    },
    {
      "x": -21,
      "y": 14,
      "z": -16,
      "name": "Rock_Stone_Aqua"
    },
    {
      "x": -21,
      "y": 0,
      "z": -15,
      "name": "Rock_Stone_Aqua"
    },
    {
      "x": -21,
      "y": 14,
      "z": -15,
      "name": "Rock_Stone_Aqua"
    },
    {
      "x": -21,
      "y": 0,
      "z": -14,
      "name": "Rock_Stone_Aqua"
    },
    {
      "x": -21,
      "y": 14,
      "z": -14,
      "name": "Rock_Stone_Aqua"
    },
    {
      "x": -21,
      "y": 0,
      "z": -13,
      "name": "Rock_Stone_Aqua"
    },
    {
      "x": -21,
      "y": 14,
      "z": -13,
      "name": "Rock_Stone_Aqua"
    },
    {
      "x": -21,
      "y": 0,
      "z": -12,
      "name": "Rock_Stone_Aqua"
    },
    {
      "x": -21,
      "y": 14,
      "z": -12,
      "name": "Rock_Stone_Aqua"
    },
    {
      "x": -21,
      "y": 0,
      "z": -11,
      "name": "Rock_Stone_Aqua"
    },
    {
      "x": -21,
      "y": 14,
      "z": -11,
      "name": "Rock_Stone_Aqua"
    },
    {
      "x": -21,
      "y": 0,
      "z": -10,
      "name": "Rock_Stone_Aqua"
    },
    {
      "x": -21,
      "y": 14,
      "z": -10,
      "name": "Rock_Stone_Aqua"
    },
    {
      "x": -21,
      "y": 0,
      "z": -9,
      "name": "Rock_Stone_Aqua"
    },
    {
      "x": -21,
      "y": 14,
      "z": -9,
      "name": "Rock_Stone_Aqua"
    },
    {
      "x": -21,
      "y": 0,
      "z": -8,
      "name": "Rock_Stone_Aqua"
    },
    {
      "x": -21,
      "y": 14,
      "z": -8,
      "name": "Rock_Stone_Aqua"
    },
    {
      "x": -21,
      "y": 0,
      "z": -7,
      "name": "Rock_Stone_Aqua"
    },
    {
      "x": -21,
      "y": 14,
      "z": -7,
      "name": "Rock_Stone_Aqua"
    },
    {
      "x": -21,
      "y": 0,
      "z": -6,
      "name": "Rock_Stone_Aqua"
    },
    {
      "x": -21,
      "y": 14,
      "z": -6,
      "name": "Rock_Stone_Aqua"
    },
    {
      "x": -21,
      "y": 0,
      "z": -5,
      "name": "Rock_Stone_Aqua"
    },
    {
      "x": -21,
      "y": 14,
      "z": -5,
      "name": "Rock_Stone_Aqua"
    },
    {
      "x": -21,
      "y": 0,
      "z": -4,
      "name": "Rock_Stone_Aqua"
    },
    {
      "x": -21,
      "y": 14,
      "z": -4,
      "name": "Rock_Stone_Aqua"
    },
    {
      "x": -21,
      "y": 0,
      "z": -3,
      "name": "Rock_Stone_Aqua"
    },
    {
      "x": -21,
      "y": 14,
      "z": -3,
      "name": "Rock_Stone_Aqua"
    },
    {
      "x": -21,
      "y": 0,
      "z": -2,
      "name": "Rock_Stone_Aqua"
    },
    {
      "x": -21,
      "y": 14,
      "z": -2,
      "name": "Rock_Stone_Aqua"
    },
    {
      "x": -21,
      "y": 0,
      "z": -1,
      "name": "Rock_Stone_Aqua"
    },
    {
      "x": -21,
      "y": 14,
      "z": -1,
      "name": "Rock_Stone_Aqua"
    },
    {
      "x": -21,
      "y": 0,
      "z": 0,
      "name": "Rock_Stone_Aqua"
    },
    {
      "x": -21,
      "y": 14,
      "z": 0,
      "name": "Rock_Stone_Aqua"
    },
    {
      "x": -21,
      "y": 0,
      "z": 1,
      "name": "Rock_Basalt_Brick"
    },
    {
      "x": -21,
      "y": 14,
      "z": 1,
      "name": "Rock_Basalt_Brick"
    },
    {
      "x": -21,
      "y": 0,
      "z": 2,
      "name": "Rock_Stone_Aqua"
    },
    {
      "x": -21,
      "y": 14,
      "z": 2,
      "name": "Rock_Stone_Aqua"
    },
    {
      "x": -21,
      "y": 0,
      "z": 3,
      "name": "Rock_Stone_Aqua"
    },
    {
      "x": -21,
      "y": 14,
      "z": 3,
      "name": "Rock_Stone_Aqua"
    },
    {
      "x": -21,
      "y": 0,
      "z": 4,
      "name": "Rock_Stone_Aqua"
    },
    {
