{
  "version": 8,
  "blockIdVersion": 11,
  "anchorX": 0,
  "anchorY": 10,
  "anchorZ": 0,
  "blocks": [
    {
      "x": -3,
      "y": 0,
      "z": 0,
      "name": "Rock_Basalt_Brick"
    },
    {
      "x": -3,
      "y": 6,
      "z": 0,
      "name": "Rock_Basalt_Brick"
    },
    {
      "x": -3,
      "y": 7,
      "z": 0,
      "name": "Rock_Basalt_Brick"
    },
    {
      "x": -3,
      "y": 8,
      "z": 0,
      "name": "Rock_Basalt_Brick"
    },
    {
      "x": -3,
      "y": 9,
      "z": 0,
      "name": "Rock_Basalt_Brick"
    },
    {
      "x": -3,
      "y": 10,
      "z": 0,
      "name": "Rock_Basalt_Brick"
    },
    {
      "x": -3,
      "y": 11,
      "z": 0,
      "name": "Rock_Basalt_Brick"
    },
    {
      "x": -3,
      "y": 12,
      "z": 0,
      "name": "Rock_Basalt_Brick"
    },
    {
      "x": -3,
      "y": 13,
      "z": 0,
      "name": "Rock_Basalt_Brick"
    },
    {
      "x": -3,
      "y": 14,
      "z": 0,
      "name": "Rock_Basalt_Brick"
    },
    {
      "x": -3,
      "y": 15,
      "z": 0,
      "name": "Rock_Basalt_Brick"
    },
    {
      "x": -3,
      "y": 21,
      "z": 0,
      "name": "Rock_Basalt_Brick"
    },
    {
      "x": -2,
      "y": 0,
      "z": -1,
      "name": "Rock_Basalt_Brick"
    },
    {
      "x": -2,
      "y": 21,
      "z": -1,
      "name": "Rock_Basalt_Brick"
    },
    {
      "x": -2,
      "y": 0,
      "z": 0,
      "name": "Rock_Basalt_Brick"
    },
    {
      "x": -2,
      "y": 6,
      "z": 0,
      "name": "Rock_Basalt_Brick"
    },
    {
      "x": -2,
      "y": 15,
      "z": 0,
      "name": "Rock_Basalt_Brick"
    },
    {
      "x": -2,
      "y": 21,
      "z": 0,
      "name": "Rock_Basalt_Brick"
    },
    {
      "x": -2,
      "y": 0,
      "z": 1,
      "name": "Rock_Basalt_Brick"
    },
    {
      "x": -2,
      "y": 21,
      "z": 1,
      "name": "Rock_Basalt_Brick"
    },
    {
      "x": -1,
      "y": 0,
      "z": -2,
      "name": "Rock_Basalt_Brick"
    },
    {
      "x": -1,
      "y": 21,
      "z": -2,
      "name": "Rock_Basalt_Brick"
    },
    {
      "x": -1,
      "y": 0,
      "z": -1,
      "name": "Rock_Basalt_Brick"
    },
    {
      "x": -1,
      "y": 21,
      "z": -1,
      "name": "Rock_Basalt_Brick"
    },
    {
      "x": -1,
      "y": 0,
      "z": 0,
      "name": "Rock_Basalt_Brick"
    },
    {
      "x": -1,
      "y": 6,
      "z": 0,
      "name": "Rock_Basalt_Brick"
    },
    {
      "x": -1,
      "y": 15,
      "z": 0,
      "name": "Rock_Basalt_Brick"
    },
    {
      "x": -1,
      "y": 21,
      "z": 0,
      "name": "Rock_Basalt_Brick"
    },
    {
      "x": -1,
      "y": 0,
      "z": 1,
      "name": "Rock_Basalt_Brick"
    },
    {
      "x": -1,
      "y": 21,
      "z": 1,
      "name": "Rock_Basalt_Brick"
    },
    {
      "x": -1,
      "y": 0,
      "z": 2,
      "name": "Rock_Basalt_Brick"
    },
    {
      "x": -1,
      "y": 21,
      "z": 2,
      "name": "Rock_Basalt_Brick"
    },
    {
      "x": 0,
      "y": 0,
      "z": -3,
      "name": "Rock_Basalt_Brick"
    },
    {
      "x": 0,
      "y": 6,
      "z": -3,
      "name": "Rock_Basalt_Brick"
    },
    {
      "x": 0,
      "y": 7,
      "z": -3,
      "name": "Rock_Basalt_Brick"
    },
    {
      "x": 0,
      "y": 8,
      "z": -3,
      "name": "Rock_Basalt_Brick"
    },
    {
      "x": 0,
      "y": 9,
      "z": -3,
      "name": "Rock_Basalt_Brick"
    },
    {
      "x": 0,
      "y": 10,
      "z": -3,
      "name": "Rock_Basalt_Brick"
    },
    {
      "x": 0,
      "y": 11,
      "z": -3,
      "name": "Rock_Basalt_Brick"
    },
    {
      "x": 0,
      "y": 12,
      "z": -3,
      "name": "Rock_Basalt_Brick"
    },
    {
      "x": 0,
      "y": 13,
      "z": -3,
      "name": "Rock_Basalt_Brick"
    },
    {
      "x": 0,
      "y": 14,
      "z": -3,
      "name": "Rock_Basalt_Brick"
    },
    {
      "x": 0,
      "y": 15,
      "z": -3,
      "name": "Rock_Basalt_Brick"
    },
    {
      "x": 0,
      "y": 21,
      "z": -3,
      "name": "Rock_Basalt_Brick"
    },
    {
      "x": 0,
      "y": 0,
      "z": -2,
      "name": "Rock_Basalt_Brick"
    },
    {
      "x": 0,
      "y": 6,
      "z": -2,
      "name": "Rock_Basalt_Brick"
    },
    {
      "x": 0,
      "y": 15,
      "z": -2,
      "name": "Rock_Basalt_Brick"
    },
    {
      "x": 0,
      "y": 21,
      "z": -2,
      "name": "Rock_Basalt_Brick"
    },
    {
      "x": 0,
      "y": 0,
      "z": -1,
      "name": "Rock_Basalt_Brick"
    },
    {
      "x": 0,
      "y": 6,
      "z": -1,
      "name": "Rock_Basalt_Brick"
    },
    {
      "x": 0,
      "y": 15,
      "z": -1,
      "name": "Rock_Basalt_Brick"
    },
    {
      "x": 0,
      "y": 21,
      "z": -1,
      "name": "Rock_Basalt_Brick"
    },
    {
      "x": 0,
      "y": 0,
      "z": 0,
      "name": "Rock_Basalt_Brick"
    },
    {
      "x": 0,
      "y": 1,
      "z": 0,
      "name": "Rock_Basalt_Brick"
    },
    {
      "x": 0,
      "y": 2,
      "z": 0,
      "name": "Rock_Basalt_Brick"
    },
    {
      "x": 0,
      "y": 3,
      "z": 0,
      "name": "Rock_Basalt_Brick"
    },
    {
      "x": 0,
      "y": 4,
      "z": 0,
      "name": "Rock_Basalt_Brick"
    },
    {
      "x": 0,
      "y": 5,
      "z": 0,
      "name": "Rock_Basalt_Brick"
    },
    {
      "x": 0,
      "y": 6,
      "z": 0,
      "name": "Rock_Basalt_Brick"
    },
    {
      "x": 0,
      "y": 15,
      "z": 0,
      "name": "Rock_Basalt_Brick"
    },
    {
      "x": 0,
      "y": 16,
      "z": 0,
      "name": "Rock_Basalt_Brick"
    },
    {
      "x": 0,
      "y": 17,
      "z": 0,
      "name": "Rock_Basalt_Brick"
    },
    {
      "x": 0,
      "y": 18,
      "z": 0,
      "name": "Rock_Basalt_Brick"
    },
    {
      "x": 0,
      "y": 19,
      "z": 0,
      "name": "Rock_Basalt_Brick"
    },
    {
      "x": 0,
      "y": 20,
      "z": 0,
      "name": "Rock_Basalt_Brick"
    },
    {
      "x": 0,
      "y": 21,
      "z": 0,
      "name": "Rock_Basalt_Brick"
    },
    {
      "x": 0,
      "y": 0,
      "z": 1,
      "name": "Rock_Basalt_Brick"
    },
    {
      "x": 0,
      "y": 6,
      "z": 1,
      "name": "Rock_Basalt_Brick"
    },
    {
      "x": 0,
      "y": 15,
      "z": 1,
      "name": "Rock_Basalt_Brick"
    },
    {
      "x": 0,
      "y": 21,
      "z": 1,
      "name": "Rock_Basalt_Brick"
    },
    {
      "x": 0,
      "y": 0,
      "z": 2,
      "name": "Rock_Basalt_Brick"
    },
    {
      "x": 0,
      "y": 6,
      "z": 2,
      "name": "Rock_Basalt_Brick"
    },
    {
      "x": 0,
      "y": 15,
      "z": 2,
      "name": "Rock_Basalt_Brick"
    },
    {
      "x": 0,
      "y": 21,
      "z": 2,
      "name": "Rock_Basalt_Brick"
    },
    {
      "x": 0,
      "y": 0,
      "z": 3,
      "name": "Rock_Basalt_Brick"
    },
    {
      "x": 0,
      "y": 6,
      "z": 3,
      "name": "Rock_Basalt_Brick"
    },
    {
      "x": 0,
      "y": 7,
      "z": 3,
      "name": "Rock_Basalt_Brick"
    },
    {
      "x": 0,
      "y": 8,
      "z": 3,
      "name": "Rock_Basalt_Brick"
    },
    {
      "x": 0,
      "y": 9,
      "z": 3,
      "name": "Rock_Basalt_Brick"
    },
    {
      "x": 0,
      "y": 10,
      "z": 3,
      "name": "Rock_Basalt_Brick"
    },
    {
      "x": 0,
      "y": 11,
      "z": 3,
      "name": "Rock_Basalt_Brick"
    },
    {
      "x": 0,
      "y": 12,
      "z": 3,
      "name": "Rock_Basalt_Brick"
    },
    {
      "x": 0,
      "y": 13,
      "z": 3,
      "name": "Rock_Basalt_Brick"
    },
    {
      "x": 0,
      "y": 14,
      "z": 3,
      "name": "Rock_Basalt_Brick"
    },
    {
      "x": 0,
      "y": 15,
      "z": 3,
      "name": "Rock_Basalt_Brick"
    },
    {
      "x": 0,
      "y": 21,
      "z": 3,
      "name": "Rock_Basalt_Brick"
    },
    {
      "x": 1,
      "y": 0,
      "z": -2,
      "name": "Rock_Basalt_Brick"
    },
    {
      "x": 1,
      "y": 21,
      "z": -2,
      "name": "Rock_Basalt_Brick"
    },
    {
      "x": 1,
      "y": 0,
      "z": -1,
      "name": "Rock_Basalt_Brick"
    },
    {
      "x": 1,
      "y": 21,
      "z": -1,
      "name": "Rock_Basalt_Brick"
    },
    {
      "x": 1,
      "y": 0,
      "z": 0,
      "name": "Rock_Basalt_Brick"
    },
    {
      "x": 1,
      "y": 6,
      "z": 0,
      "name": "Rock_Basalt_Brick"
    },
    {
      "x": 1,
      "y": 15,
      "z": 0,
      "name": "Rock_Basalt_Brick"
    },
    {
      "x": 1,
      "y": 21,
      "z": 0,
      "name": "Rock_Basalt_Brick"
    },
    {
      "x": 1,
      "y": 0,
      "z": 1,
      "name": "Rock_Basalt_Brick"
    },
    {
      "x": 1,
      "y": 21,
      "z": 1,
      "name": "Rock_Basalt_Brick"
    },
    {
      "x": 1,
      "y": 0,
      "z": 2,
      "name": "Rock_Basalt_Brick"
    },
    {
      "x": 1,
      "y": 21,
      "z": 2,
      "name": "Rock_Basalt_Brick"
    },
    {
      "x": 2,
      "y": 0,
      "z": -1,
      "name": "Rock_Basalt_Brick"
    },
    {
      "x": 2,
      "y": 21,
      "z": -1,
      "name": "Rock_Basalt_Brick"
    },
    {
      "x": 2,
      "y": 0,
      "z": 0,
      "name": "Rock_Basalt_Brick"
    },
    {
      "x": 2,
      "y": 6,
      "z": 0,
      "name": "Rock_Basalt_Brick"
    },
    {
      "x": 2,
      "y": 15,
      "z": 0,
      "name": "Rock_Basalt_Brick"
    },
    {
      "x": 2,
      "y": 21,
      "z": 0,
      "name": "Rock_Basalt_Brick"
    },
    {
      "x": 2,
      "y": 0,
      "z": 1,
      "name": "Rock_Basalt_Brick"
    },
    {
      "x": 2,
      "y": 21,
      "z": 1,
      "name": "Rock_Basalt_Brick"
    },
    {
      "x": 3,
      "y": 0,
      "z": 0,
      "name": "Rock_Basalt_Brick"
    },
    {
      "x": 3,
      "y": 6,
      "z": 0,
      "name": "Rock_Basalt_Brick"
    },
    {
      "x": 3,
      "y": 7,
      "z": 0,
      "name": "Rock_Basalt_Brick"
    },
    {
      "x": 3,
      "y": 8,
      "z": 0,
      "name": "Rock_Basalt_Brick"
    },
    {
      "x": 3,
      "y": 9,
      "z": 0,
      "name": "Rock_Basalt_Brick"
    },
    {
      "x": 3,
      "y": 10,
      "z": 0,
      "name": "Rock_Basalt_Brick"
    },
    {
      "x": 3,
      "y": 11,
      "z": 0,
      "name": "Rock_Basalt_Brick"
    },
    {
      "x": 3,
      "y": 12,
      "z": 0,
      "name": "Rock_Basalt_Brick"
    },
    {
      "x": 3,
      "y": 13,
      "z": 0,
      "name": "Rock_Basalt_Brick"
    },
    {
      "x": 3,
      "y": 14,
      "z": 0,
      "name": "Rock_Basalt_Brick"
    },
    {
      "x": 3,
      "y": 15,
      "z": 0,
      "name": "Rock_Basalt_Brick"
    },
    {
      "x": 3,
      "y": 21,
      "z": 0,
      "name": "Rock_Basalt_Brick"
    }
  ]
}