{
  "version": 8,
  "blockIdVersion": 11,
  "anchorX": 0,
  "anchorY": 3,
  "anchorZ": 0,
  "blocks": [
    {
      "x": -3,
      "y": 0,
      "z": -8,
      "name": "Rock_Basalt_Brick"
    },
    {
      "x": -3,
      "y": 1,
      "z": -8,
      "name": "Rock_Basalt_Brick"
    },
    {
      "x": -3,
      "y": 2,
      "z": -8,
      "name": "Rock_Basalt_Brick"
    },
    {
      "x": -3,
      "y": 3,
      "z": -8,
      "name": "Rock_Basalt_Brick"
    },
    {
      "x": -3,
      "y": 4,
      "z": -8,
      "name": "Rock_Basalt_Brick"
    },
    {
      "x": -3,
      "y": 5,
      "z": -8,
      "name": "Rock_Basalt_Brick"
    },
    {
      "x": -3,
      "y": 6,
      "z": -8,
      "name": "Rock_Basalt_Brick"
    },
    {
      "x": -3,
      "y": 0,
      "z": -7,
      "name": "Rock_Basalt_Brick"
    },
    {
      "x": -3,
      "y": 1,
      "z": -7,
      "name": "Rock_Basalt_Brick"
    },
    {
      "x": -3,
      "y": 2,
      "z": -7,
      "name": "Rock_Basalt_Brick"
    },
    {
      "x": -3,
      "y": 3,
      "z": -7,
      "name": "Rock_Basalt_Brick"
    },
    {
      "x": -3,
      "y": 4,
      "z": -7,
      "name": "Rock_Basalt_Brick"
    },
    {
      "x": -3,
      "y": 5,
      "z": -7,
      "name": "Rock_Basalt_Brick"
    },
    {
      "x": -3,
      "y": 6,
      "z": -7,
      "name": "Rock_Basalt_Brick"
    },
    {
      "x": -3,
      "y": 0,
      "z": -6,
      "name": "Rock_Basalt_Brick"
    },
    {
      "x": -3,
      "y": 1,
      "z": -6,
      "name": "Rock_Basalt_Brick"
    },
    {
      "x": -3,
      "y": 2,
      "z": -6,
      "name": "Rock_Basalt_Brick_Stairs",
      "rotation": 1
    },
    {
      "x": -3,
      "y": 3,
      "z": -6,
      "name": "Rock_Basalt_Brick_Decorative"
    },
    {
      "x": -3,
      "y": 4,
      "z": -6,
      "name": "Rock_Basalt_Brick_Stairs",
      "rotation": 11
    },
    {
      "x": -3,
      "y": 5,
      "z": -6,
      "name": "Rock_Basalt_Brick"
    },
    {
      "x": -3,
      "y": 6,
      "z": -6,
      "name": "Rock_Basalt_Brick"
    },
    {
      "x": -3,
      "y": 0,
      "z": -5,
      "name": "Rock_Basalt_Brick"
    },
    {
      "x": -3,
      "y": 1,
      "z": -5,
      "name": "Rock_Basalt_Brick"
    },
    {
      "x": -3,
      "y": 2,
      "z": -5,
      "name": "Rock_Basalt_Brick"
    },
    {
      "x": -3,
      "y": 3,
      "z": -5,
      "name": "Rock_Basalt_Brick"
    },
    {
      "x": -3,
      "y": 4,
      "z": -5,
      "name": "Rock_Basalt_Brick"
    },
    {
      "x": -3,
      "y": 5,
      "z": -5,
      "name": "Rock_Basalt_Brick"
    },
    {
      "x": -3,
      "y": 6,
      "z": -5,
      "name": "Rock_Basalt_Brick"
    },
    {
      "x": -3,
      "y": 0,
      "z": -4,
      "name": "Rock_Basalt_Brick"
    },
    {
      "x": -3,
      "y": 1,
      "z": -4,
      "name": "Rock_Basalt_Brick"
    },
    {
      "x": -3,
      "y": 2,
      "z": -4,
      "name": "Rock_Basalt_Brick"
    },
    {
      "x": -3,
      "y": 3,
      "z": -4,
      "name": "Rock_Basalt_Brick"
    },
    {
      "x": -3,
      "y": 4,
      "z": -4,
      "name": "Rock_Basalt_Brick"
    },
    {
      "x": -3,
      "y": 5,
      "z": -4,
      "name": "Rock_Basalt_Brick"
    },
    {
      "x": -3,
      "y": 6,
      "z": -4,
      "name": "Rock_Basalt_Brick"
    },
    {
      "x": -3,
      "y": 0,
      "z": -3,
      "name": "Rock_Basalt_Brick"
    },
    {
      "x": -3,
      "y": 1,
      "z": -3,
      "name": "Rock_Basalt_Brick"
    },
    {
      "x": -3,
      "y": 2,
      "z": -3,
      "name": "Rock_Basalt_Brick"
    },
    {
      "x": -3,
      "y": 3,
      "z": -3,
      "name": "Rock_Basalt_Brick"
    },
    {
      "x": -3,
      "y": 4,
      "z": -3,
      "name": "Rock_Basalt_Brick"
    },
    {
      "x": -3,
      "y": 5,
      "z": -3,
      "name": "Rock_Basalt_Brick"
    },
    {
      "x": -3,
      "y": 6,
      "z": -3,
      "name": "Rock_Basalt_Brick"
    },
    {
      "x": -3,
      "y": 0,
      "z": -2,
      "name": "Rock_Basalt_Brick"
    },
    {
      "x": -3,
      "y": 1,
      "z": -2,
      "name": "Rock_Basalt_Brick"
    },
    {
      "x": -3,
      "y": 2,
      "z": -2,
      "name": "Rock_Basalt_Brick_Stairs",
      "rotation": 1
    },
    {
      "x": -3,
      "y": 3,
      "z": -2,
      "name": "Rock_Basalt_Brick_Ornate"
    },
    {
      "x": -3,
      "y": 4,
      "z": -2,
      "name": "Rock_Basalt_Brick_Stairs",
      "rotation": 11
    },
    {
      "x": -3,
      "y": 5,
      "z": -2,
      "name": "Rock_Basalt_Brick"
    },
    {
      "x": -3,
      "y": 6,
      "z": -2,
      "name": "Rock_Basalt_Brick"
    },
    {
      "x": -3,
      "y": 0,
      "z": -1,
      "name": "Rock_Basalt_Brick"
    },
    {
      "x": -3,
      "y": 1,
      "z": -1,
      "name": "Rock_Basalt_Brick"
    },
    {
      "x": -3,
      "y": 2,
      "z": -1,
      "name": "Rock_Basalt_Brick"
    },
    {
      "x": -3,
      "y": 3,
      "z": -1,
      "name": "Rock_Basalt_Brick"
    },
    {
      "x": -3,
      "y": 4,
      "z": -1,
      "name": "Rock_Basalt_Brick"
    },
    {
      "x": -3,
      "y": 5,
      "z": -1,
      "name": "Rock_Basalt_Brick"
    },
    {
      "x": -3,
      "y": 6,
      "z": -1,
      "name": "Rock_Basalt_Brick"
    },
    {
      "x": -3,
      "y": 0,
      "z": 0,
      "name": "Rock_Basalt_Brick"
    },
    {
      "x": -3,
      "y": 1,
      "z": 0,
      "name": "Rock_Basalt_Brick"
    },
    {
      "x": -3,
      "y": 2,
      "z": 0,
      "name": "Rock_Basalt_Brick"
    },
    {
      "x": -3,
      "y": 3,
      "z": 0,
      "name": "Rock_Basalt_Brick"
    },
    {
      "x": -3,
      "y": 4,
      "z": 0,
      "name": "Rock_Basalt_Brick"
    },
    {
      "x": -3,
      "y": 5,
      "z": 0,
      "name": "Rock_Basalt_Brick"
    },
    {
      "x": -3,
      "y": 6,
      "z": 0,
      "name": "Rock_Basalt_Brick"
    },
    {
      "x": -3,
      "y": 0,
      "z": 1,
      "name": "Rock_Basalt_Brick"
    },
    {
      "x": -3,
      "y": 1,
      "z": 1,
      "name": "Rock_Basalt_Brick"
    },
    {
      "x": -3,
      "y": 2,
      "z": 1,
      "name": "Rock_Basalt_Brick"
    },
    {
      "x": -3,
      "y": 3,
      "z": 1,
      "name": "Rock_Basalt_Brick"
    },
    {
      "x": -3,
      "y": 4,
      "z": 1,
      "name": "Rock_Basalt_Brick"
    },
    {
      "x": -3,
      "y": 5,
      "z": 1,
      "name": "Rock_Basalt_Brick"
    },
    {
      "x": -3,
      "y": 6,
      "z": 1,
      "name": "Rock_Basalt_Brick"
    },
    {
      "x": -3,
      "y": 0,
      "z": 2,
      "name": "Rock_Basalt_Brick"
    },
    {
      "x": -3,
      "y": 1,
      "z": 2,
      "name": "Rock_Basalt_Brick"
    },
    {
      "x": -3,
      "y": 2,
      "z": 2,
      "name": "Rock_Basalt_Brick_Stairs",
      "rotation": 1
    },
    {
      "x": -3,
      "y": 3,
      "z": 2,
      "name": "Rock_Basalt_Brick_Ornate"
    },
    {
      "x": -3,
      "y": 4,
      "z": 2,
      "name": "Rock_Basalt_Brick_Stairs",
      "rotation": 11
    },
    {
      "x": -3,
      "y": 5,
      "z": 2,
      "name": "Rock_Basalt_Brick"
    },
    {
      "x": -3,
      "y": 6,
      "z": 2,
      "name": "Rock_Basalt_Brick"
    },
    {
      "x": -3,
      "y": 0,
      "z": 3,
      "name": "Rock_Basalt_Brick"
    },
    {
      "x": -3,
      "y": 1,
      "z": 3,
      "name": "Rock_Basalt_Brick"
    },
    {
      "x": -3,
      "y": 2,
      "z": 3,
      "name": "Rock_Basalt_Brick"
    },
    {
      "x": -3,
      "y": 3,
      "z": 3,
      "name": "Rock_Basalt_Brick"
    },
    {
      "x": -3,
      "y": 4,
      "z": 3,
      "name": "Rock_Basalt_Brick"
    },
    {
      "x": -3,
      "y": 5,
      "z": 3,
      "name": "Rock_Basalt_Brick"
    },
    {
      "x": -3,
      "y": 6,
      "z": 3,
      "name": "Rock_Basalt_Brick"
    },
    {
      "x": -3,
      "y": 0,
      "z": 4,
      "name": "Rock_Basalt_Brick"
    },
    {
      "x": -3,
      "y": 1,
      "z": 4,
      "name": "Rock_Basalt_Brick"
    },
    {
      "x": -3,
      "y": 2,
      "z": 4,
      "name": "Rock_Basalt_Brick"
    },
    {
      "x": -3,
      "y": 3,
      "z": 4,
      "name": "Rock_Basalt_Brick"
    },
    {
      "x": -3,
      "y": 4,
      "z": 4,
      "name": "Rock_Basalt_Brick"
    },
    {
      "x": -3,
      "y": 5,
      "z": 4,
      "name": "Rock_Basalt_Brick"
    },
    {
      "x": -3,
      "y": 6,
      "z": 4,
      "name": "Rock_Basalt_Brick"
    },
    {
      "x": -3,
      "y": 0,
      "z": 5,
      "name": "Rock_Basalt_Brick"
    },
    {
      "x": -3,
      "y": 1,
      "z": 5,
      "name": "Rock_Basalt_Brick"
    },
    {
      "x": -3,
      "y": 2,
      "z": 5,
      "name": "Rock_Basalt_Brick"
    },
    {
      "x": -3,
      "y": 3,
      "z": 5,
      "name": "Rock_Basalt_Brick"
    },
    {
      "x": -3,
      "y": 4,
      "z": 5,
      "name": "Rock_Basalt_Brick"
    },
    {
      "x": -3,
      "y": 5,
      "z": 5,
      "name": "Rock_Basalt_Brick"
    },
    {
      "x": -3,
      "y": 6,
      "z": 5,
      "name": "Rock_Basalt_Brick"
    },
    {
      "x": -3,
      "y": 0,
      "z": 6,
      "name": "Rock_Basalt_Brick"
    },
    {
      "x": -3,
      "y": 1,
      "z": 6,
      "name": "Rock_Basalt_Brick"
    },
    {
      "x": -3,
      "y": 2,
      "z": 6,
      "name": "Rock_Basalt_Brick_Stairs",
      "rotation": 1
    },
    {
      "x": -3,
      "y": 3,
      "z": 6,
      "name": "Rock_Basalt_Brick_Decorative"
    },
    {
      "x": -3,
      "y": 4,
      "z": 6,
      "name": "Rock_Basalt_Brick_Stairs",
      "rotation": 11
    },
    {
      "x": -3,
      "y": 5,
      "z": 6,
      "name": "Rock_Basalt_Brick"
    },
    {
      "x": -3,
      "y": 6,
      "z": 6,
      "name": "Rock_Basalt_Brick"
    },
    {
      "x": -3,
      "y": 0,
      "z": 7,
      "name": "Rock_Basalt_Brick"
    },
    {
      "x": -3,
      "y": 1,
      "z": 7,
      "name": "Rock_Basalt_Brick"
    },
    {
      "x": -3,
      "y": 2,
      "z": 7,
      "name": "Rock_Basalt_Brick"
    },
    {
      "x": -3,
      "y": 3,
      "z": 7,
      "name": "Rock_Basalt_Brick"
    },
    {
      "x": -3,
      "y": 4,
      "z": 7,
      "name": "Rock_Basalt_Brick"
    },
    {
      "x": -3,
      "y": 5,
      "z": 7,
      "name": "Rock_Basalt_Brick"
    },
    {
      "x": -3,
      "y": 6,
      "z": 7,
      "name": "Rock_Basalt_Brick"
    },
    {
      "x": -3,
      "y": 0,
      "z": 8,
      "name": "Rock_Basalt_Brick"
    },
    {
      "x": -3,
      "y": 1,
      "z": 8,
      "name": "Rock_Basalt_Brick"
    },
    {
      "x": -3,
      "y": 2,
      "z": 8,
      "name": "Rock_Basalt_Brick"
    },
    {
      "x": -3,
      "y": 3,
      "z": 8,
      "name": "Rock_Basalt_Brick"
    },
    {
      "x": -3,
      "y": 4,
      "z": 8,
      "name": "Rock_Basalt_Brick"
    },
    {
      "x": -3,
      "y": 5,
      "z": 8,
      "name": "Rock_Basalt_Brick"
    },
    {
      "x": -3,
      "y": 6,
      "z": 8,
      "name": "Rock_Basalt_Brick"
    },
    {
      "x": -2,
      "y": 2,
      "z": -9,
      "name": "Empty"
    },
    {
      "x": -2,
      "y": 3,
      "z": -9,
      "name": "Empty"
    },
    {
      "x": -2,
      "y": 4,
      "z": -9,
      "name": "Empty"
    },
    {
      "x": -2,
      "y": 0,
      "z": -8,
      "name": "Rock_Basalt_Brick"
    },
    {
      "x": -2,
      "y": 1,
      "z": -8,
      "name": "Rock_Basalt_Brick_Stairs",
      "rotation": 1
    },
    {
      "x": -2,
      "y": 5,
      "z": -8,
      "name": "Rock_Basalt_Brick_Stairs",
      "rotation": 11
    },
    {
      "x": -2,
      "y": 6,
      "z": -8,
      "name": "Rock_Basalt_Brick"
    },
    {
      "x": -2,
      "y": 0,
      "z": -7,
      "name": "Rock_Basalt_Brick"
    },
    {
      "x": -2,
      "y": 1,
      "z": -7,
      "name": "Rock_Basalt_Brick_Stairs",
      "rotation": 1
    },
    {
      "x": -2,
      "y": 5,
      "z": -7,
      "name": "Rock_Basalt_Brick_Stairs",
      "rotation": 11
    },
    {
      "x": -2,
      "y": 6,
      "z": -7,
      "name": "Rock_Basalt_Brick"
    },
    {
      "x": -2,
      "y": 0,
      "z": -6,
      "name": "Rock_Basalt_Brick"
    },
    {
      "x": -2,
      "y": 1,
      "z": -6,
      "name": "Rock_Basalt_Brick_Stairs",
      "rotation": 1
    },
    {
      "x": -2,
      "y": 5,
      "z": -6,
      "name": "Rock_Basalt_Brick_Stairs",
      "rotation": 11
    },
    {
      "x": -2,
      "y": 6,
      "z": -6,
      "name": "Rock_Basalt_Brick"
    },
    {
      "x": -2,
      "y": 0,
      "z": -5,
      "name": "Rock_Basalt_Brick"
    },
    {
      "x": -2,
      "y": 1,
      "z": -5,
      "name": "Rock_Basalt_Brick_Stairs",
      "rotation": 1
    },
    {
      "x": -2,
      "y": 5,
      "z": -5,
      "name": "Rock_Basalt_Brick_Stairs",
      "rotation": 11
    },
    {
      "x": -2,
      "y": 6,
      "z": -5,
      "name": "Rock_Basalt_Brick"
    },
    {
      "x": -2,
      "y": 0,
      "z": -4,
      "name": "Rock_Basalt_Brick"
    },
    {
      "x": -2,
      "y": 1,
      "z": -4,
      "name": "Rock_Basalt_Brick_Stairs",
      "rotation": 1
    },
    {
      "x": -2,
      "y": 5,
      "z": -4,
      "name": "Rock_Basalt_Brick_Stairs",
      "rotation": 11
    },
    {
      "x": -2,
      "y": 6,
      "z": -4,
      "name": "Rock_Basalt_Brick"
    },
    {
      "x": -2,
      "y": 0,
      "z": -3,
      "name": "Rock_Basalt_Brick"
    },
    {
      "x": -2,
      "y": 1,
      "z": -3,
      "name": "Rock_Basalt_Brick_Stairs",
      "rotation": 1
    },
    {
      "x": -2,
      "y": 3,
      "z": -3,
      "name": "Wood_Torch_Wall",
      "rotation": 1
    },
    {
      "x": -2,
      "y": 5,
      "z": -3,
      "name": "Rock_Basalt_Brick_Stairs",
      "rotation": 11
    },
    {
      "x": -2,
      "y": 6,
      "z": -3,
      "name": "Rock_Basalt_Brick"
    },
    {
      "x": -2,
      "y": 0,
      "z": -2,
      "name": "Rock_Basalt_Brick"
    },
    {
      "x": -2,
      "y": 1,
      "z": -2,
      "name": "Rock_Basalt_Brick_Stairs",
      "rotation": 1
    },
    {
      "x": -2,
      "y": 5,
      "z": -2,
      "name": "Rock_Basalt_Brick_Stairs",
      "rotation": 11
    },
    {
      "x": -2,
      "y": 6,
      "z": -2,
      "name": "Rock_Basalt_Brick"
    },
    {
      "x": -2,
      "y": 0,
      "z": -1,
      "name": "Rock_Basalt_Brick"
    },
    {
      "x": -2,
      "y": 1,
      "z": -1,
      "name": "Rock_Basalt_Brick_Stairs",
      "rotation": 1
    },
    {
      "x": -2,
      "y": 5,
      "z": -1,
      "name": "Rock_Basalt_Brick_Stairs",
      "rotation": 11
    },
    {
      "x": -2,
      "y": 6,
      "z": -1,
      "name": "Rock_Basalt_Brick"
    },
    {
      "x": -2,
      "y": 0,
      "z": 0,
      "name": "Rock_Basalt_Brick"
    },
    {
      "x": -2,
      "y": 1,
      "z": 0,
      "name": "Rock_Basalt_Brick_Stairs",
      "rotation": 1
    },
    {
      "x": -2,
      "y": 5,
      "z": 0,
      "name": "Rock_Basalt_Brick_Stairs",
      "rotation": 11
    },
    {
      "x": -2,
      "y": 6,
      "z": 0,
      "name": "Rock_Basalt_Brick"
    },
    {
      "x": -2,
      "y": 0,
      "z": 1,
      "name": "Rock_Basalt_Brick"
    },
    {
      "x": -2,
      "y": 1,
      "z": 1,
      "name": "Rock_Basalt_Brick_Stairs",
      "rotation": 1
    },
    {
      "x": -2,
      "y": 5,
      "z": 1,
      "name": "Rock_Basalt_Brick_Stairs",
      "rotation": 11
    },
    {
      "x": -2,
      "y": 6,
      "z": 1,
      "name": "Rock_Basalt_Brick"
    },
    {
      "x": -2,
      "y": 0,
      "z": 2,
      "name": "Rock_Basalt_Brick"
    },
    {
      "x": -2,
      "y": 1,
      "z": 2,
      "name": "Rock_Basalt_Brick_Stairs",
      "rotation": 1
    },
    {
      "x": -2,
      "y": 5,
      "z": 2,
      "name": "Rock_Basalt_Brick_Stairs",
      "rotation": 11
    },
    {
      "x": -2,
      "y": 6,
      "z": 2,
      "name": "Rock_Basalt_Brick"
    },
    {
      "x": -2,
      "y": 0,
      "z": 3,
      "name": "Rock_Basalt_Brick"
    },
    {
      "x": -2,
      "y": 1,
      "z": 3,
      "name": "Rock_Basalt_Brick_Stairs",
      "rotation": 1
    },
    {
      "x": -2,
      "y": 5,
      "z": 3,
      "name": "Rock_Basalt_Brick_Stairs",
      "rotation": 11
    },
    {
      "x": -2,
      "y": 6,
      "z": 3,
      "name": "Rock_Basalt_Brick"
    },
    {
      "x": -2,
      "y": 0,
      "z": 4,
      "name": "Rock_Basalt_Brick"
    },
    {
      "x": -2,
      "y": 1,
      "z": 4,
      "name": "Rock_Basalt_Brick_Stairs",
      "rotation": 1
    },
    {
      "x": -2,
      "y": 5,
      "z": 4,
      "name": "Rock_Basalt_Brick_Stairs",
      "rotation": 11
    },
    {
      "x": -2,
      "y": 6,
      "z": 4,
      "name": "Rock_Basalt_Brick"
    },
    {
      "x": -2,
      "y": 0,
      "z": 5,
      "name": "Rock_Basalt_Brick"
    },
    {
      "x": -2,
      "y": 1,
      "z": 5,
      "name": "Rock_Basalt_Brick_Stairs",
      "rotation": 1
    },
    {
      "x": -2,
      "y": 5,
      "z": 5,
      "name": "Rock_Basalt_Brick_Stairs",
      "rotation": 11
    },
    {
      "x": -2,
      "y": 6,
      "z": 5,
      "name": "Rock_Basalt_Brick"
    },
    {
      "x": -2,
      "y": 0,
      "z": 6,
      "name": "Rock_Basalt_Brick"
    },
    {
      "x": -2,
      "y": 1,
      "z": 6,
      "name": "Rock_Basalt_Brick_Stairs",
      "rotation": 1
    },
    {
      "x": -2,
      "y": 5,
      "z": 6,
      "name": "Rock_Basalt_Brick_Stairs",
      "rotation": 11
    },
    {
      "x": -2,
      "y": 6,
      "z": 6,
      "name": "Rock_Basalt_Brick"
    },
    {
      "x": -2,
      "y": 0,
      "z": 7,
      "name": "Rock_Basalt_Brick"
    },
    {
      "x": -2,
      "y": 1,
      "z": 7,
      "name": "Rock_Basalt_Brick_Stairs",
      "rotation": 1
    },
    {
      "x": -2,
      "y": 5,
      "z": 7,
      "name": "Rock_Basalt_Brick_Stairs",
      "rotation": 11
    },
    {
      "x": -2,
      "y": 6,
      "z": 7,
      "name": "Rock_Basalt_Brick"
    },
    {
      "x": -2,
      "y": 0,
      "z": 8,
      "name": "Rock_Basalt_Brick"
    },
    {
      "x": -2,
      "y": 1,
      "z": 8,
      "name": "Rock_Basalt_Brick_Stairs",
      "rotation": 1
    },
    {
      "x": -2,
      "y": 5,
      "z": 8,
      "name": "Rock_Basalt_Brick_Stairs",
      "rotation": 11
    },
    {
      "x": -2,
      "y": 6,
      "z": 8,
      "name": "Rock_Basalt_Brick"
    },
    {
      "x": -2,
      "y": 2,
      "z": 9,
      "name": "Empty"
    },
    {
      "x": -2,
      "y": 3,
      "z": 9,
      "name": "Empty"
    },
    {
      "x": -2,
      "y": 4,
      "z": 9,
      "name": "Empty"
    },
    {
      "x": -1,
      "y": 1,
      "z": -9,
      "name": "Empty"
    },
    {
      "x": -1,
      "y": 2,
      "z": -9,
      "name": "Empty"
    },
    {
      "x": -1,
      "y": 3,
      "z": -9,
      "name": "Empty"
    },
    {
      "x": -1,
      "y": 4,
      "z": -9,
      "name": "Empty"
    },
    {
      "x": -1,
      "y": 5,
      "z": -9,
      "name": "Empty"
    },
    {
      "x": -1,
      "y": 0,
      "z": -8,
      "name": "Rock_Stone_Aqua"
    },
    {
      "x": -1,
      "y": 6,
      "z": -8,
      "name": "Rock_Stone_Aqua"
    },
    {
      "x": -1,
      "y": 0,
      "z": -7,
      "name": "Rock_Aqua_Brick_Smooth"
    },
    {
      "x": -1,
      "y": 6,
      "z": -7,
      "name": "Rock_Stone_Aqua"
    },
    {
      "x": -1,
      "y": 0,
      "z": -6,
      "name": "Rock_Stone_Aqua"
    },
    {
      "x": -1,
      "y": 6,
      "z": -6,
      "name": "Rock_Stone_Aqua"
    },
    {
      "x": -1,
      "y": 0,
      "z": -5,
      "name": "Rock_Stone_Aqua"
    },
    {
      "x": -1,
      "y": 6,
      "z": -5,
      "name": "Rock_Stone_Aqua"
    },
    {
      "x": -1,
      "y": 0,
      "z": -4,
      "name": "Rock_Aqua_Brick_Smooth"
    },
    {
      "x": -1,
      "y": 6,
      "z": -4,
      "name": "Rock_Stone_Aqua"
    },
    {
      "x": -1,
      "y": 0,
      "z": -3,
      "name": "Rock_Stone_Aqua"
    },
    {
      "x": -1,
      "y": 6,
      "z": -3,
      "name": "Rock_Stone_Aqua"
    },
    {
      "x": -1,
      "y": 0,
      "z": -2,
      "name": "Rock_Stone_Aqua"
    },
    {
      "x": -1,
      "y": 6,
      "z": -2,
      "name": "Rock_Stone_Aqua"
    },
    {
      "x": -1,
      "y": 0,
      "z": -1,
      "name": "Rock_Aqua_Brick_Smooth"
    },
    {
      "x": -1,
      "y": 6,
      "z": -1,
      "name": "Rock_Stone_Aqua"
    },
    {
      "x": -1,
      "y": 0,
      "z": 0,
      "name": "Rock_Stone_Aqua"
    },
    {
      "x": -1,
      "y": 6,
      "z": 0,
      "name": "Rock_Stone_Aqua"
    },
    {
      "x": -1,
      "y": 0,
      "z": 1,
      "name": "Rock_Aqua_Brick_Smooth"
    },
    {
      "x": -1,
      "y": 6,
      "z": 1,
      "name": "Rock_Stone_Aqua"
    },
    {
      "x": -1,
      "y": 0,
      "z": 2,
      "name": "Rock_Stone_Aqua"
    },
    {
      "x": -1,
      "y": 6,
      "z": 2,
      "name": "Rock_Stone_Aqua"
    },
    {
      "x": -1,
      "y": 0,
      "z": 3,
      "name": "Rock_Stone_Aqua"
    },
    {
      "x": -1,
      "y": 6,
      "z": 3,
      "name": "Rock_Stone_Aqua"
    },
    {
      "x": -1,
      "y": 0,
      "z": 4,
      "name": "Rock_Aqua_Brick_Smooth"
    },
    {
      "x": -1,
      "y": 6,
      "z": 4,
      "name": "Rock_Stone_Aqua"
    },
    {
      "x": -1,
      "y": 0,
      "z": 5,
      "name": "Rock_Stone_Aqua"
    },
    {
      "x": -1,
      "y": 6,
      "z": 5,
      "name": "Rock_Stone_Aqua"
    },
    {
      "x": -1,
      "y": 0,
      "z": 6,
      "name": "Rock_Stone_Aqua"
    },
    {
      "x": -1,
      "y": 6,
      "z": 6,
      "name": "Rock_Stone_Aqua"
    },
    {
      "x": -1,
      "y": 0,
      "z": 7,
      "name": "Rock_Aqua_Brick_Smooth"
    },
    {
      "x": -1,
      "y": 6,
      "z": 7,
      "name": "Rock_Stone_Aqua"
    },
    {
      "x": -1,
      "y": 0,
      "z": 8,
      "name": "Rock_Stone_Aqua"
    },
    {
      "x": -1,
      "y": 6,
      "z": 8,
      "name": "Rock_Stone_Aqua"
    },
    {
      "x": -1,
      "y": 1,
      "z": 9,
      "name": "Empty"
    },
    {
      "x": -1,
      "y": 2,
      "z": 9,
      "name": "Empty"
    },
    {
      "x": -1,
      "y": 3,
      "z": 9,
      "name": "Empty"
    },
    {
      "x": -1,
      "y": 4,
      "z": 9,
      "name": "Empty"
    },
    {
      "x": -1,
      "y": 5,
      "z": 9,
      "name": "Empty"
    },
    {
      "x": 0,
      "y": 1,
      "z": -9,
      "name": "Empty"
    },
    {
      "x": 0,
      "y": 2,
      "z": -9,
      "name": "Empty"
    },
    {
      "x": 0,
      "y": 3,
      "z": -9,
      "name": "Empty"
    },
    {
      "x": 0,
      "y": 4,
      "z": -9,
      "name": "Empty"
    },
    {
      "x": 0,
      "y": 5,
      "z": -9,
      "name": "Empty"
    },
    {
      "x": 0,
      "y": 0,
      "z": -8,
      "name": "Rock_Stone_Aqua"
    },
    {
      "x": 0,
      "y": 6,
      "z": -8,
      "name": "Rock_Stone_Aqua"
    },
    {
      "x": 0,
      "y": 0,
      "z": -7,
      "name": "Rock_Stone_Aqua"
    },
    {
      "x": 0,
      "y": 6,
      "z": -7,
      "name": "Rock_Stone_Aqua"
    },
    {
      "x": 0,
      "y": 0,
      "z": -6,
      "name": "Rock_Stone_Aqua"
    },
    {
      "x": 0,
      "y": 6,
      "z": -6,
      "name": "Rock_Stone_Aqua"
    },
    {
      "x": 0,
      "y": 0,
      "z": -5,
      "name": "Rock_Stone_Aqua"
    },
    {
      "x": 0,
      "y": 6,
      "z": -5,
      "name": "Rock_Stone_Aqua"
    },
    {
      "x": 0,
      "y": 0,
      "z": -4,
      "name": "Rock_Stone_Aqua"
    },
    {
      "x": 0,
      "y": 6,
      "z": -4,
      "name": "Rock_Stone_Aqua"
    },
    {
      "x": 0,
      "y": 0,
      "z": -3,
      "name": "Rock_Stone_Aqua"
    },
    {
      "x": 0,
      "y": 6,
      "z": -3,
      "name": "Rock_Stone_Aqua"
    },
    {
      "x": 0,
      "y": 0,
      "z": -2,
      "name": "Rock_Stone_Aqua"
    },
    {
      "x": 0,
      "y": 6,
      "z": -2,
      "name": "Rock_Stone_Aqua"
    },
    {
      "x": 0,
      "y": 0,
      "z": -1,
      "name": "Rock_Stone_Aqua"
    },
    {
      "x": 0,
      "y": 6,
      "z": -1,
      "name": "Rock_Stone_Aqua"
    },
    {
      "x": 0,
      "y": 0,
      "z": 0,
      "name": "Rock_Stone_Aqua"
    },
    {
      "x": 0,
      "y": 6,
      "z": 0,
      "name": "Rock_Stone_Aqua"
    },
    {
      "x": 0,
      "y": 0,
      "z": 1,
      "name": "Rock_Stone_Aqua"
    },
    {
      "x": 0,
      "y": 6,
      "z": 1,
      "name": "Rock_Stone_Aqua"
    },
    {
      "x": 0,
      "y": 0,
      "z": 2,
      "name": "Rock_Stone_Aqua"
    },
    {
      "x": 0,
      "y": 6,
      "z": 2,
      "name": "Rock_Stone_Aqua"
    },
    {
      "x": 0,
      "y": 0,
      "z": 3,
      "name": "Rock_Stone_Aqua"
    },
    {
      "x": 0,
      "y": 6,
      "z": 3,
      "name": "Rock_Stone_Aqua"
    },
    {
      "x": 0,
      "y": 0,
      "z": 4,
      "name": "Rock_Stone_Aqua"
    },
    {
      "x": 0,
      "y": 6,
      "z": 4,
      "name": "Rock_Stone_Aqua"
    },
    {
      "x": 0,
      "y": 0,
      "z": 5,
      "name": "Rock_Stone_Aqua"
    },
    {
      "x": 0,
      "y": 6,
      "z": 5,
      "name": "Rock_Stone_Aqua"
    },
    {
      "x": 0,
      "y": 0,
      "z": 6,
      "name": "Rock_Stone_Aqua"
    },
    {
      "x": 0,
      "y": 6,
      "z": 6,
      "name": "Rock_Stone_Aqua"
    },
    {
      "x": 0,
      "y": 0,
      "z": 7,
      "name": "Rock_Stone_Aqua"
    },
    {
      "x": 0,
      "y": 6,
      "z": 7,
      "name": "Rock_Stone_Aqua"
    },
    {
      "x": 0,
      "y": 0,
      "z": 8,
      "name": "Rock_Stone_Aqua"
    },
    {
      "x": 0,
      "y": 6,
      "z": 8,
      "name": "Rock_Stone_Aqua"
    },
    {
      "x": 0,
      "y": 1,
      "z": 9,
      "name": "Empty"
    },
    {
      "x": 0,
      "y": 2,
      "z": 9,
      "name": "Empty"
    },
    {
      "x": 0,
      "y": 3,
      "z": 9,
      "name": "Empty"
    },
    {
      "x": 0,
      "y": 4,
      "z": 9,
      "name": "Empty"
    },
    {
      "x": 0,
      "y": 5,
      "z": 9,
      "name": "Empty"
    },
    {
      "x": 1,
      "y": 1,
      "z": -9,
      "name": "Empty"
    },
    {
      "x": 1,
      "y": 2,
      "z": -9,
      "name": "Empty"
    },
    {
      "x": 1,
      "y": 3,
      "z": -9,
      "name": "Empty"
    },
    {
      "x": 1,
      "y": 4,
      "z": -9,
      "name": "Empty"
    },
    {
      "x": 1,
      "y": 5,
      "z": -9,
      "name": "Empty"
    },
    {
      "x": 1,
      "y": 0,
      "z": -8,
      "name": "Rock_Stone_Aqua"
    },
    {
      "x": 1,
      "y": 6,
      "z": -8,
      "name": "Rock_Stone_Aqua"
    },
    {
      "x": 1,
      "y": 0,
      "z": -7,
      "name": "Rock_Aqua_Brick_Smooth"
    },
    {
      "x": 1,
      "y": 6,
      "z": -7,
      "name": "Rock_Stone_Aqua"
    },
    {
      "x": 1,
      "y": 0,
      "z": -6,
      "name": "Rock_Stone_Aqua"
    },
    {
      "x": 1,
      "y": 6,
      "z": -6,
      "name": "Rock_Stone_Aqua"
    },
    {
      "x": 1,
      "y": 0,
      "z": -5,
      "name": "Rock_Stone_Aqua"
    },
    {
      "x": 1,
      "y": 6,
      "z": -5,
      "name": "Rock_Stone_Aqua"
    },
    {
      "x": 1,
      "y": 0,
      "z": -4,
      "name": "Rock_Aqua_Brick_Smooth"
    },
    {
      "x": 1,
      "y": 6,
      "z": -4,
      "name": "Rock_Stone_Aqua"
    },
    {
      "x": 1,
      "y": 0,
      "z": -3,
      "name": "Rock_Stone_Aqua"
    },
    {
      "x": 1,
      "y": 6,
      "z": -3,
      "name": "Rock_Stone_Aqua"
    },
    {
      "x": 1,
      "y": 0,
      "z": -2,
      "name": "Rock_Stone_Aqua"
    },
    {
      "x": 1,
      "y": 6,
      "z": -2,
      "name": "Rock_Stone_Aqua"
    },
    {
      "x": 1,
      "y": 0,
      "z": -1,
      "name": "Rock_Aqua_Brick_Smooth"
    },
    {
      "x": 1,
      "y": 6,
      "z": -1,
      "name": "Rock_Stone_Aqua"
    },
    {
      "x": 1,
      "y": 0,
      "z": 0,
      "name": "Rock_Stone_Aqua"
    },
    {
      "x": 1,
      "y": 6,
      "z": 0,
      "name": "Rock_Stone_Aqua"
    },
    {
      "x": 1,
      "y": 0,
      "z": 1,
      "name": "Rock_Aqua_Brick_Smooth"
    },
    {
      "x": 1,
      "y": 6,
      "z": 1,
      "name": "Rock_Stone_Aqua"
    },
    {
      "x": 1,
      "y": 0,
      "z": 2,
      "name": "Rock_Stone_Aqua"
    },
    {
      "x": 1,
      "y": 6,
      "z": 2,
      "name": "Rock_Stone_Aqua"
    },
    {
      "x": 1,
      "y": 0,
      "z": 3,
      "name": "Rock_Stone_Aqua"
    },
    {
      "x": 1,
      "y": 6,
      "z": 3,
      "name": "Rock_Stone_Aqua"
    },
    {
      "x": 1,
      "y": 0,
      "z": 4,
      "name": "Rock_Aqua_Brick_Smooth"
    },
    {
      "x": 1,
      "y": 6,
      "z": 4,
      "name": "Rock_Stone_Aqua"
    },
    {
      "x": 1,
      "y": 0,
      "z": 5,
      "name": "Rock_Stone_Aqua"
    },
    {
      "x": 1,
      "y": 6,
      "z": 5,
      "name": "Rock_Stone_Aqua"
    },
    {
      "x": 1,
      "y": 0,
      "z": 6,
      "name": "Rock_Stone_Aqua"
    },
    {
      "x": 1,
      "y": 6,
      "z": 6,
      "name": "Rock_Stone_Aqua"
    },
    {
      "x": 1,
      "y": 0,
      "z": 7,
      "name": "Rock_Aqua_Brick_Smooth"
    },
    {
      "x": 1,
      "y": 6,
      "z": 7,
      "name": "Rock_Stone_Aqua"
    },
    {
      "x": 1,
      "y": 0,
      "z": 8,
      "name": "Rock_Stone_Aqua"
    },
    {
      "x": 1,
      "y": 6,
      "z": 8,
      "name": "Rock_Stone_Aqua"
    },
    {
      "x": 1,
      "y": 1,
      "z": 9,
      "name": "Empty"
    },
    {
      "x": 1,
      "y": 2,
      "z": 9,
      "name": "Empty"
    },
    {
      "x": 1,
      "y": 3,
      "z": 9,
      "name": "Empty"
    },
    {
      "x": 1,
      "y": 4,
      "z": 9,
      "name": "Empty"
    },
    {
      "x": 1,
      "y": 5,
      "z": 9,
      "name": "Empty"
    },
    {
      "x": 2,
      "y": 2,
      "z": -9,
      "name": "Empty"
    },
    {
      "x": 2,
      "y": 3,
      "z": -9,
      "name": "Empty"
    },
    {
      "x": 2,
      "y": 4,
      "z": -9,
      "name": "Empty"
    },
    {
      "x": 2,
      "y": 0,
      "z": -8,
      "name": "Rock_Basalt_Brick"
    },
    {
      "x": 2,
      "y": 1,
      "z": -8,
      "name": "Rock_Basalt_Brick_Stairs",
      "rotation": 3
    },
    {
      "x": 2,
      "y": 5,
      "z": -8,
      "name": "Rock_Basalt_Brick_Stairs",
      "rotation": 9
    },
    {
      "x": 2,
      "y": 6,
      "z": -8,
      "name": "Rock_Basalt_Brick"
    },
    {
      "x": 2,
      "y": 0,
      "z": -7,
      "name": "Rock_Basalt_Brick"
    },
    {
      "x": 2,
      "y": 1,
      "z": -7,
      "name": "Rock_Basalt_Brick_Stairs",
      "rotation": 3
    },
    {
      "x": 2,
      "y": 5,
      "z": -7,
      "name": "Rock_Basalt_Brick_Stairs",
      "rotation": 9
    },
    {
      "x": 2,
      "y": 6,
      "z": -7,
      "name": "Rock_Basalt_Brick"
    },
    {
      "x": 2,
      "y": 0,
      "z": -6,
      "name": "Rock_Basalt_Brick"
    },
    {
      "x": 2,
      "y": 1,
      "z": -6,
      "name": "Rock_Basalt_Brick_Stairs",
      "rotation": 3
    },
    {
      "x": 2,
      "y": 5,
      "z": -6,
      "name": "Rock_Basalt_Brick_Stairs",
      "rotation": 9
    },
    {
      "x": 2,
      "y": 6,
      "z": -6,
      "name": "Rock_Basalt_Brick"
    },
    {
      "x": 2,
      "y": 0,
      "z": -5,
      "name": "Rock_Basalt_Brick"
    },
    {
      "x": 2,
      "y": 1,
      "z": -5,
      "name": "Rock_Basalt_Brick_Stairs",
      "rotation": 3
    },
    {
      "x": 2,
      "y": 5,
      "z": -5,
      "name": "Rock_Basalt_Brick_Stairs",
      "rotation": 9
    },
    {
      "x": 2,
      "y": 6,
      "z": -5,
      "name": "Rock_Basalt_Brick"
    },
    {
      "x": 2,
      "y": 0,
      "z": -4,
      "name": "Rock_Basalt_Brick"
    },
    {
      "x": 2,
      "y": 1,
      "z": -4,
      "name": "Rock_Basalt_Brick_Stairs",
      "rotation": 3
    },
    {
      "x": 2,
      "y": 5,
      "z": -4,
      "name": "Rock_Basalt_Brick_Stairs",
      "rotation": 9
    },
    {
      "x": 2,
      "y": 6,
      "z": -4,
      "name": "Rock_Basalt_Brick"
    },
    {
      "x": 2,
      "y": 0,
      "z": -3,
      "name": "Rock_Basalt_Brick"
    },
    {
      "x": 2,
      "y": 1,
      "z": -3,
      "name": "Rock_Basalt_Brick_Stairs",
      "rotation": 3
    },
    {
      "x": 2,
      "y": 5,
      "z": -3,
      "name": "Rock_Basalt_Brick_Stairs",
      "rotation": 9
    },
    {
      "x": 2,
      "y": 6,
      "z": -3,
      "name": "Rock_Basalt_Brick"
    },
    {
      "x": 2,
      "y": 0,
      "z": -2,
      "name": "Rock_Basalt_Brick"
    },
    {
      "x": 2,
      "y": 1,
      "z": -2,
      "name": "Rock_Basalt_Brick_Stairs",
      "rotation": 3
    },
    {
      "x": 2,
      "y": 5,
      "z": -2,
      "name": "Rock_Basalt_Brick_Stairs",
      "rotation": 9
    },
    {
      "x": 2,
      "y": 6,
      "z": -2,
      "name": "Rock_Basalt_Brick"
    },
    {
      "x": 2,
      "y": 0,
      "z": -1,
      "name": "Rock_Basalt_Brick"
    },
    {
      "x": 2,
      "y": 1,
      "z": -1,
      "name": "Rock_Basalt_Brick_Stairs",
      "rotation": 3
    },
    {
      "x": 2,
      "y": 5,
      "z": -1,
      "name": "Rock_Basalt_Brick_Stairs",
      "rotation": 9
    },
    {
      "x": 2,
      "y": 6,
      "z": -1,
      "name": "Rock_Basalt_Brick"
    },
    {
      "x": 2,
      "y": 0,
      "z": 0,
      "name": "Rock_Basalt_Brick"
    },
    {
      "x": 2,
      "y": 1,
      "z": 0,
      "name": "Rock_Basalt_Brick_Stairs",
      "rotation": 3
    },
    {
      "x": 2,
      "y": 5,
      "z": 0,
      "name": "Rock_Basalt_Brick_Stairs",
      "rotation": 9
    },
    {
      "x": 2,
      "y": 6,
      "z": 0,
      "name": "Rock_Basalt_Brick"
    },
    {
      "x": 2,
      "y": 0,
      "z": 1,
      "name": "Rock_Basalt_Brick"
    },
    {
      "x": 2,
      "y": 1,
      "z": 1,
      "name": "Rock_Basalt_Brick_Stairs",
      "rotation": 3
    },
    {
      "x": 2,
      "y": 5,
      "z": 1,
      "name": "Rock_Basalt_Brick_Stairs",
      "rotation": 9
    },
    {
      "x": 2,
      "y": 6,
      "z": 1,
      "name": "Rock_Basalt_Brick"
    },
    {
      "x": 2,
      "y": 0,
      "z": 2,
      "name": "Rock_Basalt_Brick"
    },
    {
      "x": 2,
      "y": 1,
      "z": 2,
      "name": "Rock_Basalt_Brick_Stairs",
      "rotation": 3
    },
    {
      "x": 2,
      "y": 5,
      "z": 2,
      "name": "Rock_Basalt_Brick_Stairs",
      "rotation": 9
    },
    {
      "x": 2,
      "y": 6,
      "z": 2,
      "name": "Rock_Basalt_Brick"
    },
    {
      "x": 2,
      "y": 0,
      "z": 3,
      "name": "Rock_Basalt_Brick"
    },
    {
      "x": 2,
      "y": 1,
      "z": 3,
      "name": "Rock_Basalt_Brick_Stairs",
      "rotation": 3
    },
    {
      "x": 2,
      "y": 3,
      "z": 3,
      "name": "Wood_Torch_Wall",
      "rotation": 3
    },
    {
      "x": 2,
      "y": 5,
      "z": 3,
      "name": "Rock_Basalt_Brick_Stairs",
      "rotation": 9
    },
    {
      "x": 2,
      "y": 6,
      "z": 3,
      "name": "Rock_Basalt_Brick"
    },
    {
      "x": 2,
      "y": 0,
      "z": 4,
      "name": "Rock_Basalt_Brick"
    },
    {
      "x": 2,
      "y": 1,
      "z": 4,
      "name": "Rock_Basalt_Brick_Stairs",
      "rotation": 3
    },
    {
      "x": 2,
      "y": 5,
      "z": 4,
      "name": "Rock_Basalt_Brick_Stairs",
      "rotation": 9
    },
    {
      "x": 2,
      "y": 6,
      "z": 4,
      "name": "Rock_Basalt_Brick"
    },
    {
      "x": 2,
      "y": 0,
      "z": 5,
      "name": "Rock_Basalt_Brick"
    },
    {
      "x": 2,
      "y": 1,
      "z": 5,
      "name": "Rock_Basalt_Brick_Stairs",
      "rotation": 3
    },
    {
      "x": 2,
      "y": 5,
      "z": 5,
      "name": "Rock_Basalt_Brick_Stairs",
      "rotation": 9
    },
    {
      "x": 2,
      "y": 6,
      "z": 5,
      "name": "Rock_Basalt_Brick"
    },
    {
      "x": 2,
      "y": 0,
      "z": 6,
      "name": "Rock_Basalt_Brick"
    },
    {
      "x": 2,
      "y": 1,
      "z": 6,
      "name": "Rock_Basalt_Brick_Stairs",
      "rotation": 3
    },
    {
      "x": 2,
      "y": 5,
      "z": 6,
      "name": "Rock_Basalt_Brick_Stairs",
      "rotation": 9
    },
    {
      "x": 2,
      "y": 6,
      "z": 6,
      "name": "Rock_Basalt_Brick"
    },
    {
      "x": 2,
      "y": 0,
      "z": 7,
      "name": "Rock_Basalt_Brick"
    },
    {
      "x": 2,
      "y": 1,
      "z": 7,
      "name": "Rock_Basalt_Brick_Stairs",
      "rotation": 3
    },
    {
      "x": 2,
      "y": 5,
      "z": 7,
      "name": "Rock_Basalt_Brick_Stairs",
      "rotation": 9
    },
    {
      "x": 2,
      "y": 6,
      "z": 7,
      "name": "Rock_Basalt_Brick"
    },
    {
      "x": 2,
      "y": 0,
      "z": 8,
      "name": "Rock_Basalt_Brick"
    },
    {
      "x": 2,
      "y": 1,
      "z": 8,
      "name": "Rock_Basalt_Brick_Stairs",
      "rotation": 3
    },
    {
      "x": 2,
      "y": 5,
      "z": 8,
      "name": "Rock_Basalt_Brick_Stairs",
      "rotation": 9
    },
    {
      "x": 2,
      "y": 6,
      "z": 8,
      "name": "Rock_Basalt_Brick"
    },
    {
      "x": 2,
      "y": 2,
      "z": 9,
      "name": "Empty"
    },
    {
      "x": 2,
      "y": 3,
      "z": 9,
      "name": "Empty"
    },
    {
      "x": 2,
      "y": 4,
      "z": 9,
      "name": "Empty"
    },
    {
      "x": 3,
      "y": 0,
      "z": -8,
      "name": "Rock_Basalt_Brick"
    },
    {
      "x": 3,
      "y": 1,
      "z": -8,
      "name": "Rock_Basalt_Brick"
    },
    {
      "x": 3,
      "y": 2,
      "z": -8,
      "name": "Rock_Basalt_Brick"
    },
    {
      "x": 3,
      "y": 3,
      "z": -8,
      "name": "Rock_Basalt_Brick"
    },
    {
      "x": 3,
      "y": 4,
      "z": -8,
      "name": "Rock_Basalt_Brick"
    },
    {
      "x": 3,
      "y": 5,
      "z": -8,
      "name": "Rock_Basalt_Brick"
    },
    {
      "x": 3,
      "y": 6,
      "z": -8,
      "name": "Rock_Basalt_Brick"
    },
    {
      "x": 3,
      "y": 0,
      "z": -7,
      "name": "Rock_Basalt_Brick"
    },
    {
      "x": 3,
      "y": 1,
      "z": -7,
      "name": "Rock_Basalt_Brick"
    },
    {
      "x": 3,
      "y": 2,
      "z": -7,
      "name": "Rock_Basalt_Brick"
    },
    {
      "x": 3,
      "y": 3,
      "z": -7,
      "name": "Rock_Basalt_Brick"
    },
    {
      "x": 3,
      "y": 4,
      "z": -7,
      "name": "Rock_Basalt_Brick"
    },
    {
      "x": 3,
      "y": 5,
      "z": -7,
      "name": "Rock_Basalt_Brick"
    },
    {
      "x": 3,
      "y": 6,
      "z": -7,
      "name": "Rock_Basalt_Brick"
    },
    {
      "x": 3,
      "y": 0,
      "z": -6,
      "name": "Rock_Basalt_Brick"
    },
    {
      "x": 3,
      "y": 1,
      "z": -6,
      "name": "Rock_Basalt_Brick"
    },
    {
      "x": 3,
      "y": 2,
      "z": -6,
      "name": "Rock_Basalt_Brick_Stairs",
      "rotation": 3
    },
    {
      "x": 3,
      "y": 3,
      "z": -6,
      "name": "Rock_Basalt_Brick_Decorative"
    },
    {
      "x": 3,
      "y": 4,
      "z": -6,
      "name": "Rock_Basalt_Brick_Stairs",
      "rotation": 9
    },
    {
      "x": 3,
      "y": 5,
      "z": -6,
      "name": "Rock_Basalt_Brick"
    },
    {
      "x": 3,
      "y": 6,
      "z": -6,
      "name": "Rock_Basalt_Brick"
    },
    {
      "x": 3,
      "y": 0,
      "z": -5,
      "name": "Rock_Basalt_Brick"
    },
    {
      "x": 3,
      "y": 1,
      "z": -5,
      "name": "Rock_Basalt_Brick"
    },
    {
      "x": 3,
      "y": 2,
      "z": -5,
      "name": "Rock_Basalt_Brick"
    },
    {
      "x": 3,
      "y": 3,
      "z": -5,
      "name": "Rock_Basalt_Brick"
    },
    {
      "x": 3,
      "y": 4,
      "z": -5,
      "name": "Rock_Basalt_Brick"
    },
    {
      "x": 3,
      "y": 5,
      "z": -5,
      "name": "Rock_Basalt_Brick"
    },
    {
      "x": 3,
      "y": 6,
      "z": -5,
      "name": "Rock_Basalt_Brick"
    },
    {
      "x": 3,
      "y": 0,
      "z": -4,
      "name": "Rock_Basalt_Brick"
    },
    {
      "x": 3,
      "y": 1,
      "z": -4,
      "name": "Rock_Basalt_Brick"
    },
    {
      "x": 3,
      "y": 2,
      "z": -4,
      "name": "Rock_Basalt_Brick"
    },
    {
      "x": 3,
      "y": 3,
      "z": -4,
      "name": "Rock_Basalt_Brick"
    },
    {
      "x": 3,
      "y": 4,
      "z": -4,
      "name": "Rock_Basalt_Brick"
    },
    {
      "x": 3,
      "y": 5,
      "z": -4,
      "name": "Rock_Basalt_Brick"
    },
    {
      "x": 3,
      "y": 6,
      "z": -4,
      "name": "Rock_Basalt_Brick"
    },
    {
      "x": 3,
      "y": 0,
      "z": -3,
      "name": "Rock_Basalt_Brick"
    },
    {
      "x": 3,
      "y": 1,
      "z": -3,
      "name": "Rock_Basalt_Brick"
    },
    {
      "x": 3,
      "y": 2,
      "z": -3,
      "name": "Rock_Basalt_Brick"
    },
    {
      "x": 3,
      "y": 3,
      "z": -3,
      "name": "Rock_Basalt_Brick"
    },
    {
      "x": 3,
      "y": 4,
      "z": -3,
      "name": "Rock_Basalt_Brick"
    },
    {
      "x": 3,
      "y": 5,
      "z": -3,
      "name": "Rock_Basalt_Brick"
    },
    {
      "x": 3,
      "y": 6,
      "z": -3,
      "name": "Rock_Basalt_Brick"
    },
    {
      "x": 3,
      "y": 0,
      "z": -2,
      "name": "Rock_Basalt_Brick"
    },
    {
      "x": 3,
      "y": 1,
      "z": -2,
      "name": "Rock_Basalt_Brick"
    },
    {
      "x": 3,
      "y": 2,
      "z": -2,
      "name": "Rock_Basalt_Brick_Stairs",
      "rotation": 3
    },
    {
      "x": 3,
      "y": 3,
      "z": -2,
      "name": "Rock_Basalt_Brick_Ornate"
    },
    {
      "x": 3,
      "y": 4,
      "z": -2,
      "name": "Rock_Basalt_Brick_Stairs",
      "rotation": 9
    },
    {
      "x": 3,
      "y": 5,
      "z": -2,
      "name": "Rock_Basalt_Brick"
    },
    {
      "x": 3,
      "y": 6,
      "z": -2,
      "name": "Rock_Basalt_Brick"
    },
    {
      "x": 3,
      "y": 0,
      "z": -1,
      "name": "Rock_Basalt_Brick"
    },
    {
      "x": 3,
      "y": 1,
      "z": -1,
      "name": "Rock_Basalt_Brick"
    },
    {
      "x": 3,
      "y": 2,
      "z": -1,
      "name": "Rock_Basalt_Brick"
    },
    {
      "x": 3,
      "y": 3,
      "z": -1,
      "name": "Rock_Basalt_Brick"
    },
    {
      "x": 3,
      "y": 4,
      "z": -1,
      "name": "Rock_Basalt_Brick"
    },
    {
      "x": 3,
      "y": 5,
      "z": -1,
      "name": "Rock_Basalt_Brick"
    },
    {
      "x": 3,
      "y": 6,
      "z": -1,
      "name": "Rock_Basalt_Brick"
    },
    {
      "x": 3,
      "y": 0,
      "z": 0,
      "name": "Rock_Basalt_Brick"
    },
    {
      "x": 3,
      "y": 1,
      "z": 0,
      "name": "Rock_Basalt_Brick"
    },
    {
      "x": 3,
      "y": 2,
      "z": 0,
      "name": "Rock_Basalt_Brick"
    },
    {
      "x": 3,
      "y": 3,
      "z": 0,
      "name": "Rock_Basalt_Brick"
    },
    {
      "x": 3,
      "y": 4,
      "z": 0,
      "name": "Rock_Basalt_Brick"
    },
    {
      "x": 3,
      "y": 5,
      "z": 0,
      "name": "Rock_Basalt_Brick"
    },
    {
      "x": 3,
      "y": 6,
      "z": 0,
      "name": "Rock_Basalt_Brick"
    },
    {
      "x": 3,
      "y": 0,
      "z": 1,
      "name": "Rock_Basalt_Brick"
    },
    {
      "x": 3,
      "y": 1,
      "z": 1,
      "name": "Rock_Basalt_Brick"
    },
    {
      "x": 3,
      "y": 2,
      "z": 1,
      "name": "Rock_Basalt_Brick"
    },
    {
      "x": 3,
      "y": 3,
      "z": 1,
      "name": "Rock_Basalt_Brick"
    },
    {
      "x": 3,
      "y": 4,
      "z": 1,
      "name": "Rock_Basalt_Brick"
    },
    {
      "x": 3,
      "y": 5,
      "z": 1,
      "name": "Rock_Basalt_Brick"
    },
    {
      "x": 3,
      "y": 6,
      "z": 1,
      "name": "Rock_Basalt_Brick"
    },
    {
      "x": 3,
      "y": 0,
      "z": 2,
      "name": "Rock_Basalt_Brick"
    },
    {
      "x": 3,
      "y": 1,
      "z": 2,
      "name": "Rock_Basalt_Brick"
    },
    {
      "x": 3,
      "y": 2,
      "z": 2,
      "name": "Rock_Basalt_Brick_Stairs",
      "rotation": 3
    },
    {
      "x": 3,
      "y": 3,
      "z": 2,
      "name": "Rock_Basalt_Brick_Ornate"
    },
    {
      "x": 3,
      "y": 4,
      "z": 2,
      "name": "Rock_Basalt_Brick_Stairs",
      "rotation": 9
    },
    {
      "x": 3,
      "y": 5,
      "z": 2,
      "name": "Rock_Basalt_Brick"
    },
    {
      "x": 3,
      "y": 6,
      "z": 2,
      "name": "Rock_Basalt_Brick"
    },
    {
      "x": 3,
      "y": 0,
      "z": 3,
      "name": "Rock_Basalt_Brick"
    },
    {
      "x": 3,
      "y": 1,
      "z": 3,
      "name": "Rock_Basalt_Brick"
    },
    {
      "x": 3,
      "y": 2,
      "z": 3,
      "name": "Rock_Basalt_Brick"
    },
    {
      "x": 3,
      "y": 3,
      "z": 3,
      "name": "Rock_Basalt_Brick"
    },
    {
      "x": 3,
      "y": 4,
      "z": 3,
      "name": "Rock_Basalt_Brick"
    },
    {
      "x": 3,
      "y": 5,
      "z": 3,
      "name": "Rock_Basalt_Brick"
    },
    {
      "x": 3,
      "y": 6,
      "z": 3,
      "name": "Rock_Basalt_Brick"
    },
    {
      "x": 3,
      "y": 0,
      "z": 4,
      "name": "Rock_Basalt_Brick"
    },
    {
      "x": 3,
      "y": 1,
      "z": 4,
      "name": "Rock_Basalt_Brick"
    },
    {
      "x": 3,
      "y": 2,
      "z": 4,
      "name": "Rock_Basalt_Brick"
    },
    {
      "x": 3,
      "y": 3,
      "z": 4,
      "name": "Rock_Basalt_Brick"
    },
    {
      "x": 3,
      "y": 4,
      "z": 4,
      "name": "Rock_Basalt_Brick"
    },
    {
      "x": 3,
      "y": 5,
      "z": 4,
      "name": "Rock_Basalt_Brick"
    },
    {
      "x": 3,
      "y": 6,
      "z": 4,
      "name": "Rock_Basalt_Brick"
    },
    {
      "x": 3,
      "y": 0,
      "z": 5,
      "name": "Rock_Basalt_Brick"
    },
    {
      "x": 3,
      "y": 1,
      "z": 5,
      "name": "Rock_Basalt_Brick"
    },
    {
      "x": 3,
      "y": 2,
      "z": 5,
      "name": "Rock_Basalt_Brick"
    },
    {
      "x": 3,
      "y": 3,
      "z": 5,
      "name": "Rock_Basalt_Brick"
    },
    {
      "x": 3,
      "y": 4,
      "z": 5,
      "name": "Rock_Basalt_Brick"
    },
    {
      "x": 3,
      "y": 5,
      "z": 5,
      "name": "Rock_Basalt_Brick"
    },
    {
      "x": 3,
      "y": 6,
      "z": 5,
      "name": "Rock_Basalt_Brick"
    },
    {
      "x": 3,
      "y": 0,
      "z": 6,
      "name": "Rock_Basalt_Brick"
    },
    {
      "x": 3,
      "y": 1,
      "z": 6,
      "name": "Rock_Basalt_Brick"
    },
    {
      "x": 3,
      "y": 2,
      "z": 6,
      "name": "Rock_Basalt_Brick_Stairs",
      "rotation": 3
    },
    {
      "x": 3,
      "y": 3,
      "z": 6,
      "name": "Rock_Basalt_Brick_Decorative"
    },
    {
      "x": 3,
      "y": 4,
      "z": 6,
      "name": "Rock_Basalt_Brick_Stairs",
      "rotation": 9
    },
    {
      "x": 3,
      "y": 5,
      "z": 6,
      "name": "Rock_Basalt_Brick"
    },
    {
      "x": 3,
      "y": 6,
      "z": 6,
      "name": "Rock_Basalt_Brick"
    },
    {
      "x": 3,
      "y": 0,
      "z": 7,
      "name": "Rock_Basalt_Brick"
    },
    {
      "x": 3,
      "y": 1,
      "z": 7,
      "name": "Rock_Basalt_Brick"
    },
    {
      "x": 3,
      "y": 2,
      "z": 7,
      "name": "Rock_Basalt_Brick"
    },
    {
      "x": 3,
      "y": 3,
      "z": 7,
      "name": "Rock_Basalt_Brick"
    },
    {
      "x": 3,
      "y": 4,
      "z": 7,
      "name": "Rock_Basalt_Brick"
    },
    {
      "x": 3,
      "y": 5,
      "z": 7,
      "name": "Rock_Basalt_Brick"
    },
    {
      "x": 3,
      "y": 6,
      "z": 7,
      "name": "Rock_Basalt_Brick"
    },
    {
      "x": 3,
      "y": 0,
      "z": 8,
      "name": "Rock_Basalt_Brick"
    },
    {
      "x": 3,
      "y": 1,
      "z": 8,
      "name": "Rock_Basalt_Brick"
    },
    {
      "x": 3,
      "y": 2,
      "z": 8,
      "name": "Rock_Basalt_Brick"
    },
    {
      "x": 3,
      "y": 3,
      "z": 8,
      "name": "Rock_Basalt_Brick"
    },
    {
      "x": 3,
      "y": 4,
      "z": 8,
      "name": "Rock_Basalt_Brick"
    },
    {
      "x": 3,
      "y": 5,
      "z": 8,
      "name": "Rock_Basalt_Brick"
    },
    {
      "x": 3,
      "y": 6,
      "z": 8,
      "name": "Rock_Basalt_Brick"
    }
  ]
}