{
  "version": 8,
  "blockIdVersion": 11,
  "anchorX": 0,
  "anchorY": 4,
  "anchorZ": 0,
  "blocks": [
    {
      "x": -8,
      "y": 1,
      "z": -5,
      "name": "Rock_Basalt_Brick"
    },
    {
      "x": -8,
      "y": 2,
      "z": -5,
      "name": "Rock_Basalt_Brick"
    },
    {
      "x": -8,
      "y": 3,
      "z": -5,
      "name": "Rock_Basalt_Brick"
    },
    {
      "x": -8,
      "y": 4,
      "z": -5,
      "name": "Rock_Basalt_Brick"
    },
    {
      "x": -8,
      "y": 5,
      "z": -5,
      "name": "Rock_Basalt_Brick"
    },
    {
      "x": -8,
      "y": 6,
      "z": -5,
      "name": "Rock_Basalt_Brick"
    },
    {
      "x": -8,
      "y": 7,
      "z": -5,
      "name": "Rock_Basalt_Brick"
    },
    {
      "x": -8,
      "y": 1,
      "z": -4,
      "name": "Rock_Basalt_Brick"
    },
    {
      "x": -8,
      "y": 2,
      "z": -4,
      "name": "Rock_Basalt_Brick"
    },
    {
      "x": -8,
      "y": 3,
      "z": -4,
      "name": "Rock_Basalt_Brick"
    },
    {
      "x": -8,
      "y": 4,
      "z": -4,
      "name": "Rock_Basalt_Brick"
    },
    {
      "x": -8,
      "y": 5,
      "z": -4,
      "name": "Rock_Basalt_Brick"
    },
    {
      "x": -8,
      "y": 6,
      "z": -4,
      "name": "Rock_Basalt_Brick"
    },
    {
      "x": -8,
      "y": 7,
      "z": -4,
      "name": "Rock_Basalt_Brick"
    },
    {
      "x": -8,
      "y": 1,
      "z": -3,
      "name": "Rock_Basalt_Brick_Smooth"
    },
    {
      "x": -8,
      "y": 2,
      "z": -3,
      "name": "Wood_Goldenwood_Planks"
    },
    {
      "x": -8,
      "y": 3,
      "z": -3,
      "name": "Wood_Goldenwood_Planks"
    },
    {
      "x": -8,
      "y": 4,
      "z": -3,
      "name": "Wood_Goldenwood_Planks"
    },
    {
      "x": -8,
      "y": 5,
      "z": -3,
      "name": "Wood_Goldenwood_Planks"
    },
    {
      "x": -8,
      "y": 6,
      "z": -3,
      "name": "Wood_Goldenwood_Planks"
    },
    {
      "x": -8,
      "y": 7,
      "z": -3,
      "name": "Rock_Basalt_Brick_Smooth"
    },
    {
      "x": -8,
      "y": 1,
      "z": -2,
      "name": "Rock_Basalt_Brick_Smooth"
    },
    {
      "x": -8,
      "y": 2,
      "z": -2,
      "name": "Rock_Basalt_Brick_Decorative"
    },
    {
      "x": -8,
      "y": 3,
      "z": -2,
      "name": "Rock_Basalt_Brick_Smooth"
    },
    {
      "x": -8,
      "y": 4,
      "z": -2,
      "name": "Rock_Basalt_Brick_Smooth"
    },
    {
      "x": -8,
      "y": 5,
      "z": -2,
      "name": "Rock_Basalt_Brick_Smooth"
    },
    {
      "x": -8,
      "y": 6,
      "z": -2,
      "name": "Rock_Basalt_Brick_Decorative"
    },
    {
      "x": -8,
      "y": 7,
      "z": -2,
      "name": "Rock_Basalt_Brick_Smooth"
    },
    {
      "x": -8,
      "y": 1,
      "z": -1,
      "name": "Rock_Basalt_Brick_Smooth"
    },
    {
      "x": -8,
      "y": 2,
      "z": -1,
      "name": "Rock_Basalt_Brick_Smooth"
    },
    {
      "x": -8,
      "y": 3,
      "z": -1,
      "name": "Rock_Basalt_Brick_Smooth"
    },
    {
      "x": -8,
      "y": 4,
      "z": -1,
      "name": "Rock_Basalt_Brick_Smooth"
    },
    {
      "x": -8,
      "y": 5,
      "z": -1,
      "name": "Rock_Basalt_Brick_Smooth"
    },
    {
      "x": -8,
      "y": 6,
      "z": -1,
      "name": "Rock_Basalt_Brick_Smooth"
    },
    {
      "x": -8,
      "y": 7,
      "z": -1,
      "name": "Rock_Basalt_Brick_Smooth"
    },
    {
      "x": -8,
      "y": 1,
      "z": 0,
      "name": "Rock_Basalt_Brick_Smooth"
    },
    {
      "x": -8,
      "y": 2,
      "z": 0,
      "name": "Rock_Basalt_Brick_Smooth"
    },
    {
      "x": -8,
      "y": 3,
      "z": 0,
      "name": "Rock_Basalt_Brick_Smooth"
    },
    {
      "x": -8,
      "y": 4,
      "z": 0,
      "name": "Rock_Basalt_Brick_Smooth"
    },
    {
      "x": -8,
      "y": 5,
      "z": 0,
      "name": "Rock_Basalt_Brick_Smooth"
    },
    {
      "x": -8,
      "y": 6,
      "z": 0,
      "name": "Rock_Basalt_Brick_Smooth"
    },
    {
      "x": -8,
      "y": 7,
      "z": 0,
      "name": "Rock_Basalt_Brick_Smooth"
    },
    {
      "x": -8,
      "y": 1,
      "z": 1,
      "name": "Rock_Basalt_Brick_Smooth"
    },
    {
      "x": -8,
      "y": 2,
      "z": 1,
      "name": "Rock_Basalt_Brick_Smooth"
    },
    {
      "x": -8,
      "y": 3,
      "z": 1,
      "name": "Rock_Basalt_Brick_Smooth"
    },
    {
      "x": -8,
      "y": 4,
      "z": 1,
      "name": "Rock_Basalt_Brick_Smooth"
    },
    {
      "x": -8,
      "y": 5,
      "z": 1,
      "name": "Rock_Basalt_Brick_Smooth"
    },
    {
      "x": -8,
      "y": 6,
      "z": 1,
      "name": "Rock_Basalt_Brick_Smooth"
    },
    {
      "x": -8,
      "y": 7,
      "z": 1,
      "name": "Rock_Basalt_Brick_Smooth"
    },
    {
      "x": -8,
      "y": 1,
      "z": 2,
      "name": "Rock_Basalt_Brick_Smooth"
    },
    {
      "x": -8,
      "y": 2,
      "z": 2,
      "name": "Rock_Basalt_Brick_Decorative"
    },
    {
      "x": -8,
      "y": 3,
      "z": 2,
      "name": "Rock_Basalt_Brick_Smooth"
    },
    {
      "x": -8,
      "y": 4,
      "z": 2,
      "name": "Rock_Basalt_Brick_Smooth"
    },
    {
      "x": -8,
      "y": 5,
      "z": 2,
      "name": "Rock_Basalt_Brick_Smooth"
    },
    {
      "x": -8,
      "y": 6,
      "z": 2,
      "name": "Rock_Basalt_Brick_Decorative"
    },
    {
      "x": -8,
      "y": 7,
      "z": 2,
      "name": "Rock_Basalt_Brick_Smooth"
    },
    {
      "x": -8,
      "y": 1,
      "z": 3,
      "name": "Rock_Basalt_Brick_Smooth"
    },
    {
      "x": -8,
      "y": 2,
      "z": 3,
      "name": "Wood_Goldenwood_Planks"
    },
    {
      "x": -8,
      "y": 3,
      "z": 3,
      "name": "Wood_Goldenwood_Planks"
    },
    {
      "x": -8,
      "y": 4,
      "z": 3,
      "name": "Wood_Goldenwood_Planks"
    },
    {
      "x": -8,
      "y": 5,
      "z": 3,
      "name": "Wood_Goldenwood_Planks"
    },
    {
      "x": -8,
      "y": 6,
      "z": 3,
      "name": "Wood_Goldenwood_Planks"
    },
    {
      "x": -8,
      "y": 7,
      "z": 3,
      "name": "Rock_Basalt_Brick_Smooth"
    },
    {
      "x": -8,
      "y": 1,
      "z": 4,
      "name": "Rock_Basalt_Brick"
    },
    {
      "x": -8,
      "y": 2,
      "z": 4,
      "name": "Rock_Basalt_Brick"
    },
    {
      "x": -8,
      "y": 3,
      "z": 4,
      "name": "Rock_Basalt_Brick"
    },
    {
      "x": -8,
      "y": 4,
      "z": 4,
      "name": "Rock_Basalt_Brick"
    },
    {
      "x": -8,
      "y": 5,
      "z": 4,
      "name": "Rock_Basalt_Brick"
    },
    {
      "x": -8,
      "y": 6,
      "z": 4,
      "name": "Rock_Basalt_Brick"
    },
    {
      "x": -8,
      "y": 7,
      "z": 4,
      "name": "Rock_Basalt_Brick"
    },
    {
      "x": -8,
      "y": 1,
      "z": 5,
      "name": "Rock_Basalt_Brick"
    },
    {
      "x": -8,
      "y": 2,
      "z": 5,
      "name": "Rock_Basalt_Brick"
    },
    {
      "x": -8,
      "y": 3,
      "z": 5,
      "name": "Rock_Basalt_Brick"
    },
    {
      "x": -8,
      "y": 4,
      "z": 5,
      "name": "Rock_Basalt_Brick"
    },
    {
      "x": -8,
      "y": 5,
      "z": 5,
      "name": "Rock_Basalt_Brick"
    },
    {
      "x": -8,
      "y": 6,
      "z": 5,
      "name": "Rock_Basalt_Brick"
    },
    {
      "x": -8,
      "y": 7,
      "z": 5,
      "name": "Rock_Basalt_Brick"
    },
    {
      "x": -7,
      "y": 1,
      "z": -6,
      "name": "Rock_Basalt_Brick"
    },
    {
      "x": -7,
      "y": 2,
      "z": -6,
      "name": "Rock_Basalt_Brick"
    },
    {
      "x": -7,
      "y": 3,
      "z": -6,
      "name": "Rock_Basalt_Brick"
    },
    {
      "x": -7,
      "y": 4,
      "z": -6,
      "name": "Rock_Basalt_Brick"
    },
    {
      "x": -7,
      "y": 5,
      "z": -6,
      "name": "Rock_Basalt_Brick"
    },
    {
      "x": -7,
      "y": 6,
      "z": -6,
      "name": "Rock_Basalt_Brick"
    },
    {
      "x": -7,
      "y": 7,
      "z": -6,
      "name": "Rock_Basalt_Brick"
    },
    {
      "x": -7,
      "y": 1,
      "z": -5,
      "name": "Rock_Stone_Aqua"
    },
    {
      "x": -7,
      "y": 5,
      "z": -5,
      "name": "Rock_Aqua_Stalactite_Large",
      "filler": 31744,
      "rotation": 8
    },
    {
      "x": -7,
      "y": 6,
      "z": -5,
      "name": "Rock_Aqua_Stalactite_Large",
      "rotation": 8
    },
    {
      "x": -7,
      "y": 7,
      "z": -5,
      "name": "Rock_Stone_Aqua"
    },
    {
      "x": -7,
      "y": 1,
      "z": -4,
      "name": "Rock_Stone_Aqua"
    },
    {
      "x": -7,
      "y": 7,
      "z": -4,
      "name": "Rock_Stone_Aqua"
    },
    {
      "x": -7,
      "y": 1,
      "z": -3,
      "name": "Rock_Stone_Aqua"
    },
    {
      "x": -7,
      "y": 2,
      "z": -3,
      "name": "Wood_Goldenwood_Fence",
      "rotation": 1
    },
    {
      "x": -7,
      "y": 3,
      "z": -3,
      "name": "Wood_Goldenwood_Fence",
      "rotation": 1
    },
    {
      "x": -7,
      "y": 4,
      "z": -3,
      "name": "Wood_Goldenwood_Fence",
      "rotation": 1
    },
    {
      "x": -7,
      "y": 5,
      "z": -3,
      "name": "Wood_Goldenwood_Fence",
      "rotation": 1
    },
    {
      "x": -7,
      "y": 6,
      "z": -3,
      "name": "Wood_Goldenwood_Fence",
      "rotation": 1
    },
    {
      "x": -7,
      "y": 7,
      "z": -3,
      "name": "Rock_Stone_Aqua"
    },
    {
      "x": -7,
      "y": 1,
      "z": -2,
      "name": "Rock_Stone_Aqua"
    },
    {
      "x": -7,
      "y": 7,
      "z": -2,
      "name": "Rock_Stone_Aqua"
    },
    {
      "x": -7,
      "y": 1,
      "z": -1,
      "name": "Rock_Stone_Aqua"
    },
    {
      "x": -7,
      "y": 5,
      "z": -1,
      "name": "Rock_Aqua_Stalactite_Large",
      "filler": 31744,
      "rotation": 8
    },
    {
      "x": -7,
      "y": 6,
      "z": -1,
      "name": "Rock_Aqua_Stalactite_Large",
      "rotation": 8
    },
    {
      "x": -7,
      "y": 7,
      "z": -1,
      "name": "Rock_Stone_Aqua"
    },
    {
      "x": -7,
      "y": 1,
      "z": 0,
      "name": "Rock_Stone_Aqua"
    },
    {
      "x": -7,
      "y": 7,
      "z": 0,
      "name": "Rock_Stone_Aqua"
    },
    {
      "x": -7,
      "y": 1,
      "z": 1,
      "name": "Rock_Stone_Aqua"
    },
    {
      "x": -7,
      "y": 7,
      "z": 1,
      "name": "Rock_Stone_Aqua"
    },
    {
      "x": -7,
      "y": 1,
      "z": 2,
      "name": "Rock_Stone_Aqua"
    },
    {
      "x": -7,
      "y": 7,
      "z": 2,
      "name": "Rock_Stone_Aqua"
    },
    {
      "x": -7,
      "y": 1,
      "z": 3,
      "name": "Rock_Stone_Aqua"
    },
    {
      "x": -7,
      "y": 2,
      "z": 3,
      "name": "Wood_Goldenwood_Fence",
      "rotation": 1
    },
    {
      "x": -7,
      "y": 3,
      "z": 3,
      "name": "Wood_Goldenwood_Fence",
      "rotation": 1
    },
    {
      "x": -7,
      "y": 4,
      "z": 3,
      "name": "Wood_Goldenwood_Fence",
      "rotation": 1
    },
    {
      "x": -7,
      "y": 5,
      "z": 3,
      "name": "Wood_Goldenwood_Fence",
      "rotation": 1
    },
    {
      "x": -7,
      "y": 6,
      "z": 3,
      "name": "Wood_Goldenwood_Fence",
      "rotation": 1
    },
    {
      "x": -7,
      "y": 7,
      "z": 3,
      "name": "Rock_Stone_Aqua"
    },
    {
      "x": -7,
      "y": 1,
      "z": 4,
      "name": "Rock_Stone_Aqua"
    },
    {
      "x": -7,
      "y": 7,
      "z": 4,
      "name": "Rock_Stone_Aqua"
    },
    {
      "x": -7,
      "y": 1,
      "z": 5,
      "name": "Rock_Stone_Aqua"
    },
    {
      "x": -7,
      "y": 7,
      "z": 5,
      "name": "Rock_Stone_Aqua"
    },
    {
      "x": -7,
      "y": 1,
      "z": 6,
      "name": "Rock_Basalt_Brick"
    },
    {
      "x": -7,
      "y": 2,
      "z": 6,
      "name": "Rock_Basalt_Brick"
    },
    {
      "x": -7,
      "y": 3,
      "z": 6,
      "name": "Rock_Basalt_Brick"
    },
    {
      "x": -7,
      "y": 4,
      "z": 6,
      "name": "Rock_Basalt_Brick"
    },
    {
      "x": -7,
      "y": 5,
      "z": 6,
      "name": "Rock_Basalt_Brick"
    },
    {
      "x": -7,
      "y": 6,
      "z": 6,
      "name": "Rock_Basalt_Brick"
    },
    {
      "x": -7,
      "y": 7,
      "z": 6,
      "name": "Rock_Basalt_Brick"
    },
    {
      "x": -6,
      "y": 1,
      "z": -7,
      "name": "Rock_Basalt_Brick"
    },
    {
      "x": -6,
      "y": 2,
      "z": -7,
      "name": "Rock_Basalt_Brick"
    },
    {
      "x": -6,
      "y": 3,
      "z": -7,
      "name": "Rock_Basalt_Brick"
    },
    {
      "x": -6,
      "y": 4,
      "z": -7,
      "name": "Rock_Basalt_Brick"
    },
    {
      "x": -6,
      "y": 5,
      "z": -7,
      "name": "Rock_Basalt_Brick"
    },
    {
      "x": -6,
      "y": 6,
      "z": -7,
      "name": "Rock_Basalt_Brick"
    },
    {
      "x": -6,
      "y": 7,
      "z": -7,
      "name": "Rock_Basalt_Brick"
    },
    {
      "x": -6,
      "y": 1,
      "z": -6,
      "name": "Rock_Stone_Aqua"
    },
    {
      "x": -6,
      "y": 7,
      "z": -6,
      "name": "Rock_Stone_Aqua"
    },
    {
      "x": -6,
      "y": 1,
      "z": -5,
      "name": "Rock_Stone_Aqua"
    },
    {
      "x": -6,
      "y": 7,
      "z": -5,
      "name": "Rock_Stone_Aqua"
    },
    {
      "x": -6,
      "y": 1,
      "z": -4,
      "name": "Rock_Stone_Aqua"
    },
    {
      "x": -6,
      "y": 7,
      "z": -4,
      "name": "Rock_Stone_Aqua"
    },
    {
      "x": -6,
      "y": 1,
      "z": -3,
      "name": "Rock_Stone_Aqua"
    },
    {
      "x": -6,
      "y": 7,
      "z": -3,
      "name": "Rock_Stone_Aqua"
    },
    {
      "x": -6,
      "y": 1,
      "z": -2,
      "name": "Rock_Stone_Aqua"
    },
    {
      "x": -6,
      "y": 7,
      "z": -2,
      "name": "Rock_Stone_Aqua"
    },
    {
      "x": -6,
      "y": 1,
      "z": -1,
      "name": "Rock_Stone_Aqua"
    },
    {
      "x": -6,
      "y": 7,
      "z": -1,
      "name": "Rock_Stone_Aqua"
    },
    {
      "x": -6,
      "y": 1,
      "z": 0,
      "name": "Rock_Stone_Aqua"
    },
    {
      "x": -6,
      "y": 7,
      "z": 0,
      "name": "Rock_Stone_Aqua"
    },
    {
      "x": -6,
      "y": 1,
      "z": 1,
      "name": "Rock_Stone_Aqua"
    },
    {
      "x": -6,
      "y": 7,
      "z": 1,
      "name": "Rock_Stone_Aqua"
    },
    {
      "x": -6,
      "y": 1,
      "z": 2,
      "name": "Rock_Stone_Aqua"
    },
    {
      "x": -6,
      "y": 7,
      "z": 2,
      "name": "Rock_Stone_Aqua"
    },
    {
      "x": -6,
      "y": 1,
      "z": 3,
      "name": "Rock_Stone_Aqua"
    },
    {
      "x": -6,
      "y": 7,
      "z": 3,
      "name": "Rock_Stone_Aqua"
    },
    {
      "x": -6,
      "y": 1,
      "z": 4,
      "name": "Rock_Stone_Aqua"
    },
    {
      "x": -6,
      "y": 7,
      "z": 4,
      "name": "Rock_Stone_Aqua"
    },
    {
      "x": -6,
      "y": 1,
      "z": 5,
      "name": "Rock_Stone_Aqua"
    },
    {
      "x": -6,
      "y": 2,
      "z": 5,
      "name": "Rock_Aqua_Stalactite_Large"
    },
    {
      "x": -6,
      "y": 3,
      "z": 5,
      "name": "Rock_Aqua_Stalactite_Large",
      "filler": 1024
    },
    {
      "x": -6,
      "y": 7,
      "z": 5,
      "name": "Rock_Stone_Aqua"
    },
    {
      "x": -6,
      "y": 1,
      "z": 6,
      "name": "Rock_Stone_Aqua"
    },
    {
      "x": -6,
      "y": 7,
      "z": 6,
      "name": "Rock_Stone_Aqua"
    },
    {
      "x": -6,
      "y": 1,
      "z": 7,
      "name": "Rock_Basalt_Brick"
    },
    {
      "x": -6,
      "y": 2,
      "z": 7,
      "name": "Rock_Basalt_Brick"
    },
    {
      "x": -6,
      "y": 3,
      "z": 7,
      "name": "Rock_Basalt_Brick"
    },
    {
      "x": -6,
      "y": 4,
      "z": 7,
      "name": "Rock_Basalt_Brick"
    },
    {
      "x": -6,
      "y": 5,
      "z": 7,
      "name": "Rock_Basalt_Brick"
    },
    {
      "x": -6,
      "y": 6,
      "z": 7,
      "name": "Rock_Basalt_Brick"
    },
    {
      "x": -6,
      "y": 7,
      "z": 7,
      "name": "Rock_Basalt_Brick"
    },
    {
      "x": -5,
      "y": 1,
      "z": -8,
      "name": "Rock_Basalt_Brick"
    },
    {
      "x": -5,
      "y": 2,
      "z": -8,
      "name": "Rock_Basalt_Brick"
    },
    {
      "x": -5,
      "y": 3,
      "z": -8,
      "name": "Rock_Basalt_Brick"
    },
    {
      "x": -5,
      "y": 4,
      "z": -8,
      "name": "Rock_Basalt_Brick"
    },
    {
      "x": -5,
      "y": 5,
      "z": -8,
      "name": "Rock_Basalt_Brick"
    },
    {
      "x": -5,
      "y": 6,
      "z": -8,
      "name": "Rock_Basalt_Brick"
    },
    {
      "x": -5,
      "y": 7,
      "z": -8,
      "name": "Rock_Basalt_Brick"
    },
    {
      "x": -5,
      "y": 1,
      "z": -7,
      "name": "Rock_Stone_Aqua"
    },
    {
      "x": -5,
      "y": 7,
      "z": -7,
      "name": "Rock_Stone_Aqua"
    },
    {
      "x": -5,
      "y": 1,
      "z": -6,
      "name": "Rock_Stone_Aqua"
    },
    {
      "x": -5,
      "y": 7,
      "z": -6,
      "name": "Rock_Stone_Aqua"
    },
    {
      "x": -5,
      "y": 1,
      "z": -5,
      "name": "Rock_Stone_Aqua"
    },
    {
      "x": -5,
      "y": 7,
      "z": -5,
      "name": "Rock_Stone_Aqua"
    },
    {
      "x": -5,
      "y": 1,
      "z": -4,
      "name": "Rock_Stone_Aqua"
    },
    {
      "x": -5,
      "y": 7,
      "z": -4,
      "name": "Rock_Basalt_Brick"
    },
    {
      "x": -5,
      "y": 1,
      "z": -3,
      "name": "Rock_Stone_Aqua"
    },
    {
      "x": -5,
      "y": 7,
      "z": -3,
      "name": "Rock_Basalt_Brick"
    },
    {
      "x": -5,
      "y": 1,
      "z": -2,
      "name": "Rock_Stone_Aqua"
    },
    {
      "x": -5,
      "y": 7,
      "z": -2,
      "name": "Rock_Basalt_Brick"
    },
    {
      "x": -5,
      "y": 8,
      "z": -2,
      "name": "Rock_Basalt_Brick"
    },
    {
      "x": -5,
      "y": 9,
      "z": -2,
      "name": "Rock_Basalt_Brick"
    },
    {
      "x": -5,
      "y": 10,
      "z": -2,
      "name": "Rock_Basalt_Brick"
    },
    {
      "x": -5,
      "y": 11,
      "z": -2,
      "name": "Rock_Basalt_Brick"
    },
    {
      "x": -5,
      "y": 12,
      "z": -2,
      "name": "Rock_Basalt_Brick"
    },
    {
      "x": -5,
      "y": 13,
      "z": -2,
      "name": "Rock_Basalt_Brick"
    },
    {
      "x": -5,
      "y": 14,
      "z": -2,
      "name": "Rock_Basalt_Brick"
    },
    {
      "x": -5,
      "y": 15,
      "z": -2,
      "name": "Rock_Basalt_Brick"
    },
    {
      "x": -5,
      "y": 16,
      "z": -2,
      "name": "Rock_Basalt_Brick"
    },
    {
      "x": -5,
      "y": 17,
      "z": -2,
      "name": "Rock_Basalt_Brick"
    },
    {
      "x": -5,
      "y": 18,
      "z": -2,
      "name": "Rock_Basalt_Brick"
    },
    {
      "x": -5,
      "y": 19,
      "z": -2,
      "name": "Rock_Basalt_Brick"
    },
    {
      "x": -5,
      "y": 20,
      "z": -2,
      "name": "Rock_Basalt_Brick"
    },
    {
      "x": -5,
      "y": 21,
      "z": -2,
      "name": "Rock_Basalt_Brick"
    },
    {
      "x": -5,
      "y": 22,
      "z": -2,
      "name": "Rock_Basalt_Brick"
    },
    {
      "x": -5,
      "y": 23,
      "z": -2,
      "name": "Rock_Basalt_Brick"
    },
    {
      "x": -5,
      "y": 24,
      "z": -2,
      "name": "Rock_Basalt_Brick"
    },
    {
      "x": -5,
      "y": 25,
      "z": -2,
      "name": "Rock_Basalt_Brick"
    },
    {
      "x": -5,
      "y": 1,
      "z": -1,
      "name": "Rock_Stone_Aqua"
    },
    {
      "x": -5,
      "y": 7,
      "z": -1,
      "name": "Rock_Basalt_Brick"
    },
    {
      "x": -5,
      "y": 8,
      "z": -1,
      "name": "Rock_Basalt_Brick"
    },
    {
      "x": -5,
      "y": 9,
      "z": -1,
      "name": "Rock_Basalt_Brick"
    },
    {
      "x": -5,
      "y": 10,
      "z": -1,
      "name": "Rock_Basalt_Brick"
    },
    {
      "x": -5,
      "y": 11,
      "z": -1,
      "name": "Rock_Basalt_Brick"
    },
    {
      "x": -5,
      "y": 12,
      "z": -1,
      "name": "Rock_Basalt_Brick"
    },
    {
      "x": -5,
      "y": 13,
      "z": -1,
      "name": "Rock_Basalt_Brick"
    },
    {
      "x": -5,
      "y": 14,
      "z": -1,
      "name": "Rock_Basalt_Brick"
    },
    {
      "x": -5,
      "y": 15,
      "z": -1,
      "name": "Rock_Basalt_Brick"
    },
    {
      "x": -5,
      "y": 16,
      "z": -1,
      "name": "Rock_Basalt_Brick"
    },
    {
      "x": -5,
      "y": 17,
      "z": -1,
      "name": "Rock_Basalt_Brick"
    },
    {
      "x": -5,
      "y": 18,
      "z": -1,
      "name": "Rock_Basalt_Brick"
    },
    {
      "x": -5,
      "y": 19,
      "z": -1,
      "name": "Rock_Basalt_Brick"
    },
    {
      "x": -5,
      "y": 20,
      "z": -1,
      "name": "Rock_Basalt_Brick"
    },
    {
      "x": -5,
      "y": 21,
      "z": -1,
      "name": "Rock_Basalt_Brick"
    },
    {
      "x": -5,
      "y": 22,
      "z": -1,
      "name": "Rock_Basalt_Brick"
    },
    {
      "x": -5,
      "y": 23,
      "z": -1,
      "name": "Rock_Basalt_Brick"
    },
    {
      "x": -5,
      "y": 24,
      "z": -1,
      "name": "Rock_Basalt_Brick"
    },
    {
      "x": -5,
      "y": 25,
      "z": -1,
      "name": "Rock_Basalt_Brick"
    },
    {
      "x": -5,
      "y": 1,
      "z": 0,
      "name": "Rock_Stone_Aqua"
    },
    {
      "x": -5,
      "y": 7,
      "z": 0,
      "name": "Rock_Basalt_Brick"
    },
    {
      "x": -5,
      "y": 8,
      "z": 0,
      "name": "Rock_Basalt_Brick_Stairs",
      "rotation": 1
    },
    {
      "x": -5,
      "y": 9,
      "z": 0,
      "name": "Rock_Basalt_Brick_Decorative"
    },
    {
      "x": -5,
      "y": 10,
      "z": 0,
      "name": "Rock_Basalt_Brick_Stairs",
      "rotation": 11
    },
    {
      "x": -5,
      "y": 11,
      "z": 0,
      "name": "Rock_Basalt_Brick"
    },
    {
      "x": -5,
      "y": 12,
      "z": 0,
      "name": "Rock_Basalt_Brick_Stairs",
      "rotation": 1
    },
    {
      "x": -5,
      "y": 13,
      "z": 0,
      "name": "Rock_Basalt_Brick_Decorative"
    },
    {
      "x": -5,
      "y": 14,
      "z": 0,
      "name": "Rock_Basalt_Brick_Stairs",
      "rotation": 11
    },
    {
      "x": -5,
      "y": 15,
      "z": 0,
      "name": "Rock_Basalt_Brick"
    },
    {
      "x": -5,
      "y": 16,
      "z": 0,
      "name": "Rock_Basalt_Brick_Stairs",
      "rotation": 1
    },
    {
      "x": -5,
      "y": 17,
      "z": 0,
      "name": "Rock_Basalt_Brick_Decorative"
    },
    {
      "x": -5,
      "y": 18,
      "z": 0,
      "name": "Rock_Basalt_Brick_Stairs",
      "rotation": 11
    },
    {
      "x": -5,
      "y": 19,
      "z": 0,
      "name": "Rock_Basalt_Brick"
    },
    {
      "x": -5,
      "y": 20,
      "z": 0,
      "name": "Rock_Basalt_Brick_Stairs",
      "rotation": 1
    },
    {
      "x": -5,
      "y": 21,
      "z": 0,
      "name": "Rock_Basalt_Brick_Decorative"
    },
    {
      "x": -5,
      "y": 22,
      "z": 0,
      "name": "Rock_Basalt_Brick_Stairs",
      "rotation": 11
    },
    {
      "x": -5,
      "y": 23,
      "z": 0,
      "name": "Rock_Basalt_Brick"
    },
    {
      "x": -5,
      "y": 24,
      "z": 0,
      "name": "Rock_Basalt_Brick_Stairs",
      "rotation": 1
    },
    {
      "x": -5,
      "y": 25,
      "z": 0,
      "name": "Rock_Basalt_Brick_Decorative"
    },
    {
      "x": -5,
      "y": 1,
      "z": 1,
      "name": "Rock_Stone_Aqua"
    },
    {
      "x": -5,
      "y": 7,
      "z": 1,
      "name": "Rock_Basalt_Brick"
    },
    {
      "x": -5,
      "y": 8,
      "z": 1,
      "name": "Rock_Basalt_Brick"
    },
    {
      "x": -5,
      "y": 9,
      "z": 1,
      "name": "Rock_Basalt_Brick"
    },
    {
      "x": -5,
      "y": 10,
      "z": 1,
      "name": "Rock_Basalt_Brick"
    },
    {
      "x": -5,
      "y": 11,
      "z": 1,
      "name": "Rock_Basalt_Brick"
    },
    {
      "x": -5,
      "y": 12,
      "z": 1,
      "name": "Rock_Basalt_Brick"
    },
    {
      "x": -5,
      "y": 13,
      "z": 1,
      "name": "Rock_Basalt_Brick"
    },
    {
      "x": -5,
      "y": 14,
      "z": 1,
      "name": "Rock_Basalt_Brick"
    },
    {
      "x": -5,
      "y": 15,
      "z": 1,
      "name": "Rock_Basalt_Brick"
    },
    {
      "x": -5,
      "y": 16,
      "z": 1,
      "name": "Rock_Basalt_Brick"
    },
    {
      "x": -5,
      "y": 17,
      "z": 1,
      "name": "Rock_Basalt_Brick"
    },
    {
      "x": -5,
      "y": 18,
      "z": 1,
      "name": "Rock_Basalt_Brick"
    },
    {
      "x": -5,
      "y": 19,
      "z": 1,
      "name": "Rock_Basalt_Brick"
    },
    {
      "x": -5,
      "y": 20,
      "z": 1,
      "name": "Rock_Basalt_Brick"
    },
    {
      "x": -5,
      "y": 21,
      "z": 1,
      "name": "Rock_Basalt_Brick"
    },
    {
      "x": -5,
      "y": 22,
      "z": 1,
      "name": "Rock_Basalt_Brick"
    },
    {
      "x": -5,
      "y": 23,
      "z": 1,
      "name": "Rock_Basalt_Brick"
    },
    {
      "x": -5,
      "y": 24,
      "z": 1,
      "name": "Rock_Basalt_Brick"
    },
    {
      "x": -5,
      "y": 25,
      "z": 1,
      "name": "Rock_Basalt_Brick"
    },
    {
      "x": -5,
      "y": 1,
      "z": 2,
      "name": "Rock_Stone_Aqua"
    },
    {
      "x": -5,
      "y": 7,
      "z": 2,
      "name": "Rock_Basalt_Brick"
    },
    {
      "x": -5,
      "y": 8,
      "z": 2,
      "name": "Rock_Basalt_Brick"
    },
    {
      "x": -5,
      "y": 9,
      "z": 2,
      "name": "Rock_Basalt_Brick"
    },
    {
      "x": -5,
      "y": 10,
      "z": 2,
      "name": "Rock_Basalt_Brick"
    },
    {
      "x": -5,
      "y": 11,
      "z": 2,
      "name": "Rock_Basalt_Brick"
    },
    {
      "x": -5,
      "y": 12,
      "z": 2,
      "name": "Rock_Basalt_Brick"
    },
    {
      "x": -5,
      "y": 13,
      "z": 2,
      "name": "Rock_Basalt_Brick"
    },
    {
      "x": -5,
      "y": 14,
      "z": 2,
      "name": "Rock_Basalt_Brick"
    },
    {
      "x": -5,
      "y": 15,
      "z": 2,
      "name": "Rock_Basalt_Brick"
    },
    {
      "x": -5,
      "y": 16,
      "z": 2,
      "name": "Rock_Basalt_Brick"
    },
    {
      "x": -5,
      "y": 17,
      "z": 2,
      "name": "Rock_Basalt_Brick"
    },
    {
      "x": -5,
      "y": 18,
      "z": 2,
      "name": "Rock_Basalt_Brick"
    },
    {
      "x": -5,
      "y": 19,
      "z": 2,
      "name": "Rock_Basalt_Brick"
    },
    {
      "x": -5,
      "y": 20,
      "z": 2,
      "name": "Rock_Basalt_Brick"
    },
    {
      "x": -5,
      "y": 21,
      "z": 2,
      "name": "Rock_Basalt_Brick"
    },
    {
      "x": -5,
      "y": 22,
      "z": 2,
      "name": "Rock_Basalt_Brick"
    },
    {
      "x": -5,
      "y": 23,
      "z": 2,
      "name": "Rock_Basalt_Brick"
    },
    {
      "x": -5,
      "y": 24,
      "z": 2,
      "name": "Rock_Basalt_Brick"
    },
    {
      "x": -5,
      "y": 25,
      "z": 2,
      "name": "Rock_Basalt_Brick"
    },
    {
      "x": -5,
      "y": 1,
      "z": 3,
      "name": "Rock_Stone_Aqua"
    },
    {
      "x": -5,
      "y": 7,
      "z": 3,
      "name": "Rock_Basalt_Brick"
    },
    {
      "x": -5,
      "y": 1,
      "z": 4,
      "name": "Rock_Stone_Aqua"
    },
    {
      "x": -5,
      "y": 7,
      "z": 4,
      "name": "Rock_Basalt_Brick"
    },
    {
      "x": -5,
      "y": 1,
      "z": 5,
      "name": "Rock_Stone_Aqua"
    },
    {
      "x": -5,
      "y": 7,
      "z": 5,
      "name": "Rock_Stone_Aqua"
    },
    {
      "x": -5,
      "y": 1,
      "z": 6,
      "name": "Rock_Stone_Aqua"
    },
    {
      "x": -5,
      "y": 7,
      "z": 6,
      "name": "Rock_Stone_Aqua"
    },
    {
      "x": -5,
      "y": 1,
      "z": 7,
      "name": "Rock_Stone_Aqua"
    },
    {
      "x": -5,
      "y": 7,
      "z": 7,
      "name": "Rock_Stone_Aqua"
    },
    {
      "x": -5,
      "y": 1,
      "z": 8,
      "name": "Rock_Basalt_Brick"
    },
    {
      "x": -5,
      "y": 2,
      "z": 8,
      "name": "Rock_Basalt_Brick"
    },
    {
      "x": -5,
      "y": 3,
      "z": 8,
      "name": "Rock_Basalt_Brick"
    },
    {
      "x": -5,
      "y": 4,
      "z": 8,
      "name": "Rock_Basalt_Brick"
    },
    {
      "x": -5,
      "y": 5,
      "z": 8,
      "name": "Rock_Basalt_Brick"
    },
    {
      "x": -5,
      "y": 6,
      "z": 8,
      "name": "Rock_Basalt_Brick"
    },
    {
      "x": -5,
      "y": 7,
      "z": 8,
      "name": "Rock_Basalt_Brick"
    },
    {
      "x": -4,
      "y": 1,
      "z": -8,
      "name": "Rock_Basalt_Brick"
    },
    {
      "x": -4,
      "y": 2,
      "z": -8,
      "name": "Rock_Basalt_Brick"
    },
    {
      "x": -4,
      "y": 3,
      "z": -8,
      "name": "Rock_Basalt_Brick"
    },
    {
      "x": -4,
      "y": 4,
      "z": -8,
      "name": "Rock_Basalt_Brick"
    },
    {
      "x": -4,
      "y": 5,
      "z": -8,
      "name": "Rock_Basalt_Brick"
    },
    {
      "x": -4,
      "y": 6,
      "z": -8,
      "name": "Rock_Basalt_Brick"
    },
    {
      "x": -4,
      "y": 7,
      "z": -8,
      "name": "Rock_Basalt_Brick"
    },
    {
      "x": -4,
      "y": 1,
      "z": -7,
      "name": "Rock_Stone_Aqua"
    },
    {
      "x": -4,
      "y": 7,
      "z": -7,
      "name": "Rock_Stone_Aqua"
    },
    {
      "x": -4,
      "y": 1,
      "z": -6,
      "name": "Rock_Stone_Aqua"
    },
    {
      "x": -4,
      "y": 7,
      "z": -6,
      "name": "Rock_Stone_Aqua"
    },
    {
      "x": -4,
      "y": 1,
      "z": -5,
      "name": "Rock_Stone_Aqua"
    },
    {
      "x": -4,
      "y": 7,
      "z": -5,
      "name": "Rock_Basalt_Brick"
    },
    {
      "x": -4,
      "y": 1,
      "z": -4,
      "name": "Rock_Basalt_Brick"
    },
    {
      "x": -4,
      "y": 2,
      "z": -4,
      "name": "Rock_Basalt_Brick"
    },
    {
      "x": -4,
      "y": 3,
      "z": -4,
      "name": "Rock_Basalt_Brick"
    },
    {
      "x": -4,
      "y": 4,
      "z": -4,
      "name": "Rock_Basalt_Brick"
    },
    {
      "x": -4,
      "y": 5,
      "z": -4,
      "name": "Rock_Basalt_Brick"
    },
    {
      "x": -4,
      "y": 6,
      "z": -4,
      "name": "Rock_Basalt_Brick"
    },
    {
      "x": -4,
      "y": 7,
      "z": -4,
      "name": "Rock_Basalt_Brick"
    },
    {
      "x": -4,
      "y": 1,
      "z": -3,
      "name": "Rock_Basalt_Brick"
    },
    {
      "x": -4,
      "y": 2,
      "z": -3,
      "name": "Rock_Basalt_Brick"
    },
    {
      "x": -4,
      "y": 3,
      "z": -3,
      "name": "Rock_Basalt_Brick"
    },
    {
      "x": -4,
      "y": 4,
      "z": -3,
      "name": "Rock_Basalt_Brick"
    },
    {
      "x": -4,
      "y": 5,
      "z": -3,
      "name": "Rock_Basalt_Brick"
    },
    {
      "x": -4,
      "y": 6,
      "z": -3,
      "name": "Rock_Basalt_Brick"
    },
    {
      "x": -4,
      "y": 7,
      "z": -3,
      "name": "Rock_Basalt_Brick"
    },
    {
      "x": -4,
      "y": 8,
      "z": -3,
      "name": "Rock_Basalt_Brick"
    },
    {
      "x": -4,
      "y": 9,
      "z": -3,
      "name": "Rock_Basalt_Brick"
    },
    {
      "x": -4,
      "y": 10,
      "z": -3,
      "name": "Rock_Basalt_Brick"
    },
    {
      "x": -4,
      "y": 11,
      "z": -3,
      "name": "Rock_Basalt_Brick"
    },
    {
      "x": -4,
      "y": 12,
      "z": -3,
      "name": "Rock_Basalt_Brick"
    },
    {
      "x": -4,
      "y": 13,
      "z": -3,
      "name": "Rock_Basalt_Brick"
    },
    {
      "x": -4,
      "y": 14,
      "z": -3,
      "name": "Rock_Basalt_Brick"
    },
    {
      "x": -4,
      "y": 15,
      "z": -3,
      "name": "Rock_Basalt_Brick"
    },
    {
      "x": -4,
      "y": 16,
      "z": -3,
      "name": "Rock_Basalt_Brick"
    },
    {
      "x": -4,
      "y": 17,
      "z": -3,
      "name": "Rock_Basalt_Brick"
    },
    {
      "x": -4,
      "y": 18,
      "z": -3,
      "name": "Rock_Basalt_Brick"
    },
    {
      "x": -4,
      "y": 19,
      "z": -3,
      "name": "Rock_Basalt_Brick"
    },
    {
      "x": -4,
      "y": 20,
      "z": -3,
      "name": "Rock_Basalt_Brick"
    },
    {
      "x": -4,
      "y": 21,
      "z": -3,
      "name": "Rock_Basalt_Brick"
    },
    {
      "x": -4,
      "y": 22,
      "z": -3,
      "name": "Rock_Basalt_Brick"
    },
    {
      "x": -4,
      "y": 23,
      "z": -3,
      "name": "Rock_Basalt_Brick"
    },
    {
      "x": -4,
      "y": 24,
      "z": -3,
      "name": "Rock_Basalt_Brick"
    },
    {
      "x": -4,
      "y": 25,
      "z": -3,
      "name": "Rock_Basalt_Brick"
    },
    {
      "x": -4,
      "y": 1,
      "z": -2,
      "name": "Rock_Basalt_Brick_Smooth"
    },
    {
      "x": -4,
      "y": 5,
      "z": -2,
      "name": "Wood_Goldenwood_Planks"
    },
    {
      "x": -4,
      "y": 21,
      "z": -2,
      "name": "Wood_Goldenwood_Planks"
    },
    {
      "x": -4,
      "y": 1,
      "z": -1,
      "name": "Rock_Basalt_Brick_Smooth"
    },
    {
      "x": -4,
      "y": 4,
      "z": -1,
      "name": "Wood_Goldenwood_Planks"
    },
    {
      "x": -4,
      "y": 20,
      "z": -1,
      "name": "Wood_Goldenwood_Planks"
    },
    {
      "x": -4,
      "y": 1,
      "z": 0,
      "name": "Rock_Basalt_Brick_Smooth"
    },
    {
      "x": -4,
      "y": 3,
      "z": 0,
      "name": "Wood_Goldenwood_Planks"
    },
    {
      "x": -4,
      "y": 19,
      "z": 0,
      "name": "Wood_Goldenwood_Planks"
    },
    {
      "x": -4,
      "y": 1,
      "z": 1,
      "name": "Rock_Basalt_Brick_Smooth"
    },
    {
      "x": -4,
      "y": 2,
      "z": 1,
      "name": "Wood_Goldenwood_Planks"
    },
    {
      "x": -4,
      "y": 18,
      "z": 1,
      "name": "Wood_Goldenwood_Planks"
    },
    {
      "x": -4,
      "y": 1,
      "z": 2,
      "name": "Rock_Basalt_Brick_Smooth"
    },
    {
      "x": -4,
      "y": 17,
      "z": 2,
      "name": "Wood_Goldenwood_Planks"
    },
    {
      "x": -4,
      "y": 1,
      "z": 3,
      "name": "Rock_Basalt_Brick"
    },
    {
      "x": -4,
      "y": 2,
      "z": 3,
      "name": "Rock_Basalt_Brick"
    },
    {
      "x": -4,
      "y": 3,
      "z": 3,
      "name": "Rock_Basalt_Brick"
    },
    {
      "x": -4,
      "y": 4,
      "z": 3,
      "name": "Rock_Basalt_Brick"
    },
    {
      "x": -4,
      "y": 5,
      "z": 3,
      "name": "Rock_Basalt_Brick"
    },
    {
      "x": -4,
      "y": 6,
      "z": 3,
      "name": "Rock_Basalt_Brick"
    },
    {
      "x": -4,
      "y": 7,
      "z": 3,
      "name": "Rock_Basalt_Brick"
    },
    {
      "x": -4,
      "y": 8,
      "z": 3,
      "name": "Rock_Basalt_Brick"
    },
    {
      "x": -4,
      "y": 9,
      "z": 3,
      "name": "Rock_Basalt_Brick"
    },
    {
      "x": -4,
      "y": 10,
      "z": 3,
      "name": "Rock_Basalt_Brick"
    },
    {
      "x": -4,
      "y": 11,
      "z": 3,
      "name": "Rock_Basalt_Brick"
    },
    {
      "x": -4,
      "y": 12,
      "z": 3,
      "name": "Rock_Basalt_Brick"
    },
    {
      "x": -4,
      "y": 13,
      "z": 3,
      "name": "Rock_Basalt_Brick"
    },
    {
      "x": -4,
      "y": 14,
      "z": 3,
      "name": "Rock_Basalt_Brick"
    },
    {
      "x": -4,
      "y": 15,
      "z": 3,
      "name": "Rock_Basalt_Brick"
    },
    {
      "x": -4,
      "y": 16,
      "z": 3,
      "name": "Rock_Basalt_Brick"
    },
    {
      "x": -4,
      "y": 17,
      "z": 3,
      "name": "Rock_Basalt_Brick"
    },
    {
      "x": -4,
      "y": 18,
      "z": 3,
      "name": "Rock_Basalt_Brick"
    },
    {
      "x": -4,
      "y": 19,
      "z": 3,
      "name": "Rock_Basalt_Brick"
    },
    {
      "x": -4,
      "y": 20,
      "z": 3,
      "name": "Rock_Basalt_Brick"
    },
    {
      "x": -4,
      "y": 21,
      "z": 3,
      "name": "Rock_Basalt_Brick"
    },
    {
      "x": -4,
      "y": 22,
      "z": 3,
      "name": "Rock_Basalt_Brick"
    },
    {
      "x": -4,
      "y": 23,
      "z": 3,
      "name": "Rock_Basalt_Brick"
    },
    {
      "x": -4,
      "y": 24,
      "z": 3,
      "name": "Rock_Basalt_Brick"
    },
    {
      "x": -4,
      "y": 25,
      "z": 3,
      "name": "Rock_Basalt_Brick"
    },
    {
      "x": -4,
      "y": 1,
      "z": 4,
      "name": "Rock_Basalt_Brick"
    },
    {
      "x": -4,
      "y": 2,
      "z": 4,
      "name": "Rock_Basalt_Brick"
    },
    {
      "x": -4,
      "y": 3,
      "z": 4,
      "name": "Rock_Basalt_Brick"
    },
    {
      "x": -4,
      "y": 4,
      "z": 4,
      "name": "Rock_Basalt_Brick"
    },
    {
      "x": -4,
      "y": 5,
      "z": 4,
      "name": "Rock_Basalt_Brick"
    },
    {
      "x": -4,
      "y": 6,
      "z": 4,
      "name": "Rock_Basalt_Brick"
    },
    {
      "x": -4,
      "y": 7,
      "z": 4,
      "name": "Rock_Basalt_Brick"
    },
    {
      "x": -4,
      "y": 1,
      "z": 5,
      "name": "Rock_Stone_Aqua"
    },
    {
      "x": -4,
      "y": 7,
      "z": 5,
      "name": "Rock_Basalt_Brick"
    },
    {
      "x": -4,
      "y": 1,
      "z": 6,
      "name": "Rock_Stone_Aqua"
    },
    {
      "x": -4,
      "y": 7,
      "z": 6,
      "name": "Rock_Stone_Aqua"
    },
    {
      "x": -4,
      "y": 1,
      "z": 7,
      "name": "Rock_Stone_Aqua"
    },
    {
      "x": -4,
      "y": 7,
      "z": 7,
      "name": "Rock_Stone_Aqua"
    },
    {
      "x": -4,
      "y": 1,
      "z": 8,
      "name": "Rock_Basalt_Brick"
    },
    {
      "x": -4,
      "y": 2,
      "z": 8,
      "name": "Rock_Basalt_Brick"
    },
    {
      "x": -4,
      "y": 3,
      "z": 8,
      "name": "Rock_Basalt_Brick"
    },
    {
      "x": -4,
      "y": 4,
      "z": 8,
      "name": "Rock_Basalt_Brick"
    },
    {
      "x": -4,
      "y": 5,
      "z": 8,
      "name": "Rock_Basalt_Brick"
    },
    {
      "x": -4,
      "y": 6,
      "z": 8,
      "name": "Rock_Basalt_Brick"
    },
    {
      "x": -4,
      "y": 7,
      "z": 8,
      "name": "Rock_Basalt_Brick"
    },
    {
      "x": -3,
      "y": 1,
      "z": -8,
      "name": "Rock_Basalt_Brick_Smooth"
    },
    {
      "x": -3,
      "y": 2,
      "z": -8,
      "name": "Wood_Goldenwood_Planks"
    },
    {
      "x": -3,
      "y": 3,
      "z": -8,
      "name": "Wood_Goldenwood_Planks"
    },
    {
      "x": -3,
      "y": 4,
      "z": -8,
      "name": "Wood_Goldenwood_Planks"
    },
    {
      "x": -3,
      "y": 5,
      "z": -8,
      "name": "Wood_Goldenwood_Planks"
    },
    {
      "x": -3,
      "y": 6,
      "z": -8,
      "name": "Wood_Goldenwood_Planks"
    },
    {
      "x": -3,
      "y": 7,
      "z": -8,
      "name": "Rock_Basalt_Brick_Smooth"
    },
    {
      "x": -3,
      "y": 1,
      "z": -7,
      "name": "Rock_Stone_Aqua"
    },
    {
      "x": -3,
      "y": 2,
      "z": -7,
      "name": "Wood_Goldenwood_Fence"
    },
    {
      "x": -3,
      "y": 3,
      "z": -7,
      "name": "Wood_Goldenwood_Fence"
    },
    {
      "x": -3,
      "y": 4,
      "z": -7,
      "name": "Wood_Goldenwood_Fence"
    },
    {
      "x": -3,
      "y": 5,
      "z": -7,
      "name": "Wood_Goldenwood_Fence"
    },
    {
      "x": -3,
      "y": 6,
      "z": -7,
      "name": "Wood_Goldenwood_Fence"
    },
    {
      "x": -3,
      "y": 7,
      "z": -7,
      "name": "Rock_Stone_Aqua"
    },
    {
      "x": -3,
      "y": 1,
      "z": -6,
      "name": "Rock_Stone_Aqua"
    },
    {
      "x": -3,
      "y": 7,
      "z": -6,
      "name": "Rock_Stone_Aqua"
    },
    {
      "x": -3,
      "y": 1,
      "z": -5,
      "name": "Rock_Stone_Aqua"
    },
    {
      "x": -3,
      "y": 7,
      "z": -5,
      "name": "Rock_Basalt_Brick"
    },
    {
      "x": -3,
      "y": 1,
      "z": -4,
      "name": "Rock_Basalt_Brick"
    },
    {
      "x": -3,
      "y": 2,
      "z": -4,
      "name": "Rock_Basalt_Brick"
    },
    {
      "x": -3,
      "y": 3,
      "z": -4,
      "name": "Rock_Basalt_Brick"
    },
    {
      "x": -3,
      "y": 4,
      "z": -4,
      "name": "Rock_Basalt_Brick"
    },
    {
      "x": -3,
      "y": 5,
      "z": -4,
      "name": "Rock_Basalt_Brick"
    },
    {
      "x": -3,
      "y": 6,
      "z": -4,
      "name": "Rock_Basalt_Brick"
    },
    {
      "x": -3,
      "y": 7,
      "z": -4,
      "name": "Rock_Basalt_Brick"
    },
    {
      "x": -3,
      "y": 8,
      "z": -4,
      "name": "Rock_Basalt_Brick"
    },
    {
      "x": -3,
      "y": 9,
      "z": -4,
      "name": "Rock_Basalt_Brick"
    },
    {
      "x": -3,
      "y": 10,
      "z": -4,
      "name": "Rock_Basalt_Brick"
    },
    {
      "x": -3,
      "y": 11,
      "z": -4,
      "name": "Rock_Basalt_Brick"
    },
    {
      "x": -3,
      "y": 12,
      "z": -4,
      "name": "Rock_Basalt_Brick"
    },
    {
      "x": -3,
      "y": 13,
      "z": -4,
      "name": "Rock_Basalt_Brick"
    },
    {
      "x": -3,
      "y": 14,
      "z": -4,
      "name": "Rock_Basalt_Brick"
    },
    {
      "x": -3,
      "y": 15,
      "z": -4,
      "name": "Rock_Basalt_Brick"
    },
    {
      "x": -3,
      "y": 16,
      "z": -4,
      "name": "Rock_Basalt_Brick"
    },
    {
      "x": -3,
      "y": 17,
      "z": -4,
      "name": "Rock_Basalt_Brick"
    },
    {
      "x": -3,
      "y": 18,
      "z": -4,
      "name": "Rock_Basalt_Brick"
    },
    {
      "x": -3,
      "y": 19,
      "z": -4,
      "name": "Rock_Basalt_Brick"
    },
    {
      "x": -3,
      "y": 20,
      "z": -4,
      "name": "Rock_Basalt_Brick"
    },
    {
      "x": -3,
      "y": 21,
      "z": -4,
      "name": "Rock_Basalt_Brick"
    },
    {
      "x": -3,
      "y": 22,
      "z": -4,
      "name": "Rock_Basalt_Brick"
    },
    {
      "x": -3,
      "y": 23,
      "z": -4,
      "name": "Rock_Basalt_Brick"
    },
    {
      "x": -3,
      "y": 24,
      "z": -4,
      "name": "Rock_Basalt_Brick"
    },
    {
      "x": -3,
      "y": 25,
      "z": -4,
      "name": "Rock_Basalt_Brick"
    },
    {
      "x": -3,
      "y": 1,
      "z": -3,
      "name": "Rock_Stone_Aqua"
    },
    {
      "x": -3,
      "y": 5,
      "z": -3,
      "name": "Wood_Goldenwood_Planks"
    },
    {
      "x": -3,
      "y": 21,
      "z": -3,
      "name": "Wood_Goldenwood_Planks"
    },
    {
      "x": -3,
      "y": 1,
      "z": -2,
      "name": "Rock_Stone_Aqua"
    },
    {
      "x": -3,
      "y": 5,
      "z": -2,
      "name": "Wood_Goldenwood_Planks"
    },
    {
      "x": -3,
      "y": 21,
      "z": -2,
      "name": "Wood_Goldenwood_Planks"
    },
    {
      "x": -3,
      "y": 1,
      "z": -1,
      "name": "Rock_Stone_Aqua"
    },
    {
      "x": -3,
      "y": 4,
      "z": -1,
      "name": "Wood_Goldenwood_Planks"
    },
    {
      "x": -3,
      "y": 20,
      "z": -1,
      "name": "Wood_Goldenwood_Planks"
    },
    {
      "x": -3,
      "y": 1,
      "z": 0,
      "name": "Rock_Stone_Aqua"
    },
    {
      "x": -3,
      "y": 3,
      "z": 0,
      "name": "Wood_Goldenwood_Planks"
    },
    {
      "x": -3,
      "y": 19,
      "z": 0,
      "name": "Wood_Goldenwood_Planks"
    },
    {
      "x": -3,
      "y": 1,
      "z": 1,
      "name": "Rock_Stone_Aqua"
    },
    {
      "x": -3,
      "y": 2,
      "z": 1,
      "name": "Wood_Goldenwood_Planks"
    },
    {
      "x": -3,
      "y": 18,
      "z": 1,
      "name": "Wood_Goldenwood_Planks"
    },
    {
      "x": -3,
      "y": 1,
      "z": 2,
      "name": "Rock_Stone_Aqua"
    },
    {
      "x": -3,
      "y": 17,
      "z": 2,
      "name": "Wood_Goldenwood_Planks"
    },
    {
      "x": -3,
      "y": 1,
      "z": 3,
      "name": "Rock_Stone_Aqua"
    },
    {
      "x": -3,
      "y": 17,
      "z": 3,
      "name": "Wood_Goldenwood_Planks"
    },
    {
      "x": -3,
      "y": 1,
      "z": 4,
      "name": "Rock_Basalt_Brick"
    },
    {
      "x": -3,
      "y": 2,
      "z": 4,
      "name": "Rock_Basalt_Brick"
    },
    {
      "x": -3,
      "y": 3,
      "z": 4,
      "name": "Rock_Basalt_Brick"
    },
    {
      "x": -3,
      "y": 4,
      "z": 4,
      "name": "Rock_Basalt_Brick"
    },
    {
      "x": -3,
      "y": 5,
      "z": 4,
      "name": "Rock_Basalt_Brick"
    },
    {
      "x": -3,
      "y": 6,
      "z": 4,
      "name": "Rock_Basalt_Brick"
    },
    {
      "x": -3,
      "y": 7,
      "z": 4,
      "name": "Rock_Basalt_Brick"
    },
    {
      "x": -3,
      "y": 8,
      "z": 4,
      "name": "Rock_Basalt_Brick"
    },
    {
      "x": -3,
      "y": 9,
      "z": 4,
      "name": "Rock_Basalt_Brick"
    },
    {
      "x": -3,
      "y": 10,
      "z": 4,
      "name": "Rock_Basalt_Brick"
    },
    {
      "x": -3,
      "y": 11,
      "z": 4,
      "name": "Rock_Basalt_Brick"
    },
    {
      "x": -3,
      "y": 12,
      "z": 4,
      "name": "Rock_Basalt_Brick"
    },
    {
      "x": -3,
      "y": 13,
      "z": 4,
      "name": "Rock_Basalt_Brick"
    },
    {
      "x": -3,
      "y": 14,
      "z": 4,
      "name": "Rock_Basalt_Brick"
    },
    {
      "x": -3,
      "y": 15,
      "z": 4,
      "name": "Rock_Basalt_Brick"
    },
    {
      "x": -3,
      "y": 16,
      "z": 4,
      "name": "Rock_Basalt_Brick"
    },
    {
      "x": -3,
      "y": 17,
      "z": 4,
      "name": "Rock_Basalt_Brick"
    },
    {
      "x": -3,
      "y": 18,
      "z": 4,
      "name": "Rock_Basalt_Brick"
    },
    {
      "x": -3,
      "y": 19,
      "z": 4,
      "name": "Rock_Basalt_Brick"
    },
    {
      "x": -3,
      "y": 20,
      "z": 4,
      "name": "Rock_Basalt_Brick"
    },
    {
      "x": -3,
      "y": 21,
      "z": 4,
      "name": "Rock_Basalt_Brick"
    },
    {
      "x": -3,
      "y": 22,
      "z": 4,
      "name": "Rock_Basalt_Brick"
    },
    {
      "x": -3,
      "y": 23,
      "z": 4,
      "name": "Rock_Basalt_Brick"
    },
    {
      "x": -3,
      "y": 24,
      "z": 4,
      "name": "Rock_Basalt_Brick"
    },
    {
      "x": -3,
      "y": 25,
      "z": 4,
      "name": "Rock_Basalt_Brick"
    },
    {
      "x": -3,
      "y": 1,
      "z": 5,
      "name": "Rock_Stone_Aqua"
    },
    {
      "x": -3,
      "y": 7,
      "z": 5,
      "name": "Rock_Basalt_Brick"
    },
    {
      "x": -3,
      "y": 1,
      "z": 6,
      "name": "Rock_Stone_Aqua"
    },
    {
      "x": -3,
      "y": 7,
      "z": 6,
      "name": "Rock_Stone_Aqua"
    },
    {
      "x": -3,
      "y": 1,
      "z": 7,
      "name": "Rock_Stone_Aqua"
    },
    {
      "x": -3,
      "y": 2,
      "z": 7,
      "name": "Wood_Goldenwood_Fence",
      "rotation": 2
    },
    {
      "x": -3,
      "y": 3,
      "z": 7,
      "name": "Wood_Goldenwood_Fence",
      "rotation": 2
    },
    {
      "x": -3,
      "y": 4,
      "z": 7,
      "name": "Wood_Goldenwood_Fence",
      "rotation": 2
    },
    {
      "x": -3,
      "y": 5,
      "z": 7,
      "name": "Wood_Goldenwood_Fence",
      "rotation": 2
    },
    {
      "x": -3,
      "y": 6,
      "z": 7,
      "name": "Wood_Goldenwood_Fence",
      "rotation": 2
    },
    {
      "x": -3,
      "y": 7,
      "z": 7,
      "name": "Rock_Stone_Aqua"
    },
    {
      "x": -3,
      "y": 1,
      "z": 8,
      "name": "Rock_Basalt_Brick_Smooth"
    },
    {
      "x": -3,
      "y": 2,
      "z": 8,
      "name": "Wood_Goldenwood_Planks"
    },
    {
      "x": -3,
      "y": 3,
      "z": 8,
      "name": "Wood_Goldenwood_Planks"
    },
    {
      "x": -3,
      "y": 4,
      "z": 8,
      "name": "Wood_Goldenwood_Planks"
    },
    {
      "x": -3,
      "y": 5,
      "z": 8,
      "name": "Wood_Goldenwood_Planks"
    },
    {
      "x": -3,
      "y": 6,
      "z": 8,
      "name": "Wood_Goldenwood_Planks"
    },
    {
      "x": -3,
      "y": 7,
      "z": 8,
      "name": "Rock_Basalt_Brick_Smooth"
    },
    {
      "x": -2,
      "y": 1,
      "z": -8,
      "name": "Rock_Basalt_Brick_Smooth"
    },
    {
      "x": -2,
      "y": 2,
      "z": -8,
      "name": "Rock_Basalt_Brick_Decorative"
    },
    {
      "x": -2,
      "y": 3,
      "z": -8,
      "name": "Rock_Basalt_Brick_Smooth"
    },
    {
      "x": -2,
      "y": 4,
      "z": -8,
      "name": "Rock_Basalt_Brick_Smooth"
    },
    {
      "x": -2,
      "y": 5,
      "z": -8,
      "name": "Rock_Basalt_Brick_Smooth"
    },
    {
      "x": -2,
      "y": 6,
      "z": -8,
      "name": "Rock_Basalt_Brick_Decorative"
    },
    {
      "x": -2,
      "y": 7,
      "z": -8,
      "name": "Rock_Basalt_Brick_Smooth"
    },
    {
      "x": -2,
      "y": 1,
      "z": -7,
      "name": "Rock_Stone_Aqua"
    },
    {
      "x": -2,
      "y": 7,
      "z": -7,
      "name": "Rock_Stone_Aqua"
    },
    {
      "x": -2,
      "y": 1,
      "z": -6,
      "name": "Rock_Stone_Aqua"
    },
    {
      "x": -2,
      "y": 7,
      "z": -6,
      "name": "Rock_Stone_Aqua"
    },
    {
      "x": -2,
      "y": 1,
      "z": -5,
      "name": "Rock_Stone_Aqua"
    },
    {
      "x": -2,
      "y": 7,
      "z": -5,
      "name": "Rock_Basalt_Brick"
    },
    {
      "x": -2,
      "y": 8,
      "z": -5,
      "name": "Rock_Basalt_Brick"
    },
    {
      "x": -2,
      "y": 9,
      "z": -5,
      "name": "Rock_Basalt_Brick"
    },
    {
      "x": -2,
      "y": 10,
      "z": -5,
      "name": "Rock_Basalt_Brick"
    },
    {
      "x": -2,
      "y": 11,
      "z": -5,
      "name": "Rock_Basalt_Brick"
    },
    {
      "x": -2,
      "y": 12,
      "z": -5,
      "name": "Rock_Basalt_Brick"
    },
    {
      "x": -2,
      "y": 13,
      "z": -5,
      "name": "Rock_Basalt_Brick"
    },
    {
      "x": -2,
      "y": 14,
      "z": -5,
      "name": "Rock_Basalt_Brick"
    },
    {
      "x": -2,
      "y": 15,
      "z": -5,
      "name": "Rock_Basalt_Brick"
    },
    {
      "x": -2,
      "y": 16,
      "z": -5,
      "name": "Rock_Basalt_Brick"
    },
    {
      "x": -2,
      "y": 17,
      "z": -5,
      "name": "Rock_Basalt_Brick"
    },
    {
      "x": -2,
      "y": 18,
      "z": -5,
      "name": "Rock_Basalt_Brick"
    },
    {
      "x": -2,
      "y": 19,
      "z": -5,
      "name": "Rock_Basalt_Brick"
    },
    {
      "x": -2,
      "y": 20,
      "z": -5,
      "name": "Rock_Basalt_Brick"
    },
    {
      "x": -2,
      "y": 21,
      "z": -5,
      "name": "Rock_Basalt_Brick"
    },
    {
      "x": -2,
      "y": 22,
      "z": -5,
      "name": "Rock_Basalt_Brick"
    },
    {
      "x": -2,
      "y": 23,
      "z": -5,
      "name": "Rock_Basalt_Brick"
    },
    {
      "x": -2,
      "y": 24,
      "z": -5,
      "name": "Rock_Basalt_Brick"
    },
    {
      "x": -2,
      "y": 25,
      "z": -5,
      "name": "Rock_Basalt_Brick"
    },
    {
      "x": -2,
      "y": 1,
      "z": -4,
      "name": "Rock_Basalt_Brick_Smooth"
    },
    {
      "x": -2,
      "y": 5,
      "z": -4,
      "name": "Wood_Goldenwood_Planks"
    },
    {
      "x": -2,
      "y": 21,
      "z": -4,
      "name": "Wood_Goldenwood_Planks"
    },
    {
      "x": -2,
      "y": 1,
      "z": -3,
      "name": "Rock_Stone_Aqua"
    },
    {
      "x": -2,
      "y": 5,
      "z": -3,
      "name": "Wood_Goldenwood_Planks"
    },
    {
      "x": -2,
      "y": 21,
      "z": -3,
      "name": "Wood_Goldenwood_Planks"
    },
    {
      "x": -2,
      "y": 1,
      "z": -2,
      "name": "Rock_Stone_Aqua"
    },
    {
      "x": -2,
      "y": 5,
      "z": -2,
      "name": "Wood_Goldenwood_Planks"
    },
    {
      "x": -2,
      "y": 21,
      "z": -2,
      "name": "Wood_Goldenwood_Planks"
    },
    {
      "x": -2,
      "y": 1,
      "z": -1,
      "name": "Rock_Stone_Aqua"
    },
    {
      "x": -2,
      "y": 4,
      "z": -1,
      "name": "Wood_Goldenwood_Planks"
    },
    {
      "x": -2,
      "y": 20,
      "z": -1,
      "name": "Wood_Goldenwood_Planks"
    },
    {
      "x": -2,
      "y": 1,
      "z": 0,
      "name": "Rock_Stone_Aqua"
    },
    {
      "x": -2,
      "y": 1,
      "z": 1,
      "name": "Rock_Stone_Aqua"
    },
    {
      "x": -2,
      "y": 18,
      "z": 1,
      "name": "Wood_Goldenwood_Planks"
    },
    {
      "x": -2,
      "y": 1,
      "z": 2,
      "name": "Rock_Stone_Aqua"
    },
    {
      "x": -2,
      "y": 17,
      "z": 2,
      "name": "Wood_Goldenwood_Planks"
    },
    {
      "x": -2,
      "y": 1,
      "z": 3,
      "name": "Rock_Stone_Aqua"
    },
    {
      "x": -2,
      "y": 17,
      "z": 3,
      "name": "Wood_Goldenwood_Planks"
    },
    {
      "x": -2,
      "y": 1,
      "z": 4,
      "name": "Rock_Basalt_Brick_Smooth"
    },
    {
      "x": -2,
      "y": 17,
      "z": 4,
      "name": "Wood_Goldenwood_Planks"
    },
    {
      "x": -2,
      "y": 1,
      "z": 5,
      "name": "Rock_Stone_Aqua"
    },
    {
      "x": -2,
      "y": 2,
      "z": 5,
      "name": "Rock_Aqua_Stalactite_Large"
    },
    {
      "x": -2,
      "y": 3,
      "z": 5,
      "name": "Rock_Aqua_Stalactite_Large",
      "filler": 1024
    },
    {
      "x": -2,
      "y": 7,
      "z": 5,
      "name": "Rock_Basalt_Brick"
    },
    {
      "x": -2,
      "y": 8,
      "z": 5,
      "name": "Rock_Basalt_Brick"
    },
    {
      "x": -2,
      "y": 9,
      "z": 5,
      "name": "Rock_Basalt_Brick"
    },
    {
      "x": -2,
      "y": 10,
      "z": 5,
      "name": "Rock_Basalt_Brick"
    },
    {
      "x": -2,
      "y": 11,
      "z": 5,
      "name": "Rock_Basalt_Brick"
    },
    {
      "x": -2,
      "y": 12,
      "z": 5,
      "name": "Rock_Basalt_Brick"
    },
    {
      "x": -2,
      "y": 13,
      "z": 5,
      "name": "Rock_Basalt_Brick"
    },
    {
      "x": -2,
      "y": 14,
      "z": 5,
      "name": "Rock_Basalt_Brick"
    },
    {
      "x": -2,
      "y": 15,
      "z": 5,
      "name": "Rock_Basalt_Brick"
    },
    {
      "x": -2,
      "y": 16,
      "z": 5,
      "name": "Rock_Basalt_Brick"
    },
    {
      "x": -2,
      "y": 17,
      "z": 5,
      "name": "Rock_Basalt_Brick"
    },
    {
      "x": -2,
      "y": 18,
      "z": 5,
      "name": "Rock_Basalt_Brick"
    },
    {
      "x": -2,
      "y": 19,
      "z": 5,
      "name": "Rock_Basalt_Brick"
    },
    {
      "x": -2,
      "y": 20,
      "z": 5,
      "name": "Rock_Basalt_Brick"
    },
    {
      "x": -2,
      "y": 21,
      "z": 5,
      "name": "Rock_Basalt_Brick"
    },
    {
      "x": -2,
      "y": 22,
      "z": 5,
      "name": "Rock_Basalt_Brick"
    },
    {
      "x": -2,
      "y": 23,
      "z": 5,
      "name": "Rock_Basalt_Brick"
    },
    {
      "x": -2,
      "y": 24,
      "z": 5,
      "name": "Rock_Basalt_Brick"
    },
    {
      "x": -2,
      "y": 25,
      "z": 5,
      "name": "Rock_Basalt_Brick"
    },
    {
      "x": -2,
      "y": 1,
      "z": 6,
      "name": "Rock_Stone_Aqua"
    },
    {
      "x": -2,
      "y": 7,
      "z": 6,
      "name": "Rock_Stone_Aqua"
    },
    {
      "x": -2,
      "y": 1,
      "z": 7,
      "name": "Rock_Stone_Aqua"
    },
    {
      "x": -2,
      "y": 7,
      "z": 7,
      "name": "Rock_Stone_Aqua"
    },
    {
      "x": -2,
      "y": 1,
      "z": 8,
      "name": "Rock_Basalt_Brick_Smooth"
    },
    {
      "x": -2,
      "y": 2,
      "z": 8,
      "name": "Rock_Basalt_Brick_Decorative"
    },
    {
      "x": -2,
      "y": 3,
      "z": 8,
      "name": "Rock_Basalt_Brick_Smooth"
    },
    {
      "x": -2,
      "y": 4,
      "z": 8,
      "name": "Rock_Basalt_Brick_Smooth"
    },
    {
      "x": -2,
      "y": 5,
      "z": 8,
      "name": "Rock_Basalt_Brick_Smooth"
    },
    {
      "x": -2,
      "y": 6,
      "z": 8,
      "name": "Rock_Basalt_Brick_Decorative"
    },
    {
      "x": -2,
      "y": 7,
      "z": 8,
      "name": "Rock_Basalt_Brick_Smooth"
    },
    {
      "x": -1,
      "y": 1,
      "z": -8,
      "name": "Rock_Basalt_Brick_Smooth"
    },
    {
      "x": -1,
      "y": 2,
      "z": -8,
      "name": "Rock_Basalt_Brick_Smooth"
    },
    {
      "x": -1,
      "y": 3,
      "z": -8,
      "name": "Rock_Basalt_Brick_Smooth"
    },
    {
      "x": -1,
      "y": 4,
      "z": -8,
      "name": "Rock_Basalt_Brick_Smooth"
    },
    {
      "x": -1,
      "y": 5,
      "z": -8,
      "name": "Rock_Basalt_Brick_Smooth"
    },
    {
      "x": -1,
      "y": 6,
      "z": -8,
      "name": "Rock_Basalt_Brick_Smooth"
    },
    {
      "x": -1,
      "y": 7,
      "z": -8,
      "name": "Rock_Basalt_Brick_Smooth"
    },
    {
      "x": -1,
      "y": 1,
      "z": -7,
      "name": "Rock_Stone_Aqua"
    },
    {
      "x": -1,
      "y": 5,
      "z": -7,
      "name": "Rock_Aqua_Stalactite_Large",
      "filler": 31744,
      "rotation": 8
    },
    {
      "x": -1,
      "y": 6,
      "z": -7,
      "name": "Rock_Aqua_Stalactite_Large",
      "rotation": 8
    },
    {
      "x": -1,
      "y": 7,
      "z": -7,
      "name": "Rock_Stone_Aqua"
    },
    {
      "x": -1,
      "y": 1,
      "z": -6,
      "name": "Rock_Stone_Aqua"
    },
    {
      "x": -1,
      "y": 7,
      "z": -6,
      "name": "Rock_Stone_Aqua"
    },
    {
      "x": -1,
      "y": 1,
      "z": -5,
      "name": "Rock_Stone_Aqua"
    },
    {
      "x": -1,
      "y": 7,
      "z": -5,
      "name": "Rock_Basalt_Brick"
    },
    {
      "x": -1,
      "y": 8,
      "z": -5,
      "name": "Rock_Basalt_Brick"
    },
    {
      "x": -1,
      "y": 9,
      "z": -5,
      "name": "Rock_Basalt_Brick"
    },
    {
      "x": -1,
      "y": 10,
      "z": -5,
      "name": "Rock_Basalt_Brick"
    },
    {
      "x": -1,
      "y": 11,
      "z": -5,
      "name": "Rock_Basalt_Brick"
    },
    {
      "x": -1,
      "y": 12,
      "z": -5,
      "name": "Rock_Basalt_Brick"
    },
    {
      "x": -1,
      "y": 13,
      "z": -5,
      "name": "Rock_Basalt_Brick"
    },
    {
      "x": -1,
      "y": 14,
      "z": -5,
      "name": "Rock_Basalt_Brick"
    },
    {
      "x": -1,
      "y": 15,
      "z": -5,
      "name": "Rock_Basalt_Brick"
    },
    {
      "x": -1,
      "y": 16,
      "z": -5,
      "name": "Rock_Basalt_Brick"
    },
    {
      "x": -1,
      "y": 17,
      "z": -5,
      "name": "Rock_Basalt_Brick"
    },
    {
      "x": -1,
      "y": 18,
      "z": -5,
      "name": "Rock_Basalt_Brick"
    },
    {
      "x": -1,
      "y": 19,
      "z": -5,
      "name": "Rock_Basalt_Brick"
    },
    {
      "x": -1,
      "y": 20,
      "z": -5,
      "name": "Rock_Basalt_Brick"
    },
    {
      "x": -1,
      "y": 21,
      "z": -5,
      "name": "Rock_Basalt_Brick"
    },
    {
      "x": -1,
      "y": 22,
      "z": -5,
      "name": "Rock_Basalt_Brick"
    },
    {
      "x": -1,
      "y": 23,
      "z": -5,
      "name": "Rock_Basalt_Brick"
    },
    {
      "x": -1,
      "y": 24,
      "z": -5,
      "name": "Rock_Basalt_Brick"
    },
    {
      "x": -1,
      "y": 25,
      "z": -5,
      "name": "Rock_Basalt_Brick"
    },
    {
      "x": -1,
      "y": 1,
      "z": -4,
      "name": "Rock_Basalt_Brick_Smooth"
    },
    {
      "x": -1,
      "y": 6,
      "z": -4,
      "name": "Wood_Goldenwood_Planks"
    },
    {
      "x": -1,
      "y": 22,
      "z": -4,
      "name": "Wood_Goldenwood_Planks"
    },
    {
      "x": -1,
      "y": 1,
      "z": -3,
      "name": "Rock_Stone_Aqua"
    },
    {
      "x": -1,
      "y": 6,
      "z": -3,
      "name": "Wood_Goldenwood_Planks"
    },
    {
      "x": -1,
      "y": 22,
      "z": -3,
      "name": "Wood_Goldenwood_Planks"
    },
    {
      "x": -1,
      "y": 1,
      "z": -2,
      "name": "Rock_Stone_Aqua"
    },
    {
      "x": -1,
      "y": 6,
      "z": -2,
      "name": "Wood_Goldenwood_Planks"
    },
    {
      "x": -1,
      "y": 22,
      "z": -2,
      "name": "Wood_Goldenwood_Planks"
    },
    {
      "x": -1,
      "y": 0,
      "z": -1,
      "name": "Rock_Basalt_Brick"
    },
    {
      "x": -1,
      "y": 0,
      "z": 0,
      "name": "Rock_Basalt_Brick"
    },
    {
      "x": -1,
      "y": 0,
      "z": 1,
      "name": "Rock_Basalt_Brick"
    },
    {
      "x": -1,
      "y": 1,
      "z": 2,
      "name": "Rock_Stone_Aqua"
    },
    {
      "x": -1,
      "y": 16,
      "z": 2,
      "name": "Wood_Goldenwood_Planks"
    },
    {
      "x": -1,
      "y": 1,
      "z": 3,
      "name": "Rock_Stone_Aqua"
    },
    {
      "x": -1,
      "y": 16,
      "z": 3,
      "name": "Wood_Goldenwood_Planks"
    },
    {
      "x": -1,
      "y": 1,
      "z": 4,
      "name": "Rock_Basalt_Brick_Smooth"
    },
    {
      "x": -1,
      "y": 16,
      "z": 4,
      "name": "Wood_Goldenwood_Planks"
    },
    {
      "x": -1,
      "y": 1,
      "z": 5,
      "name": "Rock_Stone_Aqua"
    },
    {
      "x": -1,
      "y": 7,
      "z": 5,
      "name": "Rock_Basalt_Brick"
    },
    {
      "x": -1,
      "y": 8,
      "z": 5,
      "name": "Rock_Basalt_Brick"
    },
    {
      "x": -1,
      "y": 9,
      "z": 5,
      "name": "Rock_Basalt_Brick"
    },
    {
      "x": -1,
      "y": 10,
      "z": 5,
      "name": "Rock_Basalt_Brick"
    },
    {
      "x": -1,
      "y": 11,
      "z": 5,
      "name": "Rock_Basalt_Brick"
    },
    {
      "x": -1,
      "y": 12,
      "z": 5,
      "name": "Rock_Basalt_Brick"
    },
    {
      "x": -1,
      "y": 13,
      "z": 5,
      "name": "Rock_Basalt_Brick"
    },
    {
      "x": -1,
      "y": 14,
      "z": 5,
      "name": "Rock_Basalt_Brick"
    },
    {
      "x": -1,
      "y": 15,
      "z": 5,
      "name": "Rock_Basalt_Brick"
    },
    {
      "x": -1,
      "y": 16,
      "z": 5,
      "name": "Rock_Basalt_Brick"
    },
    {
      "x": -1,
      "y": 17,
      "z": 5,
      "name": "Rock_Basalt_Brick"
    },
    {
      "x": -1,
      "y": 18,
      "z": 5,
      "name": "Rock_Basalt_Brick"
    },
    {
      "x": -1,
      "y": 19,
      "z": 5,
      "name": "Rock_Basalt_Brick"
    },
    {
      "x": -1,
      "y": 20,
      "z": 5,
      "name": "Rock_Basalt_Brick"
    },
    {
      "x": -1,
      "y": 21,
      "z": 5,
      "name": "Rock_Basalt_Brick"
    },
    {
      "x": -1,
      "y": 22,
      "z": 5,
      "name": "Rock_Basalt_Brick"
    },
    {
      "x": -1,
      "y": 23,
      "z": 5,
      "name": "Rock_Basalt_Brick"
    },
    {
      "x": -1,
      "y": 24,
      "z": 5,
      "name": "Rock_Basalt_Brick"
    },
    {
      "x": -1,
      "y": 25,
      "z": 5,
      "name": "Rock_Basalt_Brick"
    },
    {
      "x": -1,
      "y": 1,
      "z": 6,
      "name": "Rock_Stone_Aqua"
    },
    {
      "x": -1,
      "y": 7,
      "z": 6,
      "name": "Rock_Stone_Aqua"
    },
    {
      "x": -1,
      "y": 1,
      "z": 7,
      "name": "Rock_Stone_Aqua"
    },
    {
      "x": -1,
      "y": 7,
      "z": 7,
      "name": "Rock_Stone_Aqua"
    },
    {
      "x": -1,
      "y": 1,
      "z": 8,
      "name": "Rock_Basalt_Brick_Smooth"
    },
    {
      "x": -1,
      "y": 2,
      "z": 8,
      "name": "Rock_Basalt_Brick_Smooth"
    },
    {
      "x": -1,
      "y": 3,
      "z": 8,
      "name": "Rock_Basalt_Brick_Smooth"
    },
    {
      "x": -1,
      "y": 4,
      "z": 8,
      "name": "Rock_Basalt_Brick_Smooth"
    },
    {
      "x": -1,
      "y": 5,
      "z": 8,
      "name": "Rock_Basalt_Brick_Smooth"
    },
    {
      "x": -1,
      "y": 6,
      "z": 8,
      "name": "Rock_Basalt_Brick_Smooth"
    },
    {
      "x": -1,
      "y": 7,
      "z": 8,
      "name": "Rock_Basalt_Brick_Smooth"
    },
    {
      "x": 0,
      "y": 1,
      "z": -8,
      "name": "Rock_Basalt_Brick_Smooth"
    },
    {
      "x": 0,
      "y": 2,
      "z": -8,
      "name": "Rock_Basalt_Brick_Smooth"
    },
    {
      "x": 0,
      "y": 3,
      "z": -8,
      "name": "Rock_Basalt_Brick_Smooth"
    },
    {
      "x": 0,
      "y": 4,
      "z": -8,
      "name": "Rock_Basalt_Brick_Smooth"
    },
    {
      "x": 0,
      "y": 5,
      "z": -8,
      "name": "Rock_Basalt_Brick_Smooth"
    },
    {
      "x": 0,
      "y": 6,
      "z": -8,
      "name": "Rock_Basalt_Brick_Smooth"
    },
    {
      "x": 0,
      "y": 7,
      "z": -8,
      "name": "Rock_Basalt_Brick_Smooth"
    },
    {
      "x": 0,
      "y": 1,
      "z": -7,
      "name": "Rock_Stone_Aqua"
    },
    {
      "x": 0,
      "y": 7,
      "z": -7,
      "name": "Rock_Stone_Aqua"
    },
    {
      "x": 0,
      "y": 1,
      "z": -6,
      "name": "Rock_Stone_Aqua"
    },
    {
      "x": 0,
      "y": 7,
      "z": -6,
      "name": "Rock_Stone_Aqua"
    },
    {
      "x": 0,
      "y": 1,
      "z": -5,
      "name": "Rock_Stone_Aqua"
    },
    {
      "x": 0,
      "y": 7,
      "z": -5,
      "name": "Rock_Basalt_Brick"
    },
    {
      "x": 0,
      "y": 8,
      "z": -5,
      "name": "Rock_Basalt_Brick_Stairs"
    },
    {
      "x": 0,
      "y": 9,
      "z": -5,
      "name": "Rock_Basalt_Brick_Decorative"
    },
    {
      "x": 0,
      "y": 10,
      "z": -5,
      "name": "Rock_Basalt_Brick_Stairs",
      "rotation": 10
    },
    {
      "x": 0,
      "y": 11,
      "z": -5,
      "name": "Rock_Basalt_Brick"
    },
    {
      "x": 0,
      "y": 12,
      "z": -5,
      "name": "Rock_Basalt_Brick_Stairs"
    },
    {
      "x": 0,
      "y": 13,
      "z": -5,
      "name": "Rock_Basalt_Brick_Decorative"
    },
    {
      "x": 0,
      "y": 14,
      "z": -5,
      "name": "Rock_Basalt_Brick_Stairs",
      "rotation": 10
    },
    {
      "x": 0,
      "y": 15,
      "z": -5,
      "name": "Rock_Basalt_Brick"
    },
    {
      "x": 0,
      "y": 16,
      "z": -5,
      "name": "Rock_Basalt_Brick_Stairs"
    },
    {
      "x": 0,
      "y": 17,
      "z": -5,
      "name": "Rock_Basalt_Brick_Decorative"
    },
    {
      "x": 0,
      "y": 18,
      "z": -5,
      "name": "Rock_Basalt_Brick_Stairs",
      "rotation": 10
    },
    {
      "x": 0,
      "y": 19,
      "z": -5,
      "name": "Rock_Basalt_Brick"
    },
    {
      "x": 0,
      "y": 20,
      "z": -5,
      "name": "Rock_Basalt_Brick_Stairs"
    },
    {
      "x": 0,
      "y": 21,
      "z": -5,
      "name": "Rock_Basalt_Brick_Decorative"
    },
    {
      "x": 0,
      "y": 22,
      "z": -5,
      "name": "Rock_Basalt_Brick_Stairs",
      "rotation": 10
    },
    {
      "x": 0,
      "y": 23,
      "z": -5,
      "name": "Rock_Basalt_Brick"
    },
    {
      "x": 0,
      "y": 24,
      "z": -5,
      "name": "Rock_Basalt_Brick_Stairs"
    },
    {
      "x": 0,
      "y": 25,
      "z": -5,
      "name": "Rock_Basalt_Brick_Decorative"
    },
    {
      "x": 0,
      "y": 1,
      "z": -4,
      "name": "Rock_Basalt_Brick_Smooth"
    },
    {
      "x": 0,
      "y": 7,
      "z": -4,
      "name": "Wood_Goldenwood_Planks"
    },
    {
      "x": 0,
      "y": 23,
      "z": -4,
      "name": "Wood_Goldenwood_Planks"
    },
    {
      "x": 0,
      "y": 1,
      "z": -3,
      "name": "Rock_Stone_Aqua"
    },
    {
      "x": 0,
      "y": 7,
      "z": -3,
      "name": "Wood_Goldenwood_Planks"
    },
    {
      "x": 0,
      "y": 23,
      "z": -3,
      "name": "Wood_Goldenwood_Planks"
    },
    {
      "x": 0,
      "y": 1,
      "z": -2,
      "name": "Rock_Stone_Aqua"
    },
    {
      "x": 0,
      "y": 0,
      "z": -1,
      "name": "Rock_Basalt_Brick"
    },
    {
      "x": 0,
      "y": 0,
      "z": 0,
      "name": "Rock_Basalt_Brick"
    },
    {
      "x": 0,
      "y": 0,
      "z": 1,
      "name": "Rock_Basalt_Brick"
    },
    {
      "x": 0,
      "y": 1,
      "z": 2,
      "name": "Rock_Stone_Aqua"
    },
    {
      "x": 0,
      "y": 1,
      "z": 3,
      "name": "Rock_Stone_Aqua"
    },
    {
      "x": 0,
      "y": 15,
      "z": 3,
      "name": "Wood_Goldenwood_Planks"
    },
    {
      "x": 0,
      "y": 1,
      "z": 4,
      "name": "Rock_Basalt_Brick_Smooth"
    },
    {
      "x": 0,
      "y": 15,
      "z": 4,
      "name": "Wood_Goldenwood_Planks"
    },
    {
      "x": 0,
      "y": 1,
      "z": 5,
      "name": "Rock_Stone_Aqua"
    },
    {
      "x": 0,
      "y": 7,
      "z": 5,
      "name": "Rock_Basalt_Brick"
    },
    {
      "x": 0,
      "y": 8,
      "z": 5,
      "name": "Rock_Basalt_Brick_Stairs",
      "rotation": 2
    },
    {
      "x": 0,
      "y": 9,
      "z": 5,
      "name": "Rock_Basalt_Brick_Decorative"
    },
    {
      "x": 0,
      "y": 10,
      "z": 5,
      "name": "Rock_Basalt_Brick_Stairs",
      "rotation": 8
    },
    {
      "x": 0,
      "y": 11,
      "z": 5,
      "name": "Rock_Basalt_Brick"
    },
    {
      "x": 0,
      "y": 12,
      "z": 5,
      "name": "Rock_Basalt_Brick_Stairs",
      "rotation": 2
    },
    {
      "x": 0,
      "y": 13,
      "z": 5,
      "name": "Rock_Basalt_Brick_Decorative"
    },
    {
      "x": 0,
      "y": 14,
      "z": 5,
      "name": "Rock_Basalt_Brick_Stairs",
      "rotation": 8
    },
    {
      "x": 0,
      "y": 15,
      "z": 5,
      "name": "Rock_Basalt_Brick"
    },
    {
      "x": 0,
      "y": 16,
      "z": 5,
      "name": "Rock_Basalt_Brick_Stairs",
      "rotation": 2
    },
    {
      "x": 0,
      "y": 17,
      "z": 5,
      "name": "Rock_Basalt_Brick_Decorative"
    },
    {
      "x": 0,
      "y": 18,
      "z": 5,
      "name": "Rock_Basalt_Brick_Stairs",
      "rotation": 8
    },
    {
      "x": 0,
      "y": 19,
      "z": 5,
      "name": "Rock_Basalt_Brick"
    },
    {
      "x": 0,
      "y": 20,
      "z": 5,
      "name": "Rock_Basalt_Brick_Stairs",
      "rotation": 2
    },
    {
      "x": 0,
      "y": 21,
      "z": 5,
      "name": "Rock_Basalt_Brick_Decorative"
    },
    {
      "x": 0,
      "y": 22,
      "z": 5,
      "name": "Rock_Basalt_Brick_Stairs",
      "rotation": 2
    },
    {
      "x": 0,
      "y": 23,
      "z": 5,
      "name": "Rock_Basalt_Brick"
    },
    {
      "x": 0,
      "y": 24,
      "z": 5,
      "name": "Rock_Basalt_Brick_Stairs",
      "rotation": 2
    },
    {
      "x": 0,
      "y": 25,
      "z": 5,
      "name": "Rock_Basalt_Brick_Decorative"
    },
    {
      "x": 0,
      "y": 1,
      "z": 6,
      "name": "Rock_Stone_Aqua"
    },
    {
      "x": 0,
      "y": 7,
      "z": 6,
      "name": "Rock_Stone_Aqua"
    },
    {
      "x": 0,
      "y": 1,
      "z": 7,
      "name": "Rock_Stone_Aqua"
    },
    {
      "x": 0,
      "y": 7,
      "z": 7,
      "name": "Rock_Stone_Aqua"
    },
    {
      "x": 0,
      "y": 1,
      "z": 8,
      "name": "Rock_Basalt_Brick_Smooth"
    },
    {
      "x": 0,
      "y": 2,
      "z": 8,
      "name": "Rock_Basalt_Brick_Smooth"
    },
    {
      "x": 0,
      "y": 3,
      "z": 8,
      "name": "Rock_Basalt_Brick_Smooth"
    },
    {
      "x": 0,
      "y": 4,
      "z": 8,
      "name": "Rock_Basalt_Brick_Smooth"
    },
    {
      "x": 0,
      "y": 5,
      "z": 8,
      "name": "Rock_Basalt_Brick_Smooth"
    },
    {
      "x": 0,
      "y": 6,
      "z": 8,
      "name": "Rock_Basalt_Brick_Smooth"
    },
    {
      "x": 0,
      "y": 7,
      "z": 8,
      "name": "Rock_Basalt_Brick_Smooth"
    },
    {
      "x": 1,
      "y": 1,
      "z": -8,
      "name": "Rock_Basalt_Brick_Smooth"
    },
    {
      "x": 1,
      "y": 2,
      "z": -8,
      "name": "Rock_Basalt_Brick_Smooth"
    },
    {
      "x": 1,
      "y": 3,
      "z": -8,
      "name": "Rock_Basalt_Brick_Smooth"
    },
    {
      "x": 1,
      "y": 4,
      "z": -8,
      "name": "Rock_Basalt_Brick_Smooth"
    },
    {
      "x": 1,
      "y": 5,
      "z": -8,
      "name": "Rock_Basalt_Brick_Smooth"
    },
    {
      "x": 1,
      "y": 6,
      "z": -8,
      "name": "Rock_Basalt_Brick_Smooth"
    },
    {
      "x": 1,
      "y": 7,
      "z": -8,
      "name": "Rock_Basalt_Brick_Smooth"
    },
    {
      "x": 1,
      "y": 1,
      "z": -7,
      "name": "Rock_Stone_Aqua"
    },
    {
      "x": 1,
      "y": 7,
      "z": -7,
      "name": "Rock_Stone_Aqua"
    },
    {
      "x": 1,
      "y": 1,
      "z": -6,
      "name": "Rock_Stone_Aqua"
    },
    {
      "x": 1,
      "y": 5,
      "z": -6,
      "name": "Rock_Aqua_Stalactite_Large",
      "filler": 31744,
      "rotation": 8
    },
    {
      "x": 1,
      "y": 6,
      "z": -6,
      "name": "Rock_Aqua_Stalactite_Large",
      "rotation": 8
    },
    {
      "x": 1,
      "y": 7,
      "z": -6,
      "name": "Rock_Stone_Aqua"
    },
    {
      "x": 1,
      "y": 1,
      "z": -5,
      "name": "Rock_Stone_Aqua"
    },
    {
      "x": 1,
      "y": 7,
      "z": -5,
      "name": "Rock_Basalt_Brick"
    },
    {
      "x": 1,
      "y": 8,
      "z": -5,
      "name": "Rock_Basalt_Brick"
    },
    {
      "x": 1,
      "y": 9,
      "z": -5,
      "name": "Rock_Basalt_Brick"
    },
    {
      "x": 1,
      "y": 10,
      "z": -5,
      "name": "Rock_Basalt_Brick"
    },
    {
      "x": 1,
      "y": 11,
      "z": -5,
      "name": "Rock_Basalt_Brick"
    },
    {
      "x": 1,
      "y": 12,
      "z": -5,
      "name": "Rock_Basalt_Brick"
    },
    {
      "x": 1,
      "y": 13,
      "z": -5,
      "name": "Rock_Basalt_Brick"
    },
    {
      "x": 1,
      "y": 14,
      "z": -5,
      "name": "Rock_Basalt_Brick"
    },
    {
      "x": 1,
      "y": 15,
      "z": -5,
      "name": "Rock_Basalt_Brick"
    },
    {
      "x": 1,
      "y": 16,
      "z": -5,
      "name": "Rock_Basalt_Brick"
    },
    {
      "x": 1,
      "y": 17,
      "z": -5,
      "name": "Rock_Basalt_Brick"
    },
    {
      "x": 1,
      "y": 18,
      "z": -5,
      "name": "Rock_Basalt_Brick"
    },
    {
      "x": 1,
      "y": 19,
      "z": -5,
      "name": "Rock_Basalt_Brick"
    },
    {
      "x": 1,
      "y": 20,
      "z": -5,
      "name": "Rock_Basalt_Brick"
    },
    {
      "x": 1,
      "y": 21,
      "z": -5,
      "name": "Rock_Basalt_Brick"
    },
    {
      "x": 1,
      "y": 22,
      "z": -5,
      "name": "Rock_Basalt_Brick"
    },
    {
      "x": 1,
      "y": 23,
      "z": -5,
      "name": "Rock_Basalt_Brick"
    },
    {
      "x": 1,
      "y": 24,
      "z": -5,
      "name": "Rock_Basalt_Brick"
    },
    {
      "x": 1,
      "y": 25,
      "z": -5,
      "name": "Rock_Basalt_Brick"
    },
    {
      "x": 1,
      "y": 1,
      "z": -4,
      "name": "Rock_Basalt_Brick_Smooth"
    },
    {
      "x": 1,
      "y": 8,
      "z": -4,
      "name": "Wood_Goldenwood_Planks"
    },
    {
      "x": 1,
      "y": 24,
      "z": -4,
      "name": "Wood_Goldenwood_Planks"
    },
    {
      "x": 1,
      "y": 1,
      "z": -3,
      "name": "Rock_Stone_Aqua"
    },
    {
      "x": 1,
      "y": 8,
      "z": -3,
      "name": "Wood_Goldenwood_Planks"
    },
    {
      "x": 1,
      "y": 24,
      "z": -3,
      "name": "Wood_Goldenwood_Planks"
    },
    {
      "x": 1,
      "y": 1,
      "z": -2,
      "name": "Rock_Stone_Aqua"
    },
    {
      "x": 1,
      "y": 8,
      "z": -2,
      "name": "Wood_Goldenwood_Planks"
    },
    {
      "x": 1,
      "y": 24,
      "z": -2,
      "name": "Wood_Goldenwood_Planks"
    },
    {
      "x": 1,
      "y": 0,
      "z": -1,
      "name": "Rock_Basalt_Brick"
    },
    {
      "x": 1,
      "y": 0,
      "z": 0,
      "name": "Rock_Basalt_Brick"
    },
    {
      "x": 1,
      "y": 0,
      "z": 1,
      "name": "Rock_Basalt_Brick"
    },
    {
      "x": 1,
      "y": 1,
      "z": 2,
      "name": "Rock_Stone_Aqua"
    },
    {
      "x": 1,
      "y": 14,
      "z": 2,
      "name": "Wood_Goldenwood_Planks"
    },
    {
      "x": 1,
      "y": 1,
      "z": 3,
      "name": "Rock_Stone_Aqua"
    },
    {
      "x": 1,
      "y": 14,
      "z": 3,
      "name": "Wood_Goldenwood_Planks"
    },
    {
      "x": 1,
      "y": 1,
      "z": 4,
      "name": "Rock_Basalt_Brick_Smooth"
    },
    {
      "x": 1,
      "y": 14,
      "z": 4,
      "name": "Wood_Goldenwood_Planks"
    },
    {
      "x": 1,
      "y": 1,
      "z": 5,
      "name": "Rock_Stone_Aqua"
    },
    {
      "x": 1,
      "y": 7,
      "z": 5,
      "name": "Rock_Basalt_Brick"
    },
    {
      "x": 1,
      "y": 8,
      "z": 5,
      "name": "Rock_Basalt_Brick"
    },
    {
      "x": 1,
      "y": 9,
      "z": 5,
      "name": "Rock_Basalt_Brick"
    },
    {
      "x": 1,
      "y": 10,
      "z": 5,
      "name": "Rock_Basalt_Brick"
    },
    {
      "x": 1,
      "y": 11,
      "z": 5,
      "name": "Rock_Basalt_Brick"
    },
    {
      "x": 1,
      "y": 12,
      "z": 5,
      "name": "Rock_Basalt_Brick"
    },
    {
      "x": 1,
      "y": 13,
      "z": 5,
      "name": "Rock_Basalt_Brick"
    },
    {
      "x": 1,
      "y": 14,
      "z": 5,
      "name": "Rock_Basalt_Brick"
    },
    {
      "x": 1,
      "y": 15,
      "z": 5,
      "name": "Rock_Basalt_Brick"
    },
    {
      "x": 1,
      "y": 16,
      "z": 5,
      "name": "Rock_Basalt_Brick"
    },
    {
      "x": 1,
      "y": 17,
      "z": 5,
      "name": "Rock_Basalt_Brick"
    },
    {
      "x": 1,
      "y": 18,
      "z": 5,
      "name": "Rock_Basalt_Brick"
    },
    {
      "x": 1,
      "y": 19,
      "z": 5,
      "name": "Rock_Basalt_Brick"
    },
    {
      "x": 1,
      "y": 20,
      "z": 5,
      "name": "Rock_Basalt_Brick"
    },
    {
      "x": 1,
      "y": 21,
      "z": 5,
      "name": "Rock_Basalt_Brick"
    },
    {
      "x": 1,
      "y": 22,
      "z": 5,
      "name": "Rock_Basalt_Brick"
    },
    {
      "x": 1,
      "y": 23,
      "z": 5,
      "name": "Rock_Basalt_Brick"
    },
    {
      "x": 1,
      "y": 24,
      "z": 5,
      "name": "Rock_Basalt_Brick"
    },
    {
      "x": 1,
      "y": 25,
      "z": 5,
      "name": "Rock_Basalt_Brick"
    },
    {
      "x": 1,
      "y": 1,
      "z": 6,
      "name": "Rock_Stone_Aqua"
    },
    {
      "x": 1,
      "y": 7,
      "z": 6,
      "name": "Rock_Stone_Aqua"
    },
    {
      "x": 1,
      "y": 1,
      "z": 7,
      "name": "Rock_Stone_Aqua"
    },
    {
      "x": 1,
      "y": 7,
      "z": 7,
      "name": "Rock_Stone_Aqua"
    },
    {
      "x": 1,
      "y": 1,
      "z": 8,
      "name": "Rock_Basalt_Brick_Smooth"
    },
    {
      "x": 1,
      "y": 2,
      "z": 8,
      "name": "Rock_Basalt_Brick_Smooth"
    },
    {
      "x": 1,
      "y": 3,
      "z": 8,
      "name": "Rock_Basalt_Brick_Smooth"
    },
    {
      "x": 1,
      "y": 4,
      "z": 8,
      "name": "Rock_Basalt_Brick_Smooth"
    },
    {
      "x": 1,
      "y": 5,
      "z": 8,
      "name": "Rock_Basalt_Brick_Smooth"
    },
    {
      "x": 1,
      "y": 6,
      "z": 8,
      "name": "Rock_Basalt_Brick_Smooth"
    },
    {
      "x": 1,
      "y": 7,
      "z": 8,
      "name": "Rock_Basalt_Brick_Smooth"
    },
    {
      "x": 2,
      "y": 1,
      "z": -8,
      "name": "Rock_Basalt_Brick_Smooth"
    },
    {
      "x": 2,
      "y": 2,
      "z": -8,
      "name": "Rock_Basalt_Brick_Decorative"
    },
    {
      "x": 2,
      "y": 3,
      "z": -8,
      "name": "Rock_Basalt_Brick_Smooth"
    },
    {
      "x": 2,
      "y": 4,
      "z": -8,
      "name": "Rock_Basalt_Brick_Smooth"
    },
    {
      "x": 2,
      "y": 5,
      "z": -8,
      "name": "Rock_Basalt_Brick_Smooth"
    },
    {
      "x": 2,
      "y": 6,
      "z": -8,
      "name": "Rock_Basalt_Brick_Decorative"
    },
    {
      "x": 2,
      "y": 7,
      "z": -8,
      "name": "Rock_Basalt_Brick_Smooth"
    },
    {
      "x": 2,
      "y": 1,
      "z": -7,
      "name": "Rock_Stone_Aqua"
    },
    {
      "x": 2,
      "y": 7,
      "z": -7,
      "name": "Rock_Stone_Aqua"
    },
    {
      "x": 2,
      "y": 1,
      "z": -6,
      "name": "Rock_Stone_Aqua"
    },
    {
      "x": 2,
      "y": 2,
      "z": -6,
      "name": "Rock_Aqua_Stalactite_Large"
    },
    {
      "x": 2,
      "y": 3,
      "z": -6,
      "name": "Rock_Aqua_Stalactite_Large",
      "filler": 1024
    },
    {
      "x": 2,
      "y": 7,
      "z": -6,
      "name": "Rock_Stone_Aqua"
    },
    {
      "x": 2,
      "y": 1,
      "z": -5,
      "name": "Rock_Stone_Aqua"
    },
    {
      "x": 2,
      "y": 7,
      "z": -5,
      "name": "Rock_Basalt_Brick"
    },
    {
      "x": 2,
      "y": 8,
      "z": -5,
      "name": "Rock_Basalt_Brick"
    },
    {
      "x": 2,
      "y": 9,
      "z": -5,
      "name": "Rock_Basalt_Brick"
    },
    {
      "x": 2,
      "y": 10,
      "z": -5,
      "name": "Rock_Basalt_Brick"
    },
    {
      "x": 2,
      "y": 11,
      "z": -5,
      "name": "Rock_Basalt_Brick"
    },
    {
      "x": 2,
      "y": 12,
      "z": -5,
      "name": "Rock_Basalt_Brick"
    },
    {
      "x": 2,
      "y": 13,
      "z": -5,
      "name": "Rock_Basalt_Brick"
    },
    {
      "x": 2,
      "y": 14,
      "z": -5,
      "name": "Rock_Basalt_Brick"
    },
    {
      "x": 2,
      "y": 15,
      "z": -5,
      "name": "Rock_Basalt_Brick"
    },
    {
      "x": 2,
      "y": 16,
      "z": -5,
      "name": "Rock_Basalt_Brick"
    },
    {
      "x": 2,
      "y": 17,
      "z": -5,
      "name": "Rock_Basalt_Brick"
    },
    {
      "x": 2,
      "y": 18,
      "z": -5,
      "name": "Rock_Basalt_Brick"
    },
    {
      "x": 2,
      "y": 19,
      "z": -5,
      "name": "Rock_Basalt_Brick"
    },
    {
      "x": 2,
      "y": 20,
      "z": -5,
      "name": "Rock_Basalt_Brick"
    },
    {
      "x": 2,
      "y": 21,
      "z": -5,
      "name": "Rock_Basalt_Brick"
    },
    {
      "x": 2,
      "y": 22,
      "z": -5,
      "name": "Rock_Basalt_Brick"
    },
    {
      "x": 2,
      "y": 23,
      "z": -5,
      "name": "Rock_Basalt_Brick"
    },
    {
      "x": 2,
      "y": 24,
      "z": -5,
      "name": "Rock_Basalt_Brick"
    },
    {
      "x": 2,
      "y": 25,
      "z": -5,
      "name": "Rock_Basalt_Brick"
    },
    {
      "x": 2,
      "y": 1,
      "z": -4,
      "name": "Rock_Basalt_Brick_Smooth"
    },
    {
      "x": 2,
      "y": 9,
      "z": -4,
      "name": "Wood_Goldenwood_Planks"
    },
    {
      "x": 2,
      "y": 25,
      "z": -4,
      "name": "Wood_Goldenwood_Planks"
    },
    {
      "x": 2,
      "y": 1,
      "z": -3,
      "name": "Rock_Stone_Aqua"
    },
    {
      "x": 2,
      "y": 9,
      "z": -3,
      "name": "Wood_Goldenwood_Planks"
    },
    {
      "x": 2,
      "y": 25,
      "z": -3,
      "name": "Wood_Goldenwood_Planks"
    },
    {
      "x": 2,
      "y": 1,
      "z": -2,
      "name": "Rock_Stone_Aqua"
    },
    {
      "x": 2,
      "y": 9,
      "z": -2,
      "name": "Wood_Goldenwood_Planks"
    },
    {
      "x": 2,
      "y": 25,
      "z": -2,
      "name": "Wood_Goldenwood_Planks"
    },
    {
      "x": 2,
      "y": 1,
      "z": -1,
      "name": "Rock_Stone_Aqua"
    },
    {
      "x": 2,
      "y": 10,
      "z": -1,
      "name": "Wood_Goldenwood_Planks"
    },
    {
      "x": 2,
      "y": 1,
      "z": 0,
      "name": "Rock_Stone_Aqua"
    },
    {
      "x": 2,
      "y": 1,
      "z": 1,
      "name": "Rock_Stone_Aqua"
    },
    {
      "x": 2,
      "y": 12,
      "z": 1,
      "name": "Wood_Goldenwood_Planks"
    },
    {
      "x": 2,
      "y": 1,
      "z": 2,
      "name": "Rock_Stone_Aqua"
    },
    {
      "x": 2,
      "y": 13,
      "z": 2,
      "name": "Wood_Goldenwood_Planks"
    },
    {
      "x": 2,
      "y": 1,
      "z": 3,
      "name": "Rock_Stone_Aqua"
    },
    {
      "x": 2,
      "y": 13,
      "z": 3,
      "name": "Wood_Goldenwood_Planks"
    },
    {
      "x": 2,
      "y": 1,
      "z": 4,
      "name": "Rock_Basalt_Brick_Smooth"
    },
    {
      "x": 2,
      "y": 13,
      "z": 4,
      "name": "Wood_Goldenwood_Planks"
    },
    {
      "x": 2,
      "y": 1,
      "z": 5,
      "name": "Rock_Stone_Aqua"
    },
    {
      "x": 2,
      "y": 7,
      "z": 5,
      "name": "Rock_Basalt_Brick"
    },
    {
      "x": 2,
      "y": 8,
      "z": 5,
      "name": "Rock_Basalt_Brick"
    },
    {
      "x": 2,
      "y": 9,
      "z": 5,
      "name": "Rock_Basalt_Brick"
    },
    {
      "x": 2,
      "y": 10,
      "z": 5,
      "name": "Rock_Basalt_Brick"
    },
    {
      "x": 2,
      "y": 11,
      "z": 5,
      "name": "Rock_Basalt_Brick"
    },
    {
      "x": 2,
      "y": 12,
      "z": 5,
      "name": "Rock_Basalt_Brick"
    },
    {
      "x": 2,
      "y": 13,
      "z": 5,
      "name": "Rock_Basalt_Brick"
    },
    {
      "x": 2,
      "y": 14,
      "z": 5,
      "name": "Rock_Basalt_Brick"
    },
    {
      "x": 2,
      "y": 15,
      "z": 5,
      "name": "Rock_Basalt_Brick"
    },
    {
      "x": 2,
      "y": 16,
      "z": 5,
      "name": "Rock_Basalt_Brick"
    },
    {
      "x": 2,
      "y": 17,
      "z": 5,
      "name": "Rock_Basalt_Brick"
    },
    {
      "x": 2,
      "y": 18,
      "z": 5,
      "name": "Rock_Basalt_Brick"
    },
    {
      "x": 2,
      "y": 19,
      "z": 5,
      "name": "Rock_Basalt_Brick"
    },
    {
      "x": 2,
      "y": 20,
      "z": 5,
      "name": "Rock_Basalt_Brick"
    },
    {
      "x": 2,
      "y": 21,
      "z": 5,
      "name": "Rock_Basalt_Brick"
    },
    {
      "x": 2,
      "y": 22,
      "z": 5,
      "name": "Rock_Basalt_Brick"
    },
    {
      "x": 2,
      "y": 23,
      "z": 5,
      "name": "Rock_Basalt_Brick"
    },
    {
      "x": 2,
      "y": 24,
      "z": 5,
      "name": "Rock_Basalt_Brick"
    },
    {
      "x": 2,
      "y": 25,
      "z": 5,
      "name": "Rock_Basalt_Brick"
    },
    {
      "x": 2,
      "y": 1,
      "z": 6,
      "name": "Rock_Stone_Aqua"
    },
    {
      "x": 2,
      "y": 7,
      "z": 6,
      "name": "Rock_Stone_Aqua"
    },
    {
      "x": 2,
      "y": 1,
      "z": 7,
      "name": "Rock_Stone_Aqua"
    },
    {
      "x": 2,
      "y": 7,
      "z": 7,
      "name": "Rock_Stone_Aqua"
    },
    {
      "x": 2,
      "y": 1,
      "z": 8,
      "name": "Rock_Basalt_Brick_Smooth"
    },
    {
      "x": 2,
      "y": 2,
      "z": 8,
      "name": "Rock_Basalt_Brick_Decorative"
    },
    {
      "x": 2,
      "y": 3,
      "z": 8,
      "name": "Rock_Basalt_Brick_Smooth"
    },
    {
      "x": 2,
      "y": 4,
      "z": 8,
      "name": "Rock_Basalt_Brick_Smooth"
    },
    {
      "x": 2,
      "y": 5,
      "z": 8,
      "name": "Rock_Basalt_Brick_Smooth"
    },
    {
      "x": 2,
      "y": 6,
      "z": 8,
      "name": "Rock_Basalt_Brick_Decorative"
    },
    {
      "x": 2,
      "y": 7,
      "z": 8,
      "name": "Rock_Basalt_Brick_Smooth"
    },
    {
      "x": 3,
      "y": 1,
      "z": -8,
      "name": "Rock_Basalt_Brick_Smooth"
    },
    {
      "x": 3,
      "y": 2,
      "z": -8,
      "name": "Wood_Goldenwood_Planks"
    },
    {
      "x": 3,
      "y": 3,
      "z": -8,
      "name": "Wood_Goldenwood_Planks"
    },
    {
      "x": 3,
      "y": 4,
      "z": -8,
      "name": "Wood_Goldenwood_Planks"
    },
    {
      "x": 3,
      "y": 5,
      "z": -8,
      "name": "Wood_Goldenwood_Planks"
    },
    {
      "x": 3,
      "y": 6,
      "z": -8,
      "name": "Wood_Goldenwood_Planks"
    },
    {
      "x": 3,
      "y": 7,
      "z": -8,
      "name": "Rock_Basalt_Brick_Smooth"
    },
    {
      "x": 3,
      "y": 1,
      "z": -7,
      "name": "Rock_Stone_Aqua"
    },
    {
      "x": 3,
      "y": 2,
      "z": -7,
      "name": "Wood_Goldenwood_Fence"
    },
    {
      "x": 3,
      "y": 3,
      "z": -7,
      "name": "Wood_Goldenwood_Fence"
    },
    {
      "x": 3,
      "y": 4,
      "z": -7,
      "name": "Wood_Goldenwood_Fence"
    },
    {
      "x": 3,
      "y": 5,
      "z": -7,
      "name": "Wood_Goldenwood_Fence"
    },
    {
      "x": 3,
      "y": 6,
      "z": -7,
      "name": "Wood_Goldenwood_Fence"
    },
    {
      "x": 3,
      "y": 7,
      "z": -7,
      "name": "Rock_Stone_Aqua"
    },
    {
      "x": 3,
      "y": 1,
      "z": -6,
      "name": "Rock_Stone_Aqua"
    },
    {
      "x": 3,
      "y": 7,
      "z": -6,
      "name": "Rock_Stone_Aqua"
    },
    {
      "x": 3,
      "y": 1,
      "z": -5,
      "name": "Rock_Stone_Aqua"
    },
    {
      "x": 3,
      "y": 7,
      "z": -5,
      "name": "Rock_Basalt_Brick"
    },
    {
      "x": 3,
      "y": 1,
      "z": -4,
      "name": "Rock_Basalt_Brick"
    },
    {
      "x": 3,
      "y": 2,
      "z": -4,
      "name": "Rock_Basalt_Brick"
    },
    {
      "x": 3,
      "y": 3,
      "z": -4,
      "name": "Rock_Basalt_Brick"
    },
    {
      "x": 3,
      "y": 4,
      "z": -4,
      "name": "Rock_Basalt_Brick"
    },
    {
      "x": 3,
      "y": 5,
      "z": -4,
      "name": "Rock_Basalt_Brick"
    },
    {
      "x": 3,
      "y": 6,
      "z": -4,
      "name": "Rock_Basalt_Brick"
    },
    {
      "x": 3,
      "y": 7,
      "z": -4,
      "name": "Rock_Basalt_Brick"
    },
    {
      "x": 3,
      "y": 8,
      "z": -4,
      "name": "Rock_Basalt_Brick"
    },
    {
      "x": 3,
      "y": 9,
      "z": -4,
      "name": "Rock_Basalt_Brick"
    },
    {
      "x": 3,
      "y": 10,
      "z": -4,
      "name": "Rock_Basalt_Brick"
    },
    {
      "x": 3,
      "y": 11,
      "z": -4,
      "name": "Rock_Basalt_Brick"
    },
    {
      "x": 3,
      "y": 12,
      "z": -4,
      "name": "Rock_Basalt_Brick"
    },
    {
      "x": 3,
      "y": 13,
      "z": -4,
      "name": "Rock_Basalt_Brick"
    },
    {
      "x": 3,
      "y": 14,
      "z": -4,
      "name": "Rock_Basalt_Brick"
    },
    {
      "x": 3,
      "y": 15,
      "z": -4,
      "name": "Rock_Basalt_Brick"
    },
    {
      "x": 3,
      "y": 16,
      "z": -4,
      "name": "Rock_Basalt_Brick"
    },
    {
      "x": 3,
      "y": 17,
      "z": -4,
      "name": "Rock_Basalt_Brick"
    },
    {
      "x": 3,
      "y": 18,
      "z": -4,
      "name": "Rock_Basalt_Brick"
    },
    {
      "x": 3,
      "y": 19,
      "z": -4,
      "name": "Rock_Basalt_Brick"
    },
    {
      "x": 3,
      "y": 20,
      "z": -4,
      "name": "Rock_Basalt_Brick"
    },
    {
      "x": 3,
      "y": 21,
      "z": -4,
      "name": "Rock_Basalt_Brick"
    },
    {
      "x": 3,
      "y": 22,
      "z": -4,
      "name": "Rock_Basalt_Brick"
    },
    {
      "x": 3,
      "y": 23,
      "z": -4,
      "name": "Rock_Basalt_Brick"
    },
    {
      "x": 3,
      "y": 24,
      "z": -4,
      "name": "Rock_Basalt_Brick"
    },
    {
      "x": 3,
      "y": 25,
      "z": -4,
      "name": "Rock_Basalt_Brick"
    },
    {
      "x": 3,
      "y": 1,
      "z": -3,
      "name": "Rock_Stone_Aqua"
    },
    {
      "x": 3,
      "y": 9,
      "z": -3,
      "name": "Wood_Goldenwood_Planks"
    },
    {
      "x": 3,
      "y": 25,
      "z": -3,
      "name": "Wood_Goldenwood_Planks"
    },
    {
      "x": 3,
      "y": 1,
      "z": -2,
      "name": "Rock_Stone_Aqua"
    },
    {
      "x": 3,
      "y": 9,
      "z": -2,
      "name": "Wood_Goldenwood_Planks"
    },
    {
      "x": 3,
      "y": 25,
      "z": -2,
      "name": "Wood_Goldenwood_Planks"
    },
    {
      "x": 3,
      "y": 1,
      "z": -1,
      "name": "Rock_Stone_Aqua"
    },
    {
      "x": 3,
      "y": 10,
      "z": -1,
      "name": "Wood_Goldenwood_Planks"
    },
    {
      "x": 3,
      "y": 1,
      "z": 0,
      "name": "Rock_Stone_Aqua"
    },
    {
      "x": 3,
      "y": 11,
      "z": 0,
      "name": "Wood_Goldenwood_Planks"
    },
    {
      "x": 3,
      "y": 1,
      "z": 1,
      "name": "Rock_Stone_Aqua"
    },
    {
      "x": 3,
      "y": 12,
      "z": 1,
      "name": "Wood_Goldenwood_Planks"
    },
    {
      "x": 3,
      "y": 1,
      "z": 2,
      "name": "Rock_Stone_Aqua"
    },
    {
      "x": 3,
      "y": 13,
      "z": 2,
      "name": "Wood_Goldenwood_Planks"
    },
    {
      "x": 3,
      "y": 1,
      "z": 3,
      "name": "Rock_Stone_Aqua"
    },
    {
      "x": 3,
      "y": 13,
      "z": 3,
      "name": "Wood_Goldenwood_Planks"
    },
    {
      "x": 3,
      "y": 1,
      "z": 4,
      "name": "Rock_Basalt_Brick"
    },
    {
      "x": 3,
      "y": 2,
      "z": 4,
      "name": "Rock_Basalt_Brick"
    },
    {
      "x": 3,
      "y": 3,
      "z": 4,
      "name": "Rock_Basalt_Brick"
    },
    {
      "x": 3,
      "y": 4,
      "z": 4,
      "name": "Rock_Basalt_Brick"
    },
    {
      "x": 3,
      "y": 5,
      "z": 4,
      "name": "Rock_Basalt_Brick"
    },
    {
      "x": 3,
      "y": 6,
      "z": 4,
      "name": "Rock_Basalt_Brick"
    },
    {
      "x": 3,
      "y": 7,
      "z": 4,
      "name": "Rock_Basalt_Brick"
    },
    {
      "x": 3,
      "y": 8,
      "z": 4,
      "name": "Rock_Basalt_Brick"
    },
    {
      "x": 3,
      "y": 9,
      "z": 4,
      "name": "Rock_Basalt_Brick"
    },
    {
      "x": 3,
      "y": 10,
      "z": 4,
      "name": "Rock_Basalt_Brick"
    },
    {
      "x": 3,
      "y": 11,
      "z": 4,
      "name": "Rock_Basalt_Brick"
    },
    {
      "x": 3,
      "y": 12,
      "z": 4,
      "name": "Rock_Basalt_Brick"
    },
    {
      "x": 3,
      "y": 13,
      "z": 4,
      "name": "Rock_Basalt_Brick"
    },
    {
      "x": 3,
      "y": 14,
      "z": 4,
      "name": "Rock_Basalt_Brick"
    },
    {
      "x": 3,
      "y": 15,
      "z": 4,
      "name": "Rock_Basalt_Brick"
    },
    {
      "x": 3,
      "y": 16,
      "z": 4,
      "name": "Rock_Basalt_Brick"
    },
    {
      "x": 3,
      "y": 17,
      "z": 4,
      "name": "Rock_Basalt_Brick"
    },
    {
      "x": 3,
      "y": 18,
      "z": 4,
      "name": "Rock_Basalt_Brick"
    },
    {
      "x": 3,
      "y": 19,
      "z": 4,
      "name": "Rock_Basalt_Brick"
    },
    {
      "x": 3,
      "y": 20,
      "z": 4,
      "name": "Rock_Basalt_Brick"
    },
    {
      "x": 3,
      "y": 21,
      "z": 4,
      "name": "Rock_Basalt_Brick"
    },
    {
      "x": 3,
      "y": 22,
      "z": 4,
      "name": "Rock_Basalt_Brick"
    },
    {
      "x": 3,
      "y": 23,
      "z": 4,
      "name": "Rock_Basalt_Brick"
    },
    {
      "x": 3,
      "y": 24,
      "z": 4,
      "name": "Rock_Basalt_Brick"
    },
    {
      "x": 3,
      "y": 25,
      "z": 4,
      "name": "Rock_Basalt_Brick"
    },
    {
      "x": 3,
      "y": 1,
      "z": 5,
      "name": "Rock_Stone_Aqua"
    },
    {
      "x": 3,
      "y": 7,
      "z": 5,
      "name": "Rock_Basalt_Brick"
    },
    {
      "x": 3,
      "y": 1,
      "z": 6,
      "name": "Rock_Stone_Aqua"
    },
    {
      "x": 3,
      "y": 7,
      "z": 6,
      "name": "Rock_Stone_Aqua"
    },
    {
      "x": 3,
      "y": 1,
      "z": 7,
      "name": "Rock_Stone_Aqua"
    },
    {
      "x": 3,
      "y": 2,
      "z": 7,
      "name": "Wood_Goldenwood_Fence",
      "rotation": 2
    },
    {
      "x": 3,
      "y": 3,
      "z": 7,
      "name": "Wood_Goldenwood_Fence",
      "rotation": 2
    },
    {
      "x": 3,
      "y": 4,
      "z": 7,
      "name": "Wood_Goldenwood_Fence",
      "rotation": 2
    },
    {
      "x": 3,
      "y": 5,
      "z": 7,
      "name": "Wood_Goldenwood_Fence",
      "rotation": 2
    },
    {
      "x": 3,
      "y": 6,
      "z": 7,
      "name": "Wood_Goldenwood_Fence",
      "rotation": 2
    },
    {
      "x": 3,
      "y": 7,
      "z": 7,
      "name": "Rock_Stone_Aqua"
    },
    {
      "x": 3,
      "y": 1,
      "z": 8,
      "name": "Rock_Basalt_Brick_Smooth"
    },
    {
      "x": 3,
      "y": 2,
      "z": 8,
      "name": "Wood_Goldenwood_Planks"
    },
    {
      "x": 3,
      "y": 3,
      "z": 8,
      "name": "Wood_Goldenwood_Planks"
    },
    {
      "x": 3,
      "y": 4,
      "z": 8,
      "name": "Wood_Goldenwood_Planks"
    },
    {
      "x": 3,
      "y": 5,
      "z": 8,
      "name": "Wood_Goldenwood_Planks"
    },
    {
      "x": 3,
      "y": 6,
      "z": 8,
      "name": "Wood_Goldenwood_Planks"
    },
    {
      "x": 3,
      "y": 7,
      "z": 8,
      "name": "Rock_Basalt_Brick_Smooth"
    },
    {
      "x": 4,
      "y": 1,
      "z": -8,
      "name": "Rock_Basalt_Brick"
    },
    {
      "x": 4,
      "y": 2,
      "z": -8,
      "name": "Rock_Basalt_Brick"
    },
    {
      "x": 4,
      "y": 3,
      "z": -8,
      "name": "Rock_Basalt_Brick"
    },
    {
      "x": 4,
      "y": 4,
      "z": -8,
      "name": "Rock_Basalt_Brick"
    },
    {
      "x": 4,
      "y": 5,
      "z": -8,
      "name": "Rock_Basalt_Brick"
    },
    {
      "x": 4,
      "y": 6,
      "z": -8,
      "name": "Rock_Basalt_Brick"
    },
    {
      "x": 4,
      "y": 7,
      "z": -8,
      "name": "Rock_Basalt_Brick"
    },
    {
      "x": 4,
      "y": 1,
      "z": -7,
      "name": "Rock_Stone_Aqua"
    },
    {
      "x": 4,
      "y": 7,
      "z": -7,
      "name": "Rock_Stone_Aqua"
    },
    {
      "x": 4,
      "y": 1,
      "z": -6,
      "name": "Rock_Stone_Aqua"
    },
    {
      "x": 4,
      "y": 7,
      "z": -6,
      "name": "Rock_Stone_Aqua"
    },
    {
      "x": 4,
      "y": 1,
      "z": -5,
      "name": "Rock_Stone_Aqua"
    },
    {
      "x": 4,
      "y": 7,
      "z": -5,
      "name": "Rock_Basalt_Brick"
    },
    {
      "x": 4,
      "y": 1,
      "z": -4,
      "name": "Rock_Basalt_Brick"
    },
    {
      "x": 4,
      "y": 2,
      "z": -4,
      "name": "Rock_Basalt_Brick"
    },
    {
      "x": 4,
      "y": 3,
      "z": -4,
      "name": "Rock_Basalt_Brick"
    },
    {
      "x": 4,
      "y": 4,
      "z": -4,
      "name": "Rock_Basalt_Brick"
    },
    {
      "x": 4,
      "y": 5,
      "z": -4,
      "name": "Rock_Basalt_Brick"
    },
    {
      "x": 4,
      "y": 6,
      "z": -4,
      "name": "Rock_Basalt_Brick"
    },
    {
      "x": 4,
      "y": 7,
      "z": -4,
      "name": "Rock_Basalt_Brick"
    },
    {
      "x": 4,
      "y": 1,
      "z": -3,
      "name": "Rock_Basalt_Brick"
    },
    {
      "x": 4,
      "y": 2,
      "z": -3,
      "name": "Rock_Basalt_Brick"
    },
    {
      "x": 4,
      "y": 3,
      "z": -3,
      "name": "Rock_Basalt_Brick"
    },
    {
      "x": 4,
      "y": 4,
      "z": -3,
      "name": "Rock_Basalt_Brick"
    },
    {
      "x": 4,
      "y": 5,
      "z": -3,
      "name": "Rock_Basalt_Brick"
    },
    {
      "x": 4,
      "y": 6,
      "z": -3,
      "name": "Rock_Basalt_Brick"
    },
    {
      "x": 4,
      "y": 7,
      "z": -3,
      "name": "Rock_Basalt_Brick"
    },
    {
      "x": 4,
      "y": 8,
      "z": -3,
      "name": "Rock_Basalt_Brick"
    },
    {
      "x": 4,
      "y": 9,
      "z": -3,
      "name": "Rock_Basalt_Brick"
    },
    {
      "x": 4,
      "y": 10,
      "z": -3,
      "name": "Rock_Basalt_Brick"
    },
    {
      "x": 4,
      "y": 11,
      "z": -3,
      "name": "Rock_Basalt_Brick"
    },
    {
      "x": 4,
      "y": 12,
      "z": -3,
      "name": "Rock_Basalt_Brick"
    },
    {
      "x": 4,
      "y": 13,
      "z": -3,
      "name": "Rock_Basalt_Brick"
    },
    {
      "x": 4,
      "y": 14,
      "z": -3,
      "name": "Rock_Basalt_Brick"
    },
    {
      "x": 4,
      "y": 15,
      "z": -3,
      "name": "Rock_Basalt_Brick"
    },
    {
      "x": 4,
      "y": 16,
      "z": -3,
      "name": "Rock_Basalt_Brick"
    },
    {
      "x": 4,
      "y": 17,
      "z": -3,
      "name": "Rock_Basalt_Brick"
    },
    {
      "x": 4,
      "y": 18,
      "z": -3,
      "name": "Rock_Basalt_Brick"
    },
    {
      "x": 4,
      "y": 19,
      "z": -3,
      "name": "Rock_Basalt_Brick"
    },
    {
      "x": 4,
      "y": 20,
      "z": -3,
      "name": "Rock_Basalt_Brick"
    },
    {
      "x": 4,
      "y": 21,
      "z": -3,
      "name": "Rock_Basalt_Brick"
    },
    {
      "x": 4,
      "y": 22,
      "z": -3,
      "name": "Rock_Basalt_Brick"
    },
    {
      "x": 4,
      "y": 23,
      "z": -3,
      "name": "Rock_Basalt_Brick"
    },
    {
      "x": 4,
      "y": 24,
      "z": -3,
      "name": "Rock_Basalt_Brick"
    },
    {
      "x": 4,
      "y": 25,
      "z": -3,
      "name": "Rock_Basalt_Brick"
    },
    {
      "x": 4,
      "y": 1,
      "z": -2,
      "name": "Rock_Basalt_Brick_Smooth"
    },
    {
      "x": 4,
      "y": 9,
      "z": -2,
      "name": "Wood_Goldenwood_Planks"
