{
  "version": 8,
  "blockIdVersion": 11,
  "anchorX": 3,
  "anchorY": 6,
  "anchorZ": 1,
  "blocks": [
    {
      "x": 1,
      "y": 5,
      "z": 0,
      "name": "Rock_Sandstone_White_Cobble"
    },
    {
      "x": 1,
      "y": 6,
      "z": 0,
      "name": "Cloth_Roof_Leather",
      "rotation": 3
    },
    {
      "x": 1,
      "y": 7,
      "z": 0,
      "name": "Empty"
    },
    {
      "x": 1,
      "y": 5,
      "z": 1,
      "name": "Rock_Sandstone_White_Cobble"
    },
    {
      "x": 1,
      "y": 6,
      "z": 1,
      "name": "Cloth_Roof_Leather",
      "rotation": 3
    },
    {
      "x": 1,
      "y": 7,
      "z": 1,
      "name": "Empty"
    },
    {
      "x": 1,
      "y": 5,
      "z": 2,
      "name": "Rock_Sandstone_White_Cobble"
    },
    {
      "x": 1,
      "y": 6,
      "z": 2,
      "name": "Cloth_Roof_Leather",
      "rotation": 3
    },
    {
      "x": 1,
      "y": 7,
      "z": 2,
      "name": "Empty"
    },
    {
      "x": 1,
      "y": 5,
      "z": 3,
      "name": "Rock_Sandstone_White_Cobble"
    },
    {
      "x": 1,
      "y": 6,
      "z": 3,
      "name": "Cloth_Roof_Leather",
      "rotation": 3
    },
    {
      "x": 1,
      "y": 7,
      "z": 3,
      "name": "Empty"
    },
    {
      "x": 2,
      "y": 5,
      "z": -1,
      "name": "Rock_Sandstone_White_Cobble"
    },
    {
      "x": 2,
      "y": 6,
      "z": -1,
      "name": "Empty"
    },
    {
      "x": 2,
      "y": 7,
      "z": -1,
      "name": "Empty"
    },
    {
      "x": 2,
      "y": 5,
      "z": 0,
      "name": "Rock_Sandstone_White_Cobble"
    },
    {
      "x": 2,
      "y": 6,
      "z": 0,
      "name": "Empty"
    },
    {
      "x": 2,
      "y": 7,
      "z": 0,
      "name": "Cloth_Roof_Leather",
      "rotation": 3
    },
    {
      "x": 2,
      "y": 5,
      "z": 1,
      "name": "Rock_Sandstone_White_Cobble"
    },
    {
      "x": 2,
      "y": 6,
      "z": 1,
      "name": "Furniture_Crude_Bed",
      "filler": 992,
      "rotation": 2
    },
    {
      "x": 2,
      "y": 7,
      "z": 1,
      "name": "Cloth_Roof_Leather",
      "rotation": 3
    },
    {
      "x": 2,
      "y": 5,
      "z": 2,
      "name": "Rock_Sandstone_White_Cobble"
    },
    {
      "x": 2,
      "y": 6,
      "z": 2,
      "name": "Furniture_Crude_Bed",
      "components": {
        "Components": {
          "RespawnBlock": {}
        }
      },
      "rotation": 2
    },
    {
      "x": 2,
      "y": 7,
      "z": 2,
      "name": "Cloth_Roof_Leather",
      "rotation": 3
    },
    {
      "x": 2,
      "y": 5,
      "z": 3,
      "name": "Rock_Sandstone_White_Cobble"
    },
    {
      "x": 2,
      "y": 6,
      "z": 3,
      "name": "Empty"
    },
    {
      "x": 2,
      "y": 7,
      "z": 3,
      "name": "Cloth_Roof_Leather",
      "rotation": 3
    },
    {
      "x": 3,
      "y": 5,
      "z": -1,
      "name": "Rock_Sandstone_White_Cobble"
    },
    {
      "x": 3,
      "y": 6,
      "z": -1,
      "name": "Empty"
    },
    {
      "x": 3,
      "y": 7,
      "z": -1,
      "name": "Empty"
    },
    {
      "x": 3,
      "y": 5,
      "z": 0,
      "name": "Rock_Sandstone_White_Cobble"
    },
    {
      "x": 3,
      "y": 6,
      "z": 0,
      "name": "Empty"
    },
    {
      "x": 3,
      "y": 7,
      "z": 0,
      "name": "Empty"
    },
    {
      "x": 3,
      "y": 8,
      "z": 0,
      "name": "Cloth_Roof_Leather_Flat"
    },
    {
      "x": 3,
      "y": 5,
      "z": 1,
      "name": "Rock_Sandstone_White_Cobble"
    },
    {
      "x": 3,
      "y": 6,
      "z": 1,
      "name": "Empty"
    },
    {
      "x": 3,
      "y": 7,
      "z": 1,
      "name": "Empty"
    },
    {
      "x": 3,
      "y": 8,
      "z": 1,
      "name": "Cloth_Roof_Leather_Flat"
    },
    {
      "x": 3,
      "y": 5,
      "z": 2,
      "name": "Rock_Sandstone_White_Cobble"
    },
    {
      "x": 3,
      "y": 6,
      "z": 2,
      "name": "Deco_Plate"
    },
    {
      "x": 3,
      "y": 7,
      "z": 2,
      "name": "Empty"
    },
    {
      "x": 3,
      "y": 8,
      "z": 2,
      "name": "Cloth_Roof_Leather_Flat"
    },
    {
      "x": 3,
      "y": 5,
      "z": 3,
      "name": "Rock_Sandstone_White_Cobble"
    },
    {
      "x": 3,
      "y": 6,
      "z": 3,
      "name": "Wood_Hardwood_Beam"
    },
    {
      "x": 3,
      "y": 7,
      "z": 3,
      "name": "Wood_Hardwood_Beam"
    },
    {
      "x": 3,
      "y": 8,
      "z": 3,
      "name": "Cloth_Roof_Leather_Flat"
    },
    {
      "x": 4,
      "y": 5,
      "z": -1,
      "name": "Rock_Sandstone_White_Cobble"
    },
    {
      "x": 4,
      "y": 6,
      "z": -1,
      "name": "Empty"
    },
    {
      "x": 4,
      "y": 7,
      "z": -1,
      "name": "Empty"
    },
    {
      "x": 4,
      "y": 5,
      "z": 0,
      "name": "Rock_Sandstone_White_Cobble"
    },
    {
      "x": 4,
      "y": 6,
      "z": 0,
      "name": "Empty"
    },
    {
      "x": 4,
      "y": 7,
      "z": 0,
      "name": "Cloth_Roof_Leather",
      "rotation": 1
    },
    {
      "x": 4,
      "y": 5,
      "z": 1,
      "name": "Rock_Sandstone_White_Cobble"
    },
    {
      "x": 4,
      "y": 6,
      "z": 1,
      "name": "Wood_Sticks"
    },
    {
      "x": 4,
      "y": 7,
      "z": 1,
      "name": "Cloth_Roof_Leather",
      "rotation": 1
    },
    {
      "x": 4,
      "y": 5,
      "z": 2,
      "name": "Rock_Sandstone_White_Cobble"
    },
    {
      "x": 4,
      "y": 6,
      "z": 2,
      "name": "Empty"
    },
    {
      "x": 4,
      "y": 7,
      "z": 2,
      "name": "Cloth_Roof_Leather",
      "rotation": 1
    },
    {
      "x": 4,
      "y": 5,
      "z": 3,
      "name": "Rock_Sandstone_White_Cobble"
    },
    {
      "x": 4,
      "y": 6,
      "z": 3,
      "name": "Wood_Sticks",
      "support": 15
    },
    {
      "x": 4,
      "y": 7,
      "z": 3,
      "name": "Cloth_Roof_Leather",
      "rotation": 1
    },
    {
      "x": 5,
      "y": 5,
      "z": 0,
      "name": "Rock_Sandstone_White_Cobble"
    },
    {
      "x": 5,
      "y": 6,
      "z": 0,
      "name": "Cloth_Roof_Leather",
      "rotation": 1
    },
    {
      "x": 5,
      "y": 7,
      "z": 0,
      "name": "Empty"
    },
    {
      "x": 5,
      "y": 5,
      "z": 1,
      "name": "Rock_Sandstone_White_Cobble"
    },
    {
      "x": 5,
      "y": 6,
      "z": 1,
      "name": "Cloth_Roof_Leather",
      "rotation": 1
    },
    {
      "x": 5,
      "y": 7,
      "z": 1,
      "name": "Empty"
    },
    {
      "x": 5,
      "y": 5,
      "z": 2,
      "name": "Rock_Sandstone_White_Cobble"
    },
    {
      "x": 5,
      "y": 6,
      "z": 2,
      "name": "Cloth_Roof_Leather",
      "rotation": 1
    },
    {
      "x": 5,
      "y": 7,
      "z": 2,
      "name": "Empty"
    },
    {
      "x": 5,
      "y": 5,
      "z": 3,
      "name": "Rock_Sandstone_White_Cobble"
    },
    {
      "x": 5,
      "y": 6,
      "z": 3,
      "name": "Cloth_Roof_Leather",
      "rotation": 1
    },
    {
      "x": 5,
      "y": 7,
      "z": 3,
      "name": "Empty"
    }
  ],
  "entities": [
    {
      "Components": {
        "Nameplate": {
          "Text": "Kweebec"
        },
        "HiddenFromAdventurePlayer": {},
        "SpawnMarkerComponent": {
          "SpawnMarker": "Kweebec",
          "RespawnTime": 0.0,
          "SpawnCount": 0,
          "NPCReferences": [],
          "PersistedFlock": {},
          "SpawnPosition": {
            "X": 0.0,
            "Y": 0.0,
            "Z": 0.0
          }
        },
        "Transform": {
          "Position": {
            "X": 3.5279359817504883,
            "Y": 6.059474945068359,
            "Z": -0.6400463581085205
          },
          "Rotation": {
            "Pitch": 0.0,
            "Yaw": -0.012481212615966797,
            "Roll": 0.0
          }
        },
        "Intangible": {},
        "PrefabCopyable": {},
        "Model": {
          "Model": {
            "Id": "NPC_Spawn_Marker",
            "Scale": 1.0,
            "Static": false
          }
        },
        "UUID": {
          "UUID": {
            "$binary": "1MrQNA3qNva85KOS5ZP3kw==",
            "$type": "04"
          }
        }
      }
    }
  ]
}